Workbook

Sheet Charts
A2: Yearly Seasonality Cross-Validation
B4: Year | C4: 2025 | D4: =IF(C5=12,C4+1,C4) -> 2025 | E4: =IF(D5=12,D4+1,D4) -> 2025 | F4: =IF(E5=12,E4+1,E4) -> 2025 | G4: =IF(F5=12,F4+1,F4) -> 2025 | H4: =IF(G5=12,G4+1,G4) -> 2025 | I4: =IF(H5=12,H4+1,H4) -> 2025 | J4: =IF(I5=12,I4+1,I4) -> 2025 | K4: =IF(J5=12,J4+1,J4) -> 2025 | ... Q4: =IF(P5=12,P4+1,P4) -> 2026
B5: Month | C5: 1 | D5: =IF(C5=12,1,C5+1) -> 2 | E5: =IF(D5=12,1,D5+1) -> 3 | F5: =IF(E5=12,1,E5+1) -> 4 | G5: =IF(F5=12,1,F5+1) -> 5 | H5: =IF(G5=12,1,G5+1) -> 6 | I5: =IF(H5=12,1,H5+1) -> 7 | J5: =IF(I5=12,1,I5+1) -> 8 | K5: =IF(J5=12,1,J5+1) -> 9 | ... Q5: =IF(P5=12,1,P5+1) -> 3
B6: Actual | C6: =SUMIFS(Consolidated!$F:$F,Consolidated!$B:$B,C$4,Consolidated!$C:$C,C$5) -> 53930 | D6: =SUMIFS(Consolidated!$F:$F,Consolidated!$B:$B,D$4,Consolidated!$C:$C,D$5) -> 67327 | E6: =SUMIFS(Consolidated!$F:$F,Consolidated!$B:$B,E$4,Consolidated!$C:$C,E$5) -> 77121 | F6: =SUMIFS(Consolidated!$F:$F,Consolidated!$B:$B,F$4,Consolidated!$C:$C,F$5) -> 65200 | G6: =SUMIFS(Consolidated!$F:$F,Consolidated!$B:$B,G$4,Consolidated!$C:$C,G$5) -> 74393 | H6: =SUMIFS(Consolidated!$F:$F,Consolidated!$B:$B,H$4,Consolidated!$C:$C,H$5) -> 58858 | I6: =SUMIFS(Consolidated!$F:$F,Consolidated!$B:$B,I$4,Consolidated!$C:$C,I$5) -> 75663 | J6: =SUMIFS(Consolidated!$F:$F,Consolidated!$B:$B,J$4,Consolidated!$C:$C,J$5) -> 78978 | ... Q6: =SUMIFS(Consolidated!$F:$F,Consolidated!$B:$B,Q$4,Consolidated!$C:$C,Q$5) -> 67846
B7: M1 | C7: =SUMIFS(Consolidated!$G:$G,Consolidated!$B:$B,C$4,Consolidated!$C:$C,C$5) -> 73955 | D7: =SUMIFS(Consolidated!$G:$G,Consolidated!$B:$B,D$4,Consolidated!$C:$C,D$5) -> 68102 | E7: =SUMIFS(Consolidated!$G:$G,Consolidated!$B:$B,E$4,Consolidated!$C:$C,E$5) -> 85688 | F7: =SUMIFS(Consolidated!$G:$G,Consolidated!$B:$B,F$4,Consolidated!$C:$C,F$5) -> 75093 | G7: =SUMIFS(Consolidated!$G:$G,Consolidated!$B:$B,G$4,Consolidated!$C:$C,G$5) -> 75430 | H7: =SUMIFS(Consolidated!$G:$G,Consolidated!$B:$B,H$4,Consolidated!$C:$C,H$5) -> 75499 | I7: =SUMIFS(Consolidated!$G:$G,Consolidated!$B:$B,I$4,Consolidated!$C:$C,I$5) -> 77712 | J7: =SUMIFS(Consolidated!$G:$G,Consolidated!$B:$B,J$4,Consolidated!$C:$C,J$5) -> 82371 | ... Q7: =SUMIFS(Consolidated!$G:$G,Consolidated!$B:$B,Q$4,Consolidated!$C:$C,Q$5) -> 88381
B8: M2 | C8: =SUMIFS(Consolidated!$H:$H,Consolidated!$B:$B,C$4,Consolidated!$C:$C,C$5) -> 73148 | D8: =SUMIFS(Consolidated!$H:$H,Consolidated!$B:$B,D$4,Consolidated!$C:$C,D$5) -> 58587 | E8: =SUMIFS(Consolidated!$H:$H,Consolidated!$B:$B,E$4,Consolidated!$C:$C,E$5) -> 83786 | F8: =SUMIFS(Consolidated!$H:$H,Consolidated!$B:$B,F$4,Consolidated!$C:$C,F$5) -> 70245 | G8: =SUMIFS(Consolidated!$H:$H,Consolidated!$B:$B,G$4,Consolidated!$C:$C,G$5) -> 74723 | H8: =SUMIFS(Consolidated!$H:$H,Consolidated!$B:$B,H$4,Consolidated!$C:$C,H$5) -> 70027 | I8: =SUMIFS(Consolidated!$H:$H,Consolidated!$B:$B,I$4,Consolidated!$C:$C,I$5) -> 78078 | J8: =SUMIFS(Consolidated!$H:$H,Consolidated!$B:$B,J$4,Consolidated!$C:$C,J$5) -> 79767 | ... Q8: =SUMIFS(Consolidated!$H:$H,Consolidated!$B:$B,Q$4,Consolidated!$C:$C,Q$5) -> 88468
B9: M3 | C9: =SUMIFS(Consolidated!$I:$I,Consolidated!$B:$B,C$4,Consolidated!$C:$C,C$5) -> 71732 | D9: =SUMIFS(Consolidated!$I:$I,Consolidated!$B:$B,D$4,Consolidated!$C:$C,D$5) -> 59376 | E9: =SUMIFS(Consolidated!$I:$I,Consolidated!$B:$B,E$4,Consolidated!$C:$C,E$5) -> 79445 | F9: =SUMIFS(Consolidated!$I:$I,Consolidated!$B:$B,F$4,Consolidated!$C:$C,F$5) -> 71266 | G9: =SUMIFS(Consolidated!$I:$I,Consolidated!$B:$B,G$4,Consolidated!$C:$C,G$5) -> 76738 | H9: =SUMIFS(Consolidated!$I:$I,Consolidated!$B:$B,H$4,Consolidated!$C:$C,H$5) -> 67278 | I9: =SUMIFS(Consolidated!$I:$I,Consolidated!$B:$B,I$4,Consolidated!$C:$C,I$5) -> 83376 | J9: =SUMIFS(Consolidated!$I:$I,Consolidated!$B:$B,J$4,Consolidated!$C:$C,J$5) -> 77931 | ... Q9: =SUMIFS(Consolidated!$I:$I,Consolidated!$B:$B,Q$4,Consolidated!$C:$C,Q$5) -> 71599
B10: M4 | C10: =SUMIFS(Consolidated!$J:$J,Consolidated!$B:$B,C$4,Consolidated!$C:$C,C$5) -> 71428 | D10: =SUMIFS(Consolidated!$J:$J,Consolidated!$B:$B,D$4,Consolidated!$C:$C,D$5) -> 59336 | E10: =SUMIFS(Consolidated!$J:$J,Consolidated!$B:$B,E$4,Consolidated!$C:$C,E$5) -> 79613 | F10: =SUMIFS(Consolidated!$J:$J,Consolidated!$B:$B,F$4,Consolidated!$C:$C,F$5) -> 71388 | G10: =SUMIFS(Consolidated!$J:$J,Consolidated!$B:$B,G$4,Consolidated!$C:$C,G$5) -> 76741 | H10: =SUMIFS(Consolidated!$J:$J,Consolidated!$B:$B,H$4,Consolidated!$C:$C,H$5) -> 67298 | I10: =SUMIFS(Consolidated!$J:$J,Consolidated!$B:$B,I$4,Consolidated!$C:$C,I$5) -> 83116 | J10: =SUMIFS(Consolidated!$J:$J,Consolidated!$B:$B,J$4,Consolidated!$C:$C,J$5) -> 77954 | ... Q10: =SUMIFS(Consolidated!$J:$J,Consolidated!$B:$B,Q$4,Consolidated!$C:$C,Q$5) -> 71386
B11: M5 | C11: =SUMIFS(Consolidated!$K:$K,Consolidated!$B:$B,C$4,Consolidated!$C:$C,C$5) -> 70060 | D11: =SUMIFS(Consolidated!$K:$K,Consolidated!$B:$B,D$4,Consolidated!$C:$C,D$5) -> 62532 | E11: =SUMIFS(Consolidated!$K:$K,Consolidated!$B:$B,E$4,Consolidated!$C:$C,E$5) -> 75376 | F11: =SUMIFS(Consolidated!$K:$K,Consolidated!$B:$B,F$4,Consolidated!$C:$C,F$5) -> 70823 | G11: =SUMIFS(Consolidated!$K:$K,Consolidated!$B:$B,G$4,Consolidated!$C:$C,G$5) -> 73655 | H11: =SUMIFS(Consolidated!$K:$K,Consolidated!$B:$B,H$4,Consolidated!$C:$C,H$5) -> 65980 | I11: =SUMIFS(Consolidated!$K:$K,Consolidated!$B:$B,I$4,Consolidated!$C:$C,I$5) -> 78782 | J11: =SUMIFS(Consolidated!$K:$K,Consolidated!$B:$B,J$4,Consolidated!$C:$C,J$5) -> 75943 | ... Q11: =SUMIFS(Consolidated!$K:$K,Consolidated!$B:$B,Q$4,Consolidated!$C:$C,Q$5) -> 66867
B12: M6 | C12: =SUMIFS(Consolidated!$L:$L,Consolidated!$B:$B,C$4,Consolidated!$C:$C,C$5) -> 63584 | D12: =SUMIFS(Consolidated!$L:$L,Consolidated!$B:$B,D$4,Consolidated!$C:$C,D$5) -> 77838 | E12: =SUMIFS(Consolidated!$L:$L,Consolidated!$B:$B,E$4,Consolidated!$C:$C,E$5) -> 58330 | F12: =SUMIFS(Consolidated!$L:$L,Consolidated!$B:$B,F$4,Consolidated!$C:$C,F$5) -> 81731 | G12: =SUMIFS(Consolidated!$L:$L,Consolidated!$B:$B,G$4,Consolidated!$C:$C,G$5) -> 57672 | H12: =SUMIFS(Consolidated!$L:$L,Consolidated!$B:$B,H$4,Consolidated!$C:$C,H$5) -> 60920 | I12: =SUMIFS(Consolidated!$L:$L,Consolidated!$B:$B,I$4,Consolidated!$C:$C,I$5) -> 89410 | J12: =SUMIFS(Consolidated!$L:$L,Consolidated!$B:$B,J$4,Consolidated!$C:$C,J$5) -> 66922 | ... Q12: =SUMIFS(Consolidated!$L:$L,Consolidated!$B:$B,Q$4,Consolidated!$C:$C,Q$5) -> 64540
B13: M7 | C13: =SUMIFS(Consolidated!$M:$M,Consolidated!$B:$B,C$4,Consolidated!$C:$C,C$5) -> 70335 | D13: =SUMIFS(Consolidated!$M:$M,Consolidated!$B:$B,D$4,Consolidated!$C:$C,D$5) -> 63165 | E13: =SUMIFS(Consolidated!$M:$M,Consolidated!$B:$B,E$4,Consolidated!$C:$C,E$5) -> 75633 | F13: =SUMIFS(Consolidated!$M:$M,Consolidated!$B:$B,F$4,Consolidated!$C:$C,F$5) -> 70957 | G13: =SUMIFS(Consolidated!$M:$M,Consolidated!$B:$B,G$4,Consolidated!$C:$C,G$5) -> 73963 | H13: =SUMIFS(Consolidated!$M:$M,Consolidated!$B:$B,H$4,Consolidated!$C:$C,H$5) -> 66271 | I13: =SUMIFS(Consolidated!$M:$M,Consolidated!$B:$B,I$4,Consolidated!$C:$C,I$5) -> 78756 | J13: =SUMIFS(Consolidated!$M:$M,Consolidated!$B:$B,J$4,Consolidated!$C:$C,J$5) -> 75987 | ... Q13: =SUMIFS(Consolidated!$M:$M,Consolidated!$B:$B,Q$4,Consolidated!$C:$C,Q$5) -> 67336
B14: M6xM7 | C14: =SUMIFS(Consolidated!$N:$N,Consolidated!$B:$B,C$4,Consolidated!$C:$C,C$5) -> 68703 | D14: =SUMIFS(Consolidated!$N:$N,Consolidated!$B:$B,D$4,Consolidated!$C:$C,D$5) -> 82055 | E14: =SUMIFS(Consolidated!$N:$N,Consolidated!$B:$B,E$4,Consolidated!$C:$C,E$5) -> 77422 | F14: =SUMIFS(Consolidated!$N:$N,Consolidated!$B:$B,F$4,Consolidated!$C:$C,F$5) -> 71216 | G14: =SUMIFS(Consolidated!$N:$N,Consolidated!$B:$B,G$4,Consolidated!$C:$C,G$5) -> 66720 | H14: =SUMIFS(Consolidated!$N:$N,Consolidated!$B:$B,H$4,Consolidated!$C:$C,H$5) -> 64345 | I14: =SUMIFS(Consolidated!$N:$N,Consolidated!$B:$B,I$4,Consolidated!$C:$C,I$5) -> 74007 | J14: =SUMIFS(Consolidated!$N:$N,Consolidated!$B:$B,J$4,Consolidated!$C:$C,J$5) -> 76969 | ... Q14: =SUMIFS(Consolidated!$N:$N,Consolidated!$B:$B,Q$4,Consolidated!$C:$C,Q$5) -> 54239
A15: MSE
B16: M1 | C16: =(C7-C$6)^2 -> 401000625 | D16: =(D7-D$6)^2 -> 600625 | E16: =(E7-E$6)^2 -> 73393489 | F16: =(F7-F$6)^2 -> 97871449 | G16: =(G7-G$6)^2 -> 1075369 | H16: =(H7-H$6)^2 -> 276922881 | I16: =(I7-I$6)^2 -> 4198401 | J16: =(J7-J$6)^2 -> 11512449 | ... Q16: =(Q7-Q$6)^2 -> 421686225 | S16: =SQRT(AVERAGE(C16:Q16)) -> 10684.174
B17: M2 | C17: =(C8-C$6)^2 -> 369331524 | D17: =(D8-D$6)^2 -> 76387600 | E17: =(E8-E$6)^2 -> 44422225 | F17: =(F8-F$6)^2 -> 25452025 | G17: =(G8-G$6)^2 -> 108900 | H17: =(H8-H$6)^2 -> 124746561 | I17: =(I8-I$6)^2 -> 5832225 | J17: =(J8-J$6)^2 -> 622521 | ... Q17: =(Q8-Q$6)^2 -> 425266884 | S17: =SQRT(AVERAGE(C17:Q17)) -> 9233.8631
B18: M3 | C18: =(C9-C$6)^2 -> 316911204 | D18: =(D9-D$6)^2 -> 63218401 | E18: =(E9-E$6)^2 -> 5400976 | F18: =(F9-F$6)^2 -> 36796356 | G18: =(G9-G$6)^2 -> 5499025 | H18: =(H9-H$6)^2 -> 70896400 | I18: =(I9-I$6)^2 -> 59490369 | J18: =(J9-J$6)^2 -> 1096209 | ... Q18: =(Q9-Q$6)^2 -> 14085009 | S18: =SQRT(AVERAGE(C18:Q18)) -> 6739.5612
B19: M4 | C19: =(C10-C$6)^2 -> 306180004 | D19: =(D10-D$6)^2 -> 63856081 | E19: =(E10-E$6)^2 -> 6210064 | F19: =(F10-F$6)^2 -> 38291344 | G19: =(G10-G$6)^2 -> 5513104 | H19: =(H10-H$6)^2 -> 71233600 | I19: =(I10-I$6)^2 -> 55547209 | J19: =(J10-J$6)^2 -> 1048576 | ... Q19: =(Q10-Q$6)^2 -> 12531600 | S19: =SQRT(AVERAGE(C19:Q19)) -> 6683.1995
B20: M5 | C20: =(C11-C$6)^2 -> 260176900 | D20: =(D11-D$6)^2 -> 22992025 | E20: =(E11-E$6)^2 -> 3045025 | F20: =(F11-F$6)^2 -> 31618129 | G20: =(G11-G$6)^2 -> 544644 | H20: =(H11-H$6)^2 -> 50722884 | I20: =(I11-I$6)^2 -> 9728161 | J20: =(J11-J$6)^2 -> 9211225 | ... Q20: =(Q11-Q$6)^2 -> 958441 | S20: =SQRT(AVERAGE(C20:Q20)) -> 5947.848
B21: M6 | C21: =(C12-C$6)^2 -> 93199716 | D21: =(D12-D$6)^2 -> 110481121 | E21: =(E12-E$6)^2 -> 353101681 | F21: =(F12-F$6)^2 -> 273273961 | G21: =(G12-G$6)^2 -> 279591841 | H21: =(H12-H$6)^2 -> 4251844 | I21: =(I12-I$6)^2 -> 188980009 | J21: =(J12-J$6)^2 -> 145347136 | ... Q21: =(Q12-Q$6)^2 -> 10929636 | S21: =SQRT(AVERAGE(C21:Q21)) -> 11946.335
B22: M7 | C22: =(C13-C$6)^2 -> 269124025 | D22: =(D13-D$6)^2 -> 17322244 | E22: =(E13-E$6)^2 -> 2214144 | F22: =(F13-F$6)^2 -> 33143049 | G22: =(G13-G$6)^2 -> 184900 | H22: =(H13-H$6)^2 -> 54952569 | I22: =(I13-I$6)^2 -> 9566649 | J22: =(J13-J$6)^2 -> 8946081 | ... Q22: =(Q13-Q$6)^2 -> 260100 | S22: =SQRT(AVERAGE(C22:Q22)) -> 5925.1205
B23: M6xM7 | C23: =(C14-C$6)^2 -> 218241529 | D23: =(D14-D$6)^2 -> 216913984 | E23: =(E14-E$6)^2 -> 90601 | F23: =(F14-F$6)^2 -> 36192256 | G23: =(G14-G$6)^2 -> 58874929 | H23: =(H14-H$6)^2 -> 30107169 | I23: =(I14-I$6)^2 -> 2742336 | J23: =(J14-J$6)^2 -> 4036081 | ... Q23: =(Q14-Q$6)^2 -> 185150449 | S23: =SQRT(AVERAGE(C23:Q23)) -> 8754.4141
A58: Monthly Seasonality Cross-Validation
B60: Day | C60: 1 | D60: =C60+1 -> 2 | E60: =D60+1 -> 3 | F60: =E60+1 -> 4 | G60: =F60+1 -> 5 | H60: =G60+1 -> 6 | I60: =H60+1 -> 7 | J60: =I60+1 -> 8 | K60: =J60+1 -> 9 | ... AG60: =AF60+1 -> 31
B61: Actual | C61: =AVERAGEIFS(Consolidated!$F:$F,Consolidated!$D:$D,C$60) -> 385.53333 | D61: =AVERAGEIFS(Consolidated!$F:$F,Consolidated!$D:$D,D$60) -> 454.33333 | E61: =AVERAGEIFS(Consolidated!$F:$F,Consolidated!$D:$D,E$60) -> 558.4 | F61: =AVERAGEIFS(Consolidated!$F:$F,Consolidated!$D:$D,F$60) -> 654.4 | G61: =AVERAGEIFS(Consolidated!$F:$F,Consolidated!$D:$D,G$60) -> 755.46667 | H61: =AVERAGEIFS(Consolidated!$F:$F,Consolidated!$D:$D,H$60) -> 865.6 | I61: =AVERAGEIFS(Consolidated!$F:$F,Consolidated!$D:$D,I$60) -> 822.66667 | J61: =AVERAGEIFS(Consolidated!$F:$F,Consolidated!$D:$D,J$60) -> 875.26667 | ... AG61: =AVERAGEIFS(Consolidated!$F:$F,Consolidated!$D:$D,AG$60) -> 8048.5556
B62: M1 | C62: =AVERAGEIFS(Consolidated!$G:$G,Consolidated!$D:$D,C$60) -> 2482.0667 | D62: =AVERAGEIFS(Consolidated!$G:$G,Consolidated!$D:$D,D$60) -> 2754.4 | E62: =AVERAGEIFS(Consolidated!$G:$G,Consolidated!$D:$D,E$60) -> 2975 | F62: =AVERAGEIFS(Consolidated!$G:$G,Consolidated!$D:$D,F$60) -> 2882 | G62: =AVERAGEIFS(Consolidated!$G:$G,Consolidated!$D:$D,G$60) -> 2823.3333 | H62: =AVERAGEIFS(Consolidated!$G:$G,Consolidated!$D:$D,H$60) -> 2831.0667 | I62: =AVERAGEIFS(Consolidated!$G:$G,Consolidated!$D:$D,I$60) -> 2660.5333 | J62: =AVERAGEIFS(Consolidated!$G:$G,Consolidated!$D:$D,J$60) -> 2446.3333 | ... AG62: =AVERAGEIFS(Consolidated!$G:$G,Consolidated!$D:$D,AG$60) -> 2378.2222
B63: M2 | C63: =AVERAGEIFS(Consolidated!$H:$H,Consolidated!$D:$D,C$60) -> 4603.4667 | D63: =AVERAGEIFS(Consolidated!$H:$H,Consolidated!$D:$D,D$60) -> 3469.0667 | E63: =AVERAGEIFS(Consolidated!$H:$H,Consolidated!$D:$D,E$60) -> 2075.3333 | F63: =AVERAGEIFS(Consolidated!$H:$H,Consolidated!$D:$D,F$60) -> 1295.5333 | G63: =AVERAGEIFS(Consolidated!$H:$H,Consolidated!$D:$D,G$60) -> 1051.2 | H63: =AVERAGEIFS(Consolidated!$H:$H,Consolidated!$D:$D,H$60) -> 1217.4667 | I63: =AVERAGEIFS(Consolidated!$H:$H,Consolidated!$D:$D,I$60) -> 1236.8 | J63: =AVERAGEIFS(Consolidated!$H:$H,Consolidated!$D:$D,J$60) -> 1203.4 | ... AG63: =AVERAGEIFS(Consolidated!$H:$H,Consolidated!$D:$D,AG$60) -> 5540.5556
B64: M3 | C64: =AVERAGEIFS(Consolidated!$I:$I,Consolidated!$D:$D,C$60) -> 4041.4667 | D64: =AVERAGEIFS(Consolidated!$I:$I,Consolidated!$D:$D,D$60) -> 3444.6667 | E64: =AVERAGEIFS(Consolidated!$I:$I,Consolidated!$D:$D,E$60) -> 2119.2667 | F64: =AVERAGEIFS(Consolidated!$I:$I,Consolidated!$D:$D,F$60) -> 1368.9333 | G64: =AVERAGEIFS(Consolidated!$I:$I,Consolidated!$D:$D,G$60) -> 1091.0667 | H64: =AVERAGEIFS(Consolidated!$I:$I,Consolidated!$D:$D,H$60) -> 1223.5333 | I64: =AVERAGEIFS(Consolidated!$I:$I,Consolidated!$D:$D,I$60) -> 1226.9333 | J64: =AVERAGEIFS(Consolidated!$I:$I,Consolidated!$D:$D,J$60) -> 1153.8 | ... AG64: =AVERAGEIFS(Consolidated!$I:$I,Consolidated!$D:$D,AG$60) -> 5326.3333
B65: M4 | C65: =AVERAGEIFS(Consolidated!$J:$J,Consolidated!$D:$D,C$60) -> 4038.9333 | D65: =AVERAGEIFS(Consolidated!$J:$J,Consolidated!$D:$D,D$60) -> 3442.1333 | E65: =AVERAGEIFS(Consolidated!$J:$J,Consolidated!$D:$D,E$60) -> 2120.3333 | F65: =AVERAGEIFS(Consolidated!$J:$J,Consolidated!$D:$D,F$60) -> 1369.3333 | G65: =AVERAGEIFS(Consolidated!$J:$J,Consolidated!$D:$D,G$60) -> 1089.8667 | H65: =AVERAGEIFS(Consolidated!$J:$J,Consolidated!$D:$D,H$60) -> 1221.7333 | I65: =AVERAGEIFS(Consolidated!$J:$J,Consolidated!$D:$D,I$60) -> 1224.6 | J65: =AVERAGEIFS(Consolidated!$J:$J,Consolidated!$D:$D,J$60) -> 1153.5333 | ... AG65: =AVERAGEIFS(Consolidated!$J:$J,Consolidated!$D:$D,AG$60) -> 5322.5556
B66: M5 | C66: =AVERAGEIFS(Consolidated!$K:$K,Consolidated!$D:$D,C$60) -> 1197.2667 | D66: =AVERAGEIFS(Consolidated!$K:$K,Consolidated!$D:$D,D$60) -> 1310.9333 | E66: =AVERAGEIFS(Consolidated!$K:$K,Consolidated!$D:$D,E$60) -> 1189.7333 | F66: =AVERAGEIFS(Consolidated!$K:$K,Consolidated!$D:$D,F$60) -> 1186.6667 | G66: =AVERAGEIFS(Consolidated!$K:$K,Consolidated!$D:$D,G$60) -> 1159.4667 | H66: =AVERAGEIFS(Consolidated!$K:$K,Consolidated!$D:$D,H$60) -> 1184.7333 | I66: =AVERAGEIFS(Consolidated!$K:$K,Consolidated!$D:$D,I$60) -> 1017.3333 | J66: =AVERAGEIFS(Consolidated!$K:$K,Consolidated!$D:$D,J$60) -> 1335.5333 | ... AG66: =AVERAGEIFS(Consolidated!$K:$K,Consolidated!$D:$D,AG$60) -> 8513.4444
B67: M6 | C67: =AVERAGEIFS(Consolidated!$L:$L,Consolidated!$D:$D,C$60) -> 370.06667 | D67: =AVERAGEIFS(Consolidated!$L:$L,Consolidated!$D:$D,D$60) -> 394.26667 | E67: =AVERAGEIFS(Consolidated!$L:$L,Consolidated!$D:$D,E$60) -> 658.06667 | F67: =AVERAGEIFS(Consolidated!$L:$L,Consolidated!$D:$D,F$60) -> 646.26667 | G67: =AVERAGEIFS(Consolidated!$L:$L,Consolidated!$D:$D,G$60) -> 598.93333 | H67: =AVERAGEIFS(Consolidated!$L:$L,Consolidated!$D:$D,H$60) -> 614.4 | I67: =AVERAGEIFS(Consolidated!$L:$L,Consolidated!$D:$D,I$60) -> 592.2 | J67: =AVERAGEIFS(Consolidated!$L:$L,Consolidated!$D:$D,J$60) -> 1035.0667 | ... AG67: =AVERAGEIFS(Consolidated!$L:$L,Consolidated!$D:$D,AG$60) -> 11145
B68: M7 | C68: =AVERAGEIFS(Consolidated!$M:$M,Consolidated!$D:$D,C$60) -> 1172.5333 | D68: =AVERAGEIFS(Consolidated!$M:$M,Consolidated!$D:$D,D$60) -> 1167.6667 | E68: =AVERAGEIFS(Consolidated!$M:$M,Consolidated!$D:$D,E$60) -> 1167.2 | F68: =AVERAGEIFS(Consolidated!$M:$M,Consolidated!$D:$D,F$60) -> 1233.3333 | G68: =AVERAGEIFS(Consolidated!$M:$M,Consolidated!$D:$D,G$60) -> 1142.8 | H68: =AVERAGEIFS(Consolidated!$M:$M,Consolidated!$D:$D,H$60) -> 1150.0667 | I68: =AVERAGEIFS(Consolidated!$M:$M,Consolidated!$D:$D,I$60) -> 1005.1333 | J68: =AVERAGEIFS(Consolidated!$M:$M,Consolidated!$D:$D,J$60) -> 1372.1333 | ... AG68: =AVERAGEIFS(Consolidated!$M:$M,Consolidated!$D:$D,AG$60) -> 8645.5556
B69: M6xM7 | C69: =AVERAGEIFS(Consolidated!$N:$N,Consolidated!$D:$D,C$60) -> 370.06667 | D69: =AVERAGEIFS(Consolidated!$N:$N,Consolidated!$D:$D,D$60) -> 394.26667 | E69: =AVERAGEIFS(Consolidated!$N:$N,Consolidated!$D:$D,E$60) -> 658.06667 | F69: =AVERAGEIFS(Consolidated!$N:$N,Consolidated!$D:$D,F$60) -> 646.26667 | G69: =AVERAGEIFS(Consolidated!$N:$N,Consolidated!$D:$D,G$60) -> 707.73333 | H69: =AVERAGEIFS(Consolidated!$N:$N,Consolidated!$D:$D,H$60) -> 882.46667 | I69: =AVERAGEIFS(Consolidated!$N:$N,Consolidated!$D:$D,I$60) -> 798.93333 | J69: =AVERAGEIFS(Consolidated!$N:$N,Consolidated!$D:$D,J$60) -> 1203.8 | ... AG69: =AVERAGEIFS(Consolidated!$N:$N,Consolidated!$D:$D,AG$60) -> 8645.5556
A70: MSE
B71: M1 | C71: =(C62-C$61)^2 -> 4395452 | D71: =(D62-D$61)^2 -> 5290306.7 | E71: =(E62-E$61)^2 -> 5839955.6 | F71: =(F62-F$61)^2 -> 4962201.8 | G71: =(G62-G$61)^2 -> 4276072.6 | H71: =(H62-H$61)^2 -> 3863059.2 | I71: =(I62-I$61)^2 -> 3377753.9 | J71: =(J62-J$61)^2 -> 2468250.5 | ... AG71: =(AG62-AG$61)^2 -> 32152680 | AI71: =SQRT(AVERAGE(C71:AG71)) -> 2090.566
B72: M2 | C72: =(C63-C$61)^2 -> 17790962 | D72: =(D63-D$61)^2 -> 9088617.1 | E72: =(E63-E$61)^2 -> 2301086.7 | F72: =(F63-F$61)^2 -> 411051.95 | G72: =(G63-G$61)^2 -> 87458.204 | H72: =(H63-H$61)^2 -> 123810.15 | I72: =(I63-I$61)^2 -> 171506.42 | J72: =(J63-J$61)^2 -> 107671.48 | ... AG72: =(AG63-AG$61)^2 -> 6290064 | AI72: =SQRT(AVERAGE(C72:AG72)) -> 1218.4412
B73: M3 | C73: =(C64-C$61)^2 -> 13365849 | D73: =(D64-D$61)^2 -> 8942093.4 | E73: =(E64-E$61)^2 -> 2436304.8 | F73: =(F64-F$61)^2 -> 510557.88 | G73: =(G64-G$61)^2 -> 112627.36 | H73: =(H64-H$61)^2 -> 128116.27 | I73: =(I64-I$61)^2 -> 163431.54 | J73: =(J64-J$61)^2 -> 77580.818 | ... AG73: =(AG64-AG$61)^2 -> 7410493.8 | AI73: =SQRT(AVERAGE(C73:AG73)) -> 1177.9276
B74: M4 | C74: =(C65-C$61)^2 -> 13347332 | D74: =(D65-D$61)^2 -> 8926948.8 | E74: =(E65-E$61)^2 -> 2439635.7 | F74: =(F65-F$61)^2 -> 511129.67 | G74: =(G65-G$61)^2 -> 111823.36 | H74: =(H65-H$61)^2 -> 126830.95 | I74: =(I65-I$61)^2 -> 161550.4 | J74: =(J65-J$61)^2 -> 77432.338 | ... AG74: =(AG65-AG$61)^2 -> 7431076 | AI74: =SQRT(AVERAGE(C74:AG74)) -> 1178.349
B75: M5 | C75: =(C66-C$61)^2 -> 658911 | D75: =(D66-D$61)^2 -> 733763.56 | E75: =(E66-E$61)^2 -> 398581.78 | F75: =(F66-F$61)^2 -> 283307.8 | G75: =(G66-G$61)^2 -> 163216 | H75: =(H66-H$61)^2 -> 101846.08 | I75: =(I66-I$61)^2 -> 37895.111 | J75: =(J66-J$61)^2 -> 211845.4 | ... AG75: =(AG66-AG$61)^2 -> 216121.68 | AI75: =SQRT(AVERAGE(C75:AG75)) -> 437.39896
B76: M6 | C76: =(C67-C$61)^2 -> 239.21778 | D76: =(D67-D$61)^2 -> 3608.0044 | E76: =(E67-E$61)^2 -> 9933.4444 | F76: =(F67-F$61)^2 -> 66.151111 | G76: =(G67-G$61)^2 -> 24502.684 | H76: =(H67-H$61)^2 -> 63101.44 | I76: =(I67-I$61)^2 -> 53114.884 | J76: =(J67-J$61)^2 -> 25536.04 | ... AG76: =(AG67-AG$61)^2 -> 9587968.2 | AI76: =SQRT(AVERAGE(C76:AG76)) -> 678.38799
B77: M7 | C77: =(C68-C$61)^2 -> 619369 | D77: =(D68-D$61)^2 -> 508844.44 | E77: =(E68-E$61)^2 -> 370637.44 | F77: =(F68-F$61)^2 -> 335163.8 | G77: =(G68-G$61)^2 -> 150027.11 | H77: =(H68-H$61)^2 -> 80921.284 | I77: =(I68-I$61)^2 -> 33294.084 | J77: =(J68-J$61)^2 -> 246876.48 | ... AG77: =(AG68-AG$61)^2 -> 356409 | AI77: =SQRT(AVERAGE(C77:AG77)) -> 432.68091
...

Sheet Consolidated
A1: Date | B1: Year | C1: Month | D1: Day | E1: Cutoff | F1: Actual | G1: M1 | H1: M2 | I1: M3 | J1: M4 | K1: M5 | L1: M6 | M1: M7 | N1: M6xM7
A2: 45658 | B2: =YEAR($A2) -> 2025 | C2: =MONTH($A2) -> 1 | D2: =DAY($A2) -> 1 | E2: =DATE($B2,$C2,1)-1 -> 45657 | F2: =_xlfn.XLOOKUP($A2,m1_cv!$B:$B,m1_cv!$C:$C) -> 90 | G2: =MAX(0,ROUND(SUMIFS(m1_cv!$E:$E,m1_cv!$A:$A,$E2,m1_cv!$B:$B,$A2),0)) -> 3522 | H2: =MAX(0,ROUND(SUMIFS(m2_cv!$E:$E,m2_cv!$A:$A,$E2,m2_cv!$B:$B,$A2),0)) -> 4096 | I2: =MAX(0,ROUND(SUMIFS(m3_cv!$E:$E,m3_cv!$A:$A,$E2,m3_cv!$B:$B,$A2),0)) -> 2895 | J2: =MAX(0,ROUND(SUMIFS(m4_cv!$E:$E,m4_cv!$A:$A,$E2,m4_cv!$B:$B,$A2),0)) -> 2889 | K2: =MAX(0,ROUND(SUMIFS(m5_cv!$E:$E,m5_cv!$A:$A,$E2,m5_cv!$B:$B,$A2),0)) -> 642 | L2: =MAX(0,ROUND(SUMIFS(m6_cv!$E:$E,m6_cv!$A:$A,$E2,m6_cv!$B:$B,$A2),0)) -> 94 | M2: =MAX(0,ROUND(SUMIFS(m7_cv!$E:$E,m7_cv!$A:$A,$E2,m7_cv!$B:$B,$A2),0)) -> 536 | N2: =ROUND(_xlfn.XLOOKUP($D2,Charts!$W$82:$W$112,Charts!$X$82:$X$112)*$L2+_xlfn.XLOOKUP($D2,Charts!$W$82:$W$112,Charts!$Y$82:$Y$112)*$M2,0) -> 94
A3: =A2+1 -> 45659 | B3: =YEAR(A3) -> 2025 | C3: =MONTH($A3) -> 1 | D3: =DAY($A3) -> 2 | E3: =DATE($B3,$C3,1)-1 -> 45657 | F3: =_xlfn.XLOOKUP($A3,m1_cv!$B:$B,m1_cv!$C:$C) -> 541 | G3: =MAX(0,ROUND(SUMIFS(m1_cv!$E:$E,m1_cv!$A:$A,$E3,m1_cv!$B:$B,$A3),0)) -> 3467 | H3: =MAX(0,ROUND(SUMIFS(m2_cv!$E:$E,m2_cv!$A:$A,$E3,m2_cv!$B:$B,$A3),0)) -> 2253 | I3: =MAX(0,ROUND(SUMIFS(m3_cv!$E:$E,m3_cv!$A:$A,$E3,m3_cv!$B:$B,$A3),0)) -> 2572 | J3: =MAX(0,ROUND(SUMIFS(m4_cv!$E:$E,m4_cv!$A:$A,$E3,m4_cv!$B:$B,$A3),0)) -> 2563 | K3: =MAX(0,ROUND(SUMIFS(m5_cv!$E:$E,m5_cv!$A:$A,$E3,m5_cv!$B:$B,$A3),0)) -> 1719 | L3: =MAX(0,ROUND(SUMIFS(m6_cv!$E:$E,m6_cv!$A:$A,$E3,m6_cv!$B:$B,$A3),0)) -> 556 | M3: =MAX(0,ROUND(SUMIFS(m7_cv!$E:$E,m7_cv!$A:$A,$E3,m7_cv!$B:$B,$A3),0)) -> 1817 | N3: =ROUND(_xlfn.XLOOKUP($D3,Charts!$W$82:$W$112,Charts!$X$82:$X$112)*$L3+_xlfn.XLOOKUP($D3,Charts!$W$82:$W$112,Charts!$Y$82:$Y$112)*$M3,0) -> 556
A4: =A3+1 -> 45660 | B4: =YEAR(A4) -> 2025 | C4: =MONTH($A4) -> 1 | D4: =DAY($A4) -> 3 | E4: =DATE($B4,$C4,1)-1 -> 45657 | F4: =_xlfn.XLOOKUP($A4,m1_cv!$B:$B,m1_cv!$C:$C) -> 563 | G4: =MAX(0,ROUND(SUMIFS(m1_cv!$E:$E,m1_cv!$A:$A,$E4,m1_cv!$B:$B,$A4),0)) -> 3307 | H4: =MAX(0,ROUND(SUMIFS(m2_cv!$E:$E,m2_cv!$A:$A,$E4,m2_cv!$B:$B,$A4),0)) -> 1153 | I4: =MAX(0,ROUND(SUMIFS(m3_cv!$E:$E,m3_cv!$A:$A,$E4,m3_cv!$B:$B,$A4),0)) -> 1356 | J4: =MAX(0,ROUND(SUMIFS(m4_cv!$E:$E,m4_cv!$A:$A,$E4,m4_cv!$B:$B,$A4),0)) -> 1348 | K4: =MAX(0,ROUND(SUMIFS(m5_cv!$E:$E,m5_cv!$A:$A,$E4,m5_cv!$B:$B,$A4),0)) -> 1735 | L4: =MAX(0,ROUND(SUMIFS(m6_cv!$E:$E,m6_cv!$A:$A,$E4,m6_cv!$B:$B,$A4),0)) -> 649 | M4: =MAX(0,ROUND(SUMIFS(m7_cv!$E:$E,m7_cv!$A:$A,$E4,m7_cv!$B:$B,$A4),0)) -> 1861 | N4: =ROUND(_xlfn.XLOOKUP($D4,Charts!$W$82:$W$112,Charts!$X$82:$X$112)*$L4+_xlfn.XLOOKUP($D4,Charts!$W$82:$W$112,Charts!$Y$82:$Y$112)*$M4,0) -> 649
A5: =A4+1 -> 45661 | B5: =YEAR(A5) -> 2025 | C5: =MONTH($A5) -> 1 | D5: =DAY($A5) -> 4 | E5: =DATE($B5,$C5,1)-1 -> 45657 | F5: =_xlfn.XLOOKUP($A5,m1_cv!$B:$B,m1_cv!$C:$C) -> 42 | G5: =MAX(0,ROUND(SUMIFS(m1_cv!$E:$E,m1_cv!$A:$A,$E5,m1_cv!$B:$B,$A5),0)) -> 1098 | H5: =MAX(0,ROUND(SUMIFS(m2_cv!$E:$E,m2_cv!$A:$A,$E5,m2_cv!$B:$B,$A5),0)) -> 0 | I5: =MAX(0,ROUND(SUMIFS(m3_cv!$E:$E,m3_cv!$A:$A,$E5,m3_cv!$B:$B,$A5),0)) -> 0 | J5: =MAX(0,ROUND(SUMIFS(m4_cv!$E:$E,m4_cv!$A:$A,$E5,m4_cv!$B:$B,$A5),0)) -> 0 | K5: =MAX(0,ROUND(SUMIFS(m5_cv!$E:$E,m5_cv!$A:$A,$E5,m5_cv!$B:$B,$A5),0)) -> 0 | L5: =MAX(0,ROUND(SUMIFS(m6_cv!$E:$E,m6_cv!$A:$A,$E5,m6_cv!$B:$B,$A5),0)) -> 112 | M5: =MAX(0,ROUND(SUMIFS(m7_cv!$E:$E,m7_cv!$A:$A,$E5,m7_cv!$B:$B,$A5),0)) -> 0 | N5: =ROUND(_xlfn.XLOOKUP($D5,Charts!$W$82:$W$112,Charts!$X$82:$X$112)*$L5+_xlfn.XLOOKUP($D5,Charts!$W$82:$W$112,Charts!$Y$82:$Y$112)*$M5,0) -> 112
A6: =A5+1 -> 45662 | B6: =YEAR(A6) -> 2025 | C6: =MONTH($A6) -> 1 | D6: =DAY($A6) -> 5 | E6: =DATE($B6,$C6,1)-1 -> 45657 | F6: =_xlfn.XLOOKUP($A6,m1_cv!$B:$B,m1_cv!$C:$C) -> 22 | G6: =MAX(0,ROUND(SUMIFS(m1_cv!$E:$E,m1_cv!$A:$A,$E6,m1_cv!$B:$B,$A6),0)) -> 505 | H6: =MAX(0,ROUND(SUMIFS(m2_cv!$E:$E,m2_cv!$A:$A,$E6,m2_cv!$B:$B,$A6),0)) -> 0 | I6: =MAX(0,ROUND(SUMIFS(m3_cv!$E:$E,m3_cv!$A:$A,$E6,m3_cv!$B:$B,$A6),0)) -> 0 | J6: =MAX(0,ROUND(SUMIFS(m4_cv!$E:$E,m4_cv!$A:$A,$E6,m4_cv!$B:$B,$A6),0)) -> 0 | K6: =MAX(0,ROUND(SUMIFS(m5_cv!$E:$E,m5_cv!$A:$A,$E6,m5_cv!$B:$B,$A6),0)) -> 0 | L6: =MAX(0,ROUND(SUMIFS(m6_cv!$E:$E,m6_cv!$A:$A,$E6,m6_cv!$B:$B,$A6),0)) -> 49 | M6: =MAX(0,ROUND(SUMIFS(m7_cv!$E:$E,m7_cv!$A:$A,$E6,m7_cv!$B:$B,$A6),0)) -> 0 | N6: =ROUND(_xlfn.XLOOKUP($D6,Charts!$W$82:$W$112,Charts!$X$82:$X$112)*$L6+_xlfn.XLOOKUP($D6,Charts!$W$82:$W$112,Charts!$Y$82:$Y$112)*$M6,0) -> 39
A7: =A6+1 -> 45663 | B7: =YEAR(A7) -> 2025 | C7: =MONTH($A7) -> 1 | D7: =DAY($A7) -> 6 | E7: =DATE($B7,$C7,1)-1 -> 45657 | F7: =_xlfn.XLOOKUP($A7,m1_cv!$B:$B,m1_cv!$C:$C) -> 533 | G7: =MAX(0,ROUND(SUMIFS(m1_cv!$E:$E,m1_cv!$A:$A,$E7,m1_cv!$B:$B,$A7),0)) -> 2745 | H7: =MAX(0,ROUND(SUMIFS(m2_cv!$E:$E,m2_cv!$A:$A,$E7,m2_cv!$B:$B,$A7),0)) -> 1504 | I7: =MAX(0,ROUND(SUMIFS(m3_cv!$E:$E,m3_cv!$A:$A,$E7,m3_cv!$B:$B,$A7),0)) -> 1781 | J7: =MAX(0,ROUND(SUMIFS(m4_cv!$E:$E,m4_cv!$A:$A,$E7,m4_cv!$B:$B,$A7),0)) -> 1771 | K7: =MAX(0,ROUND(SUMIFS(m5_cv!$E:$E,m5_cv!$A:$A,$E7,m5_cv!$B:$B,$A7),0)) -> 1407 | L7: =MAX(0,ROUND(SUMIFS(m6_cv!$E:$E,m6_cv!$A:$A,$E7,m6_cv!$B:$B,$A7),0)) -> 606 | M7: =MAX(0,ROUND(SUMIFS(m7_cv!$E:$E,m7_cv!$A:$A,$E7,m7_cv!$B:$B,$A7),0)) -> 1439 | N7: =ROUND(_xlfn.XLOOKUP($D7,Charts!$W$82:$W$112,Charts!$X$82:$X$112)*$L7+_xlfn.XLOOKUP($D7,Charts!$W$82:$W$112,Charts!$Y$82:$Y$112)*$M7,0) -> 1023
A8: =A7+1 -> 45664 | B8: =YEAR(A8) -> 2025 | C8: =MONTH($A8) -> 1 | D8: =DAY($A8) -> 7 | E8: =DATE($B8,$C8,1)-1 -> 45657 | F8: =_xlfn.XLOOKUP($A8,m1_cv!$B:$B,m1_cv!$C:$C) -> 712 | G8: =MAX(0,ROUND(SUMIFS(m1_cv!$E:$E,m1_cv!$A:$A,$E8,m1_cv!$B:$B,$A8),0)) -> 3284 | H8: =MAX(0,ROUND(SUMIFS(m2_cv!$E:$E,m2_cv!$A:$A,$E8,m2_cv!$B:$B,$A8),0)) -> 2043 | I8: =MAX(0,ROUND(SUMIFS(m3_cv!$E:$E,m3_cv!$A:$A,$E8,m3_cv!$B:$B,$A8),0)) -> 2024 | J8: =MAX(0,ROUND(SUMIFS(m4_cv!$E:$E,m4_cv!$A:$A,$E8,m4_cv!$B:$B,$A8),0)) -> 2016 | K8: =MAX(0,ROUND(SUMIFS(m5_cv!$E:$E,m5_cv!$A:$A,$E8,m5_cv!$B:$B,$A8),0)) -> 1505 | L8: =MAX(0,ROUND(SUMIFS(m6_cv!$E:$E,m6_cv!$A:$A,$E8,m6_cv!$B:$B,$A8),0)) -> 706 | M8: =MAX(0,ROUND(SUMIFS(m7_cv!$E:$E,m7_cv!$A:$A,$E8,m7_cv!$B:$B,$A8),0)) -> 1636 | N8: =ROUND(_xlfn.XLOOKUP($D8,Charts!$W$82:$W$112,Charts!$X$82:$X$112)*$L8+_xlfn.XLOOKUP($D8,Charts!$W$82:$W$112,Charts!$Y$82:$Y$112)*$M8,0) -> 1171
A9: =A8+1 -> 45665 | B9: =YEAR(A9) -> 2025 | C9: =MONTH($A9) -> 1 | D9: =DAY($A9) -> 8 | E9: =DATE($B9,$C9,1)-1 -> 45657 | F9: =_xlfn.XLOOKUP($A9,m1_cv!$B:$B,m1_cv!$C:$C) -> 904 | G9: =MAX(0,ROUND(SUMIFS(m1_cv!$E:$E,m1_cv!$A:$A,$E9,m1_cv!$B:$B,$A9),0)) -> 3230 | H9: =MAX(0,ROUND(SUMIFS(m2_cv!$E:$E,m2_cv!$A:$A,$E9,m2_cv!$B:$B,$A9),0)) -> 1850 | I9: =MAX(0,ROUND(SUMIFS(m3_cv!$E:$E,m3_cv!$A:$A,$E9,m3_cv!$B:$B,$A9),0)) -> 1871 | J9: =MAX(0,ROUND(SUMIFS(m4_cv!$E:$E,m4_cv!$A:$A,$E9,m4_cv!$B:$B,$A9),0)) -> 1860 | K9: =MAX(0,ROUND(SUMIFS(m5_cv!$E:$E,m5_cv!$A:$A,$E9,m5_cv!$B:$B,$A9),0)) -> 2143 | L9: =MAX(0,ROUND(SUMIFS(m6_cv!$E:$E,m6_cv!$A:$A,$E9,m6_cv!$B:$B,$A9),0)) -> 1300 | M9: =MAX(0,ROUND(SUMIFS(m7_cv!$E:$E,m7_cv!$A:$A,$E9,m7_cv!$B:$B,$A9),0)) -> 2181 | N9: =ROUND(_xlfn.XLOOKUP($D9,Charts!$W$82:$W$112,Charts!$X$82:$X$112)*$L9+_xlfn.XLOOKUP($D9,Charts!$W$82:$W$112,Charts!$Y$82:$Y$112)*$M9,0) -> 1741
A10: =A9+1 -> 45666 | B10: =YEAR(A10) -> 2025 | C10: =MONTH($A10) -> 1 | D10: =DAY($A10) -> 9 | E10: =DATE($B10,$C10,1)-1 -> 45657 | F10: =_xlfn.XLOOKUP($A10,m1_cv!$B:$B,m1_cv!$C:$C) -> 1135 | G10: =MAX(0,ROUND(SUMIFS(m1_cv!$E:$E,m1_cv!$A:$A,$E10,m1_cv!$B:$B,$A10),0)) -> 3181 | H10: =MAX(0,ROUND(SUMIFS(m2_cv!$E:$E,m2_cv!$A:$A,$E10,m2_cv!$B:$B,$A10),0)) -> 1773 | I10: =MAX(0,ROUND(SUMIFS(m3_cv!$E:$E,m3_cv!$A:$A,$E10,m3_cv!$B:$B,$A10),0)) -> 1784 | J10: =MAX(0,ROUND(SUMIFS(m4_cv!$E:$E,m4_cv!$A:$A,$E10,m4_cv!$B:$B,$A10),0)) -> 1773 | K10: =MAX(0,ROUND(SUMIFS(m5_cv!$E:$E,m5_cv!$A:$A,$E10,m5_cv!$B:$B,$A10),0)) -> 2064 | L10: =MAX(0,ROUND(SUMIFS(m6_cv!$E:$E,m6_cv!$A:$A,$E10,m6_cv!$B:$B,$A10),0)) -> 1317 | M10: =MAX(0,ROUND(SUMIFS(m7_cv!$E:$E,m7_cv!$A:$A,$E10,m7_cv!$B:$B,$A10),0)) -> 1983 | N10: =ROUND(_xlfn.XLOOKUP($D10,Charts!$W$82:$W$112,Charts!$X$82:$X$112)*$L10+_xlfn.XLOOKUP($D10,Charts!$W$82:$W$112,Charts!$Y$82:$Y$112)*$M10,0) -> 1650
A11: =A10+1 -> 45667 | B11: =YEAR(A11) -> 2025 | C11: =MONTH($A11) -> 1 | D11: =DAY($A11) -> 10 | E11: =DATE($B11,$C11,1)-1 -> 45657 | F11: =_xlfn.XLOOKUP($A11,m1_cv!$B:$B,m1_cv!$C:$C) -> 1270 | G11: =MAX(0,ROUND(SUMIFS(m1_cv!$E:$E,m1_cv!$A:$A,$E11,m1_cv!$B:$B,$A11),0)) -> 3030 | H11: =MAX(0,ROUND(SUMIFS(m2_cv!$E:$E,m2_cv!$A:$A,$E11,m2_cv!$B:$B,$A11),0)) -> 1814 | I11: =MAX(0,ROUND(SUMIFS(m3_cv!$E:$E,m3_cv!$A:$A,$E11,m3_cv!$B:$B,$A11),0)) -> 1785 | J11: =MAX(0,ROUND(SUMIFS(m4_cv!$E:$E,m4_cv!$A:$A,$E11,m4_cv!$B:$B,$A11),0)) -> 1775 | K11: =MAX(0,ROUND(SUMIFS(m5_cv!$E:$E,m5_cv!$A:$A,$E11,m5_cv!$B:$B,$A11),0)) -> 1944 | L11: =MAX(0,ROUND(SUMIFS(m6_cv!$E:$E,m6_cv!$A:$A,$E11,m6_cv!$B:$B,$A11),0)) -> 1210 | M11: =MAX(0,ROUND(SUMIFS(m7_cv!$E:$E,m7_cv!$A:$A,$E11,m7_cv!$B:$B,$A11),0)) -> 1913 | N11: =ROUND(_xlfn.XLOOKUP($D11,Charts!$W$82:$W$112,Charts!$X$82:$X$112)*$L11+_xlfn.XLOOKUP($D11,Charts!$W$82:$W$112,Charts!$Y$82:$Y$112)*$M11,0) -> 1562
A12: =A11+1 -> 45668 | B12: =YEAR(A12) -> 2025 | C12: =MONTH($A12) -> 1 | D12: =DAY($A12) -> 11 | E12: =DATE($B12,$C12,1)-1 -> 45657 | F12: =_xlfn.XLOOKUP($A12,m1_cv!$B:$B,m1_cv!$C:$C) -> 203 | G12: =MAX(0,ROUND(SUMIFS(m1_cv!$E:$E,m1_cv!$A:$A,$E12,m1_cv!$B:$B,$A12),0)) -> 834 | H12: =MAX(0,ROUND(SUMIFS(m2_cv!$E:$E,m2_cv!$A:$A,$E12,m2_cv!$B:$B,$A12),0)) -> 0 | I12: =MAX(0,ROUND(SUMIFS(m3_cv!$E:$E,m3_cv!$A:$A,$E12,m3_cv!$B:$B,$A12),0)) -> 0 | J12: =MAX(0,ROUND(SUMIFS(m4_cv!$E:$E,m4_cv!$A:$A,$E12,m4_cv!$B:$B,$A12),0)) -> 0 | K12: =MAX(0,ROUND(SUMIFS(m5_cv!$E:$E,m5_cv!$A:$A,$E12,m5_cv!$B:$B,$A12),0)) -> 0 | L12: =MAX(0,ROUND(SUMIFS(m6_cv!$E:$E,m6_cv!$A:$A,$E12,m6_cv!$B:$B,$A12),0)) -> 225 | M12: =MAX(0,ROUND(SUMIFS(m7_cv!$E:$E,m7_cv!$A:$A,$E12,m7_cv!$B:$B,$A12),0)) -> 0 | N12: =ROUND(_xlfn.XLOOKUP($D12,Charts!$W$82:$W$112,Charts!$X$82:$X$112)*$L12+_xlfn.XLOOKUP($D12,Charts!$W$82:$W$112,Charts!$Y$82:$Y$112)*$M12,0) -> 68
A13: =A12+1 -> 45669 | B13: =YEAR(A13) -> 2025 | C13: =MONTH($A13) -> 1 | D13: =DAY($A13) -> 12 | E13: =DATE($B13,$C13,1)-1 -> 45657 | F13: =_xlfn.XLOOKUP($A13,m1_cv!$B:$B,m1_cv!$C:$C) -> 41 | G13: =MAX(0,ROUND(SUMIFS(m1_cv!$E:$E,m1_cv!$A:$A,$E13,m1_cv!$B:$B,$A13),0)) -> 257 | H13: =MAX(0,ROUND(SUMIFS(m2_cv!$E:$E,m2_cv!$A:$A,$E13,m2_cv!$B:$B,$A13),0)) -> 0 | I13: =MAX(0,ROUND(SUMIFS(m3_cv!$E:$E,m3_cv!$A:$A,$E13,m3_cv!$B:$B,$A13),0)) -> 0 | J13: =MAX(0,ROUND(SUMIFS(m4_cv!$E:$E,m4_cv!$A:$A,$E13,m4_cv!$B:$B,$A13),0)) -> 0 | K13: =MAX(0,ROUND(SUMIFS(m5_cv!$E:$E,m5_cv!$A:$A,$E13,m5_cv!$B:$B,$A13),0)) -> 0 | L13: =MAX(0,ROUND(SUMIFS(m6_cv!$E:$E,m6_cv!$A:$A,$E13,m6_cv!$B:$B,$A13),0)) -> 104 | M13: =MAX(0,ROUND(SUMIFS(m7_cv!$E:$E,m7_cv!$A:$A,$E13,m7_cv!$B:$B,$A13),0)) -> 0 | N13: =ROUND(_xlfn.XLOOKUP($D13,Charts!$W$82:$W$112,Charts!$X$82:$X$112)*$L13+_xlfn.XLOOKUP($D13,Charts!$W$82:$W$112,Charts!$Y$82:$Y$112)*$M13,0) -> 31
A14: =A13+1 -> 45670 | B14: =YEAR(A14) -> 2025 | C14: =MONTH($A14) -> 1 | D14: =DAY($A14) -> 13 | E14: =DATE($B14,$C14,1)-1 -> 45657 | F14: =_xlfn.XLOOKUP($A14,m1_cv!$B:$B,m1_cv!$C:$C) -> 1313 | G14: =MAX(0,ROUND(SUMIFS(m1_cv!$E:$E,m1_cv!$A:$A,$E14,m1_cv!$B:$B,$A14),0)) -> 2515 | H14: =MAX(0,ROUND(SUMIFS(m2_cv!$E:$E,m2_cv!$A:$A,$E14,m2_cv!$B:$B,$A14),0)) -> 1705 | I14: =MAX(0,ROUND(SUMIFS(m3_cv!$E:$E,m3_cv!$A:$A,$E14,m3_cv!$B:$B,$A14),0)) -> 1860 | J14: =MAX(0,ROUND(SUMIFS(m4_cv!$E:$E,m4_cv!$A:$A,$E14,m4_cv!$B:$B,$A14),0)) -> 1848 | K14: =MAX(0,ROUND(SUMIFS(m5_cv!$E:$E,m5_cv!$A:$A,$E14,m5_cv!$B:$B,$A14),0)) -> 1766 | L14: =MAX(0,ROUND(SUMIFS(m6_cv!$E:$E,m6_cv!$A:$A,$E14,m6_cv!$B:$B,$A14),0)) -> 1363 | M14: =MAX(0,ROUND(SUMIFS(m7_cv!$E:$E,m7_cv!$A:$A,$E14,m7_cv!$B:$B,$A14),0)) -> 1798 | N14: =ROUND(_xlfn.XLOOKUP($D14,Charts!$W$82:$W$112,Charts!$X$82:$X$112)*$L14+_xlfn.XLOOKUP($D14,Charts!$W$82:$W$112,Charts!$Y$82:$Y$112)*$M14,0) -> 1668
... A424: =A423+1 -> 46080 | B424: =YEAR(A424) -> 2026 | C424: =MONTH($A424) -> 2 | D424: =DAY($A424) -> 27 | E424: =DATE($B424,$C424,1)-1 -> 46053 | F424: =_xlfn.XLOOKUP($A424,m1_cv!$B:$B,m1_cv!$C:$C) -> 8803 | G424: =MAX(0,ROUND(SUMIFS(m1_cv!$E:$E,m1_cv!$A:$A,$E424,m1_cv!$B:$B,$A424),0)) -> 3417 | H424: =MAX(0,ROUND(SUMIFS(m2_cv!$E:$E,m2_cv!$A:$A,$E424,m2_cv!$B:$B,$A424),0)) -> 5151 | I424: =MAX(0,ROUND(SUMIFS(m3_cv!$E:$E,m3_cv!$A:$A,$E424,m3_cv!$B:$B,$A424),0)) -> 4922 | J424: =MAX(0,ROUND(SUMIFS(m4_cv!$E:$E,m4_cv!$A:$A,$E424,m4_cv!$B:$B,$A424),0)) -> 4918 | K424: =MAX(0,ROUND(SUMIFS(m5_cv!$E:$E,m5_cv!$A:$A,$E424,m5_cv!$B:$B,$A424),0)) -> 7423 | L424: =MAX(0,ROUND(SUMIFS(m6_cv!$E:$E,m6_cv!$A:$A,$E424,m6_cv!$B:$B,$A424),0)) -> 10564 | M424: =MAX(0,ROUND(SUMIFS(m7_cv!$E:$E,m7_cv!$A:$A,$E424,m7_cv!$B:$B,$A424),0)) -> 7344 | N424: =ROUND(_xlfn.XLOOKUP($D424,Charts!$W$82:$W$112,Charts!$X$82:$X$112)*$L424+_xlfn.XLOOKUP($D424,Charts!$W$82:$W$112,Charts!$Y$82:$Y$112)*$M424,0) -> 10564
A425: =A424+1 -> 46081 | B425: =YEAR(A425) -> 2026 | C425: =MONTH($A425) -> 2 | D425: =DAY($A425) -> 28 | E425: =DATE($B425,$C425,1)-1 -> 46053 | F425: =_xlfn.XLOOKUP($A425,m1_cv!$B:$B,m1_cv!$C:$C) -> 9425 | G425: =MAX(0,ROUND(SUMIFS(m1_cv!$E:$E,m1_cv!$A:$A,$E425,m1_cv!$B:$B,$A425),0)) -> 1174 | H425: =MAX(0,ROUND(SUMIFS(m2_cv!$E:$E,m2_cv!$A:$A,$E425,m2_cv!$B:$B,$A425),0)) -> 4125 | I425: =MAX(0,ROUND(SUMIFS(m3_cv!$E:$E,m3_cv!$A:$A,$E425,m3_cv!$B:$B,$A425),0)) -> 3861 | J425: =MAX(0,ROUND(SUMIFS(m4_cv!$E:$E,m4_cv!$A:$A,$E425,m4_cv!$B:$B,$A425),0)) -> 3858 | K425: =MAX(0,ROUND(SUMIFS(m5_cv!$E:$E,m5_cv!$A:$A,$E425,m5_cv!$B:$B,$A425),0)) -> 8105 | L425: =MAX(0,ROUND(SUMIFS(m6_cv!$E:$E,m6_cv!$A:$A,$E425,m6_cv!$B:$B,$A425),0)) -> 3414 | M425: =MAX(0,ROUND(SUMIFS(m7_cv!$E:$E,m7_cv!$A:$A,$E425,m7_cv!$B:$B,$A425),0)) -> 8316 | N425: =ROUND(_xlfn.XLOOKUP($D425,Charts!$W$82:$W$112,Charts!$X$82:$X$112)*$L425+_xlfn.XLOOKUP($D425,Charts!$W$82:$W$112,Charts!$Y$82:$Y$112)*$M425,0) -> 3414 | P425: M6 | Q425: M7 | R425: Diff | S425: Adj | T425: Adj NoDiff | V425: Adj | W425: Adj No Diff | X425: Actual
A426: =A425+1 -> 46082 | B426: =YEAR(A426) -> 2026 | C426: =MONTH($A426) -> 3 | D426: =DAY($A426) -> 1 | E426: =DATE($B426,$C426,1)-1 -> 46081 | F426: =_xlfn.XLOOKUP($A426,m1_cv!$B:$B,m1_cv!$C:$C) -> 40 | G426: =MAX(0,ROUND(SUMIFS(m1_cv!$E:$E,m1_cv!$A:$A,$E426,m1_cv!$B:$B,$A426),0)) -> 759 | H426: =MAX(0,ROUND(SUMIFS(m2_cv!$E:$E,m2_cv!$A:$A,$E426,m2_cv!$B:$B,$A426),0)) -> 4377 | I426: =MAX(0,ROUND(SUMIFS(m3_cv!$E:$E,m3_cv!$A:$A,$E426,m3_cv!$B:$B,$A426),0)) -> 4263 | J426: =MAX(0,ROUND(SUMIFS(m4_cv!$E:$E,m4_cv!$A:$A,$E426,m4_cv!$B:$B,$A426),0)) -> 4257 | K426: =MAX(0,ROUND(SUMIFS(m5_cv!$E:$E,m5_cv!$A:$A,$E426,m5_cv!$B:$B,$A426),0)) -> 972 | L426: =MAX(0,ROUND(SUMIFS(m6_cv!$E:$E,m6_cv!$A:$A,$E426,m6_cv!$B:$B,$A426),0)) -> 95 | M426: =MAX(0,ROUND(SUMIFS(m7_cv!$E:$E,m7_cv!$A:$A,$E426,m7_cv!$B:$B,$A426),0)) -> 1294 | N426: =ROUND(_xlfn.XLOOKUP($D426,Charts!$W$82:$W$112,Charts!$X$82:$X$112)*$L426+_xlfn.XLOOKUP($D426,Charts!$W$82:$W$112,Charts!$Y$82:$Y$112)*$M426,0) -> 95 | P426: 95 | Q426: 1294 | R426: =Q426-S426 -> 1199 | S426: =P426 -> 95 | T426: =S426 -> 95 | V426: Cumulative | W426: Cumulative | X426: Cumulative
A427: =A426+1 -> 46083 | B427: =YEAR(A427) -> 2026 | C427: =MONTH($A427) -> 3 | D427: =DAY($A427) -> 2 | E427: =DATE($B427,$C427,1)-1 -> 46081 | F427: =_xlfn.XLOOKUP($A427,m1_cv!$B:$B,m1_cv!$C:$C) -> 617 | G427: =MAX(0,ROUND(SUMIFS(m1_cv!$E:$E,m1_cv!$A:$A,$E427,m1_cv!$B:$B,$A427),0)) -> 3079 | H427: =MAX(0,ROUND(SUMIFS(m2_cv!$E:$E,m2_cv!$A:$A,$E427,m2_cv!$B:$B,$A427),0)) -> 6287 | I427: =MAX(0,ROUND(SUMIFS(m3_cv!$E:$E,m3_cv!$A:$A,$E427,m3_cv!$B:$B,$A427),0)) -> 6488 | J427: =MAX(0,ROUND(SUMIFS(m4_cv!$E:$E,m4_cv!$A:$A,$E427,m4_cv!$B:$B,$A427),0)) -> 6484 | K427: =MAX(0,ROUND(SUMIFS(m5_cv!$E:$E,m5_cv!$A:$A,$E427,m5_cv!$B:$B,$A427),0)) -> 2916 | L427: =MAX(0,ROUND(SUMIFS(m6_cv!$E:$E,m6_cv!$A:$A,$E427,m6_cv!$B:$B,$A427),0)) -> 836 | M427: =MAX(0,ROUND(SUMIFS(m7_cv!$E:$E,m7_cv!$A:$A,$E427,m7_cv!$B:$B,$A427),0)) -> 2797 | N427: =ROUND(_xlfn.XLOOKUP($D427,Charts!$W$82:$W$112,Charts!$X$82:$X$112)*$L427+_xlfn.XLOOKUP($D427,Charts!$W$82:$W$112,Charts!$Y$82:$Y$112)*$M427,0) -> 836 | P427: 836 | Q427: 2797 | R427: =Q427-S427 -> 1961 | S427: =P427 -> 836 | T427: =S427 -> 836 | V427: =SUM(S$426:S427) -> 931 | W427: =SUM(T$426:T427) -> 931 | X427: =SUM(F$426:F427) -> 657 | Y427: =W427-X427 -> 274
A428: =A427+1 -> 46084 | B428: =YEAR(A428) -> 2026 | C428: =MONTH($A428) -> 3 | D428: =DAY($A428) -> 3 | E428: =DATE($B428,$C428,1)-1 -> 46081 | F428: =_xlfn.XLOOKUP($A428,m1_cv!$B:$B,m1_cv!$C:$C) -> 799 | G428: =MAX(0,ROUND(SUMIFS(m1_cv!$E:$E,m1_cv!$A:$A,$E428,m1_cv!$B:$B,$A428),0)) -> 3644 | H428: =MAX(0,ROUND(SUMIFS(m2_cv!$E:$E,m2_cv!$A:$A,$E428,m2_cv!$B:$B,$A428),0)) -> 5336 | I428: =MAX(0,ROUND(SUMIFS(m3_cv!$E:$E,m3_cv!$A:$A,$E428,m3_cv!$B:$B,$A428),0)) -> 5408 | J428: =MAX(0,ROUND(SUMIFS(m4_cv!$E:$E,m4_cv!$A:$A,$E428,m4_cv!$B:$B,$A428),0)) -> 5402 | K428: =MAX(0,ROUND(SUMIFS(m5_cv!$E:$E,m5_cv!$A:$A,$E428,m5_cv!$B:$B,$A428),0)) -> 2569 | L428: =MAX(0,ROUND(SUMIFS(m6_cv!$E:$E,m6_cv!$A:$A,$E428,m6_cv!$B:$B,$A428),0)) -> 1413 | M428: =MAX(0,ROUND(SUMIFS(m7_cv!$E:$E,m7_cv!$A:$A,$E428,m7_cv!$B:$B,$A428),0)) -> 2199 | N428: =ROUND(_xlfn.XLOOKUP($D428,Charts!$W$82:$W$112,Charts!$X$82:$X$112)*$L428+_xlfn.XLOOKUP($D428,Charts!$W$82:$W$112,Charts!$Y$82:$Y$112)*$M428,0) -> 1413 | P428: 1413 | Q428: 2199 | R428: =Q428-S428 -> 786 | S428: =P428 -> 1413 | T428: =S428 -> 1413 | V428: =SUM(S$426:S428) -> 2344 | W428: =SUM(T$426:T428) -> 2344 | X428: =SUM(F$426:F428) -> 1456 | Y428: =W428-X428 -> 888
A429: =A428+1 -> 46085 | B429: =YEAR(A429) -> 2026 | C429: =MONTH($A429) -> 3 | D429: =DAY($A429) -> 4 | E429: =DATE($B429,$C429,1)-1 -> 46081 | F429: =_xlfn.XLOOKUP($A429,m1_cv!$B:$B,m1_cv!$C:$C) -> 995 | G429: =MAX(0,ROUND(SUMIFS(m1_cv!$E:$E,m1_cv!$A:$A,$E429,m1_cv!$B:$B,$A429),0)) -> 3744 | H429: =MAX(0,ROUND(SUMIFS(m2_cv!$E:$E,m2_cv!$A:$A,$E429,m2_cv!$B:$B,$A429),0)) -> 3537 | I429: =MAX(0,ROUND(SUMIFS(m3_cv!$E:$E,m3_cv!$A:$A,$E429,m3_cv!$B:$B,$A429),0)) -> 3631 | J429: =MAX(0,ROUND(SUMIFS(m4_cv!$E:$E,m4_cv!$A:$A,$E429,m4_cv!$B:$B,$A429),0)) -> 3626 | K429: =MAX(0,ROUND(SUMIFS(m5_cv!$E:$E,m5_cv!$A:$A,$E429,m5_cv!$B:$B,$A429),0)) -> 1979 | L429: =MAX(0,ROUND(SUMIFS(m6_cv!$E:$E,m6_cv!$A:$A,$E429,m6_cv!$B:$B,$A429),0)) -> 1185 | M429: =MAX(0,ROUND(SUMIFS(m7_cv!$E:$E,m7_cv!$A:$A,$E429,m7_cv!$B:$B,$A429),0)) -> 1882 | N429: =ROUND(_xlfn.XLOOKUP($D429,Charts!$W$82:$W$112,Charts!$X$82:$X$112)*$L429+_xlfn.XLOOKUP($D429,Charts!$W$82:$W$112,Charts!$Y$82:$Y$112)*$M429,0) -> 1185 | P429: 1185 | Q429: 1882 | R429: =Q429-S429 -> 697 | S429: =P429 -> 1185 | T429: =S429 -> 1185 | V429: =SUM(S$426:S429) -> 3529 | W429: =SUM(T$426:T429) -> 3529 | X429: =SUM(F$426:F429) -> 2451 | Y429: =W429-X429 -> 1078
A430: =A429+1 -> 46086 | B430: =YEAR(A430) -> 2026 | C430: =MONTH($A430) -> 3 | D430: =DAY($A430) -> 5 | E430: =DATE($B430,$C430,1)-1 -> 46081 | F430: =_xlfn.XLOOKUP($A430,m1_cv!$B:$B,m1_cv!$C:$C) -> 1314 | G430: =MAX(0,ROUND(SUMIFS(m1_cv!$E:$E,m1_cv!$A:$A,$E430,m1_cv!$B:$B,$A430),0)) -> 3779 | H430: =MAX(0,ROUND(SUMIFS(m2_cv!$E:$E,m2_cv!$A:$A,$E430,m2_cv!$B:$B,$A430),0)) -> 2118 | I430: =MAX(0,ROUND(SUMIFS(m3_cv!$E:$E,m3_cv!$A:$A,$E430,m3_cv!$B:$B,$A430),0)) -> 2162 | J430: =MAX(0,ROUND(SUMIFS(m4_cv!$E:$E,m4_cv!$A:$A,$E430,m4_cv!$B:$B,$A430),0)) -> 2157 | K430: =MAX(0,ROUND(SUMIFS(m5_cv!$E:$E,m5_cv!$A:$A,$E430,m5_cv!$B:$B,$A430),0)) -> 1726 | L430: =MAX(0,ROUND(SUMIFS(m6_cv!$E:$E,m6_cv!$A:$A,$E430,m6_cv!$B:$B,$A430),0)) -> 1081 | M430: =MAX(0,ROUND(SUMIFS(m7_cv!$E:$E,m7_cv!$A:$A,$E430,m7_cv!$B:$B,$A430),0)) -> 1919 | N430: =ROUND(_xlfn.XLOOKUP($D430,Charts!$W$82:$W$112,Charts!$X$82:$X$112)*$L430+_xlfn.XLOOKUP($D430,Charts!$W$82:$W$112,Charts!$Y$82:$Y$112)*$M430,0) -> 1249 | P430: 1081 | Q430: 1919 | R430: =Q430-S430 -> 838 | S430: =P430 -> 1081 | T430: =S430 -> 1081 | V430: =SUM(S$426:S430) -> 4610 | W430: =SUM(T$426:T430) -> 4610 | X430: =SUM(F$426:F430) -> 3765 | Y430: =W430-X430 -> 845
A431: =A430+1 -> 46087 | B431: =YEAR(A431) -> 2026 | C431: =MONTH($A431) -> 3 | D431: =DAY($A431) -> 6 | E431: =DATE($B431,$C431,1)-1 -> 46081 | F431: =_xlfn.XLOOKUP($A431,m1_cv!$B:$B,m1_cv!$C:$C) -> 1617 | G431: =MAX(0,ROUND(SUMIFS(m1_cv!$E:$E,m1_cv!$A:$A,$E431,m1_cv!$B:$B,$A431),0)) -> 3863 | H431: =MAX(0,ROUND(SUMIFS(m2_cv!$E:$E,m2_cv!$A:$A,$E431,m2_cv!$B:$B,$A431),0)) -> 1652 | I431: =MAX(0,ROUND(SUMIFS(m3_cv!$E:$E,m3_cv!$A:$A,$E431,m3_cv!$B:$B,$A431),0)) -> 1588 | J431: =MAX(0,ROUND(SUMIFS(m4_cv!$E:$E,m4_cv!$A:$A,$E431,m4_cv!$B:$B,$A431),0)) -> 1582 | K431: =MAX(0,ROUND(SUMIFS(m5_cv!$E:$E,m5_cv!$A:$A,$E431,m5_cv!$B:$B,$A431),0)) -> 1832 | L431: =MAX(0,ROUND(SUMIFS(m6_cv!$E:$E,m6_cv!$A:$A,$E431,m6_cv!$B:$B,$A431),0)) -> 989 | M431: =MAX(0,ROUND(SUMIFS(m7_cv!$E:$E,m7_cv!$A:$A,$E431,m7_cv!$B:$B,$A431),0)) -> 1890 | N431: =ROUND(_xlfn.XLOOKUP($D431,Charts!$W$82:$W$112,Charts!$X$82:$X$112)*$L431+_xlfn.XLOOKUP($D431,Charts!$W$82:$W$112,Charts!$Y$82:$Y$112)*$M431,0) -> 1440 | P431: 989 | Q431: 1890 | R431: =Q431-S431 -> 901 | S431: =P431 -> 989 | T431: =S431 -> 989 | V431: =SUM(S$426:S431) -> 5599 | W431: =SUM(T$426:T431) -> 5599 | X431: =SUM(F$426:F431) -> 5382 | Y431: =W431-X431 -> 217
A432: =A431+1 -> 46088 | B432: =YEAR(A432) -> 2026 | C432: =MONTH($A432) -> 3 | D432: =DAY($A432) -> 7 | E432: =DATE($B432,$C432,1)-1 -> 46081 | F432: =_xlfn.XLOOKUP($A432,m1_cv!$B:$B,m1_cv!$C:$C) -> 220 | G432: =MAX(0,ROUND(SUMIFS(m1_cv!$E:$E,m1_cv!$A:$A,$E432,m1_cv!$B:$B,$A432),0)) -> 1634 | H432: =MAX(0,ROUND(SUMIFS(m2_cv!$E:$E,m2_cv!$A:$A,$E432,m2_cv!$B:$B,$A432),0)) -> 0 | I432: =MAX(0,ROUND(SUMIFS(m3_cv!$E:$E,m3_cv!$A:$A,$E432,m3_cv!$B:$B,$A432),0)) -> 0 | J432: =MAX(0,ROUND(SUMIFS(m4_cv!$E:$E,m4_cv!$A:$A,$E432,m4_cv!$B:$B,$A432),0)) -> 0 | K432: =MAX(0,ROUND(SUMIFS(m5_cv!$E:$E,m5_cv!$A:$A,$E432,m5_cv!$B:$B,$A432),0)) -> 0 | L432: =MAX(0,ROUND(SUMIFS(m6_cv!$E:$E,m6_cv!$A:$A,$E432,m6_cv!$B:$B,$A432),0)) -> 19 | M432: =MAX(0,ROUND(SUMIFS(m7_cv!$E:$E,m7_cv!$A:$A,$E432,m7_cv!$B:$B,$A432),0)) -> 0 | N432: =ROUND(_xlfn.XLOOKUP($D432,Charts!$W$82:$W$112,Charts!$X$82:$X$112)*$L432+_xlfn.XLOOKUP($D432,Charts!$W$82:$W$112,Charts!$Y$82:$Y$112)*$M432,0) -> 10 | P432: 19 | Q432: 0 | R432: =Q432-S432 -> -19 | S432: =P432 -> 19 | T432: =S432 -> 19 | V432: =SUM(S$426:S432) -> 5618 | W432: =SUM(T$426:T432) -> 5618 | X432: =SUM(F$426:F432) -> 5602 | Y432: =W432-X432 -> 16
A433: =A432+1 -> 46089 | B433: =YEAR(A433) -> 2026 | C433: =MONTH($A433) -> 3 | D433: =DAY($A433) -> 8 | E433: =DATE($B433,$C433,1)-1 -> 46081 | F433: =_xlfn.XLOOKUP($A433,m1_cv!$B:$B,m1_cv!$C:$C) -> 43 | G433: =MAX(0,ROUND(SUMIFS(m1_cv!$E:$E,m1_cv!$A:$A,$E433,m1_cv!$B:$B,$A433),0)) -> 1001 | H433: =MAX(0,ROUND(SUMIFS(m2_cv!$E:$E,m2_cv!$A:$A,$E433,m2_cv!$B:$B,$A433),0)) -> 0 | I433: =MAX(0,ROUND(SUMIFS(m3_cv!$E:$E,m3_cv!$A:$A,$E433,m3_cv!$B:$B,$A433),0)) -> 0 | J433: =MAX(0,ROUND(SUMIFS(m4_cv!$E:$E,m4_cv!$A:$A,$E433,m4_cv!$B:$B,$A433),0)) -> 0 | K433: =MAX(0,ROUND(SUMIFS(m5_cv!$E:$E,m5_cv!$A:$A,$E433,m5_cv!$B:$B,$A433),0)) -> 0 | L433: =MAX(0,ROUND(SUMIFS(m6_cv!$E:$E,m6_cv!$A:$A,$E433,m6_cv!$B:$B,$A433),0)) -> 128 | M433: =MAX(0,ROUND(SUMIFS(m7_cv!$E:$E,m7_cv!$A:$A,$E433,m7_cv!$B:$B,$A433),0)) -> 0 | N433: =ROUND(_xlfn.XLOOKUP($D433,Charts!$W$82:$W$112,Charts!$X$82:$X$112)*$L433+_xlfn.XLOOKUP($D433,Charts!$W$82:$W$112,Charts!$Y$82:$Y$112)*$M433,0) -> 64 | P433: 128 | Q433: 0 | R433: =Q433-S433 -> -128 | S433: =P433 -> 128 | T433: =S433 -> 128 | V433: =SUM(S$426:S433) -> 5746 | W433: =SUM(T$426:T433) -> 5746 | X433: =SUM(F$426:F433) -> 5645 | Y433: =W433-X433 -> 101
A434: =A433+1 -> 46090 | B434: =YEAR(A434) -> 2026 | C434: =MONTH($A434) -> 3 | D434: =DAY($A434) -> 9 | E434: =DATE($B434,$C434,1)-1 -> 46081 | F434: =_xlfn.XLOOKUP($A434,m1_cv!$B:$B,m1_cv!$C:$C) -> 1766 | G434: =MAX(0,ROUND(SUMIFS(m1_cv!$E:$E,m1_cv!$A:$A,$E434,m1_cv!$B:$B,$A434),0)) -> 3287 | H434: =MAX(0,ROUND(SUMIFS(m2_cv!$E:$E,m2_cv!$A:$A,$E434,m2_cv!$B:$B,$A434),0)) -> 1986 | I434: =MAX(0,ROUND(SUMIFS(m3_cv!$E:$E,m3_cv!$A:$A,$E434,m3_cv!$B:$B,$A434),0)) -> 2119 | J434: =MAX(0,ROUND(SUMIFS(m4_cv!$E:$E,m4_cv!$A:$A,$E434,m4_cv!$B:$B,$A434),0)) -> 2114 | K434: =MAX(0,ROUND(SUMIFS(m5_cv!$E:$E,m5_cv!$A:$A,$E434,m5_cv!$B:$B,$A434),0)) -> 2381 | L434: =MAX(0,ROUND(SUMIFS(m6_cv!$E:$E,m6_cv!$A:$A,$E434,m6_cv!$B:$B,$A434),0)) -> 1698 | M434: =MAX(0,ROUND(SUMIFS(m7_cv!$E:$E,m7_cv!$A:$A,$E434,m7_cv!$B:$B,$A434),0)) -> 2398 | N434: =ROUND(_xlfn.XLOOKUP($D434,Charts!$W$82:$W$112,Charts!$X$82:$X$112)*$L434+_xlfn.XLOOKUP($D434,Charts!$W$82:$W$112,Charts!$Y$82:$Y$112)*$M434,0) -> 2048 | P434: 1698 | Q434: 2398 | R434: =Q434-S434 -> 700 | S434: =P434 -> 1698 | T434: =S434 -> 1698 | V434: =SUM(S$426:S434) -> 7444 | W434: =SUM(T$426:T434) -> 7444 | X434: =SUM(F$426:F434) -> 7411 | Y434: =W434-X434 -> 33
A435: =A434+1 -> 46091 | B435: =YEAR(A435) -> 2026 | C435: =MONTH($A435) -> 3 | D435: =DAY($A435) -> 10 | E435: =DATE($B435,$C435,1)-1 -> 46081 | F435: =_xlfn.XLOOKUP($A435,m1_cv!$B:$B,m1_cv!$C:$C) -> 2170 | G435: =MAX(0,ROUND(SUMIFS(m1_cv!$E:$E,m1_cv!$A:$A,$E435,m1_cv!$B:$B,$A435),0)) -> 3814 | H435: =MAX(0,ROUND(SUMIFS(m2_cv!$E:$E,m2_cv!$A:$A,$E435,m2_cv!$B:$B,$A435),0)) -> 2463 | I435: =MAX(0,ROUND(SUMIFS(m3_cv!$E:$E,m3_cv!$A:$A,$E435,m3_cv!$B:$B,$A435),0)) -> 2370 | J435: =MAX(0,ROUND(SUMIFS(m4_cv!$E:$E,m4_cv!$A:$A,$E435,m4_cv!$B:$B,$A435),0)) -> 2364 | K435: =MAX(0,ROUND(SUMIFS(m5_cv!$E:$E,m5_cv!$A:$A,$E435,m5_cv!$B:$B,$A435),0)) -> 2536 | L435: =MAX(0,ROUND(SUMIFS(m6_cv!$E:$E,m6_cv!$A:$A,$E435,m6_cv!$B:$B,$A435),0)) -> 2107 | M435: =MAX(0,ROUND(SUMIFS(m7_cv!$E:$E,m7_cv!$A:$A,$E435,m7_cv!$B:$B,$A435),0)) -> 2633 | N435: =ROUND(_xlfn.XLOOKUP($D435,Charts!$W$82:$W$112,Charts!$X$82:$X$112)*$L435+_xlfn.XLOOKUP($D435,Charts!$W$82:$W$112,Charts!$Y$82:$Y$112)*$M435,0) -> 2370 | P435: 2107 | Q435: 2633 | R435: =Q435-S435 -> 526 | S435: =P435 -> 2107 | T435: =S435 -> 2107 | V435: =SUM(S$426:S435) -> 9551 | W435: =SUM(T$426:T435) -> 9551 | X435: =SUM(F$426:F435) -> 9581 | Y435: =W435-X435 -> -30
A436: =A435+1 -> 46092 | B436: =YEAR(A436) -> 2026 | C436: =MONTH($A436) -> 3 | D436: =DAY($A436) -> 11 | E436: =DATE($B436,$C436,1)-1 -> 46081 | F436: =_xlfn.XLOOKUP($A436,m1_cv!$B:$B,m1_cv!$C:$C) -> 2907 | G436: =MAX(0,ROUND(SUMIFS(m1_cv!$E:$E,m1_cv!$A:$A,$E436,m1_cv!$B:$B,$A436),0)) -> 3876 | H436: =MAX(0,ROUND(SUMIFS(m2_cv!$E:$E,m2_cv!$A:$A,$E436,m2_cv!$B:$B,$A436),0)) -> 2463 | I436: =MAX(0,ROUND(SUMIFS(m3_cv!$E:$E,m3_cv!$A:$A,$E436,m3_cv!$B:$B,$A436),0)) -> 2382 | J436: =MAX(0,ROUND(SUMIFS(m4_cv!$E:$E,m4_cv!$A:$A,$E436,m4_cv!$B:$B,$A436),0)) -> 2376 | K436: =MAX(0,ROUND(SUMIFS(m5_cv!$E:$E,m5_cv!$A:$A,$E436,m5_cv!$B:$B,$A436),0)) -> 2577 | L436: =MAX(0,ROUND(SUMIFS(m6_cv!$E:$E,m6_cv!$A:$A,$E436,m6_cv!$B:$B,$A436),0)) -> 2154 | M436: =MAX(0,ROUND(SUMIFS(m7_cv!$E:$E,m7_cv!$A:$A,$E436,m7_cv!$B:$B,$A436),0)) -> 2621 | N436: =ROUND(_xlfn.XLOOKUP($D436,Charts!$W$82:$W$112,Charts!$X$82:$X$112)*$L436+_xlfn.XLOOKUP($D436,Charts!$W$82:$W$112,Charts!$Y$82:$Y$112)*$M436,0) -> 2481 | P436: 2154 | Q436: 2621 | R436: =Q436-S436 -> 0 | S436: =Q436 -> 2621 | T436: =ROUND(S436+S436/$S$459*$R$457,0) -> 3010 | V436: =SUM(S$426:S436) -> 12172 | W436: =SUM(T$426:T436) -> 12561 | X436: =SUM(F$426:F436) -> 12488 | Y436: =W436-X436 -> 73
A437: =A436+1 -> 46093 | B437: =YEAR(A437) -> 2026 | C437: =MONTH($A437) -> 3 | D437: =DAY($A437) -> 12 | E437: =DATE($B437,$C437,1)-1 -> 46081 | F437: =_xlfn.XLOOKUP($A437,m1_cv!$B:$B,m1_cv!$C:$C) -> 3020 | G437: =MAX(0,ROUND(SUMIFS(m1_cv!$E:$E,m1_cv!$A:$A,$E437,m1_cv!$B:$B,$A437),0)) -> 3871 | H437: =MAX(0,ROUND(SUMIFS(m2_cv!$E:$E,m2_cv!$A:$A,$E437,m2_cv!$B:$B,$A437),0)) -> 2573 | I437: =MAX(0,ROUND(SUMIFS(m3_cv!$E:$E,m3_cv!$A:$A,$E437,m3_cv!$B:$B,$A437),0)) -> 2526 | J437: =MAX(0,ROUND(SUMIFS(m4_cv!$E:$E,m4_cv!$A:$A,$E437,m4_cv!$B:$B,$A437),0)) -> 2520 | K437: =MAX(0,ROUND(SUMIFS(m5_cv!$E:$E,m5_cv!$A:$A,$E437,m5_cv!$B:$B,$A437),0)) -> 2688 | L437: =MAX(0,ROUND(SUMIFS(m6_cv!$E:$E,m6_cv!$A:$A,$E437,m6_cv!$B:$B,$A437),0)) -> 2296 | M437: =MAX(0,ROUND(SUMIFS(m7_cv!$E:$E,m7_cv!$A:$A,$E437,m7_cv!$B:$B,$A437),0)) -> 2623 | N437: =ROUND(_xlfn.XLOOKUP($D437,Charts!$W$82:$W$112,Charts!$X$82:$X$112)*$L437+_xlfn.XLOOKUP($D437,Charts!$W$82:$W$112,Charts!$Y$82:$Y$112)*$M437,0) -> 2525 | P437: 2296 | Q437: 2623 | R437: =Q437-S437 -> 0 | S437: =Q437 -> 2623 | T437: =ROUND(S437+S437/$S$459*$R$457,0) -> 3012 | V437: =SUM(S$426:S437) -> 14795 | W437: =SUM(T$426:T437) -> 15573 | X437: =SUM(F$426:F437) -> 15508 | Y437: =W437-X437 -> 65
A438: =A437+1 -> 46094 | B438: =YEAR(A438) -> 2026 | C438: =MONTH($A438) -> 3 | D438: =DAY($A438) -> 13 | E438: =DATE($B438,$C438,1)-1 -> 46081 | F438: =_xlfn.XLOOKUP($A438,m1_cv!$B:$B,m1_cv!$C:$C) -> 3551 | G438: =MAX(0,ROUND(SUMIFS(m1_cv!$E:$E,m1_cv!$A:$A,$E438,m1_cv!$B:$B,$A438),0)) -> 3914 | H438: =MAX(0,ROUND(SUMIFS(m2_cv!$E:$E,m2_cv!$A:$A,$E438,m2_cv!$B:$B,$A438),0)) -> 2878 | I438: =MAX(0,ROUND(SUMIFS(m3_cv!$E:$E,m3_cv!$A:$A,$E438,m3_cv!$B:$B,$A438),0)) -> 2845 | J438: =MAX(0,ROUND(SUMIFS(m4_cv!$E:$E,m4_cv!$A:$A,$E438,m4_cv!$B:$B,$A438),0)) -> 2839 | K438: =MAX(0,ROUND(SUMIFS(m5_cv!$E:$E,m5_cv!$A:$A,$E438,m5_cv!$B:$B,$A438),0)) -> 2834 | L438: =MAX(0,ROUND(SUMIFS(m6_cv!$E:$E,m6_cv!$A:$A,$E438,m6_cv!$B:$B,$A438),0)) -> 2295 | M438: =MAX(0,ROUND(SUMIFS(m7_cv!$E:$E,m7_cv!$A:$A,$E438,m7_cv!$B:$B,$A438),0)) -> 2777 | N438: =ROUND(_xlfn.XLOOKUP($D438,Charts!$W$82:$W$112,Charts!$X$82:$X$112)*$L438+_xlfn.XLOOKUP($D438,Charts!$W$82:$W$112,Charts!$Y$82:$Y$112)*$M438,0) -> 2632 | P438: 2295 | Q438: 2777 | R438: =Q438-S438 -> 0 | S438: =Q438 -> 2777 | T438: =ROUND(S438+S438/$S$459*$R$457,0) -> 3189 | V438: =SUM(S$426:S438) -> 17572 | W438: =SUM(T$426:T438) -> 18762 | X438: =SUM(F$426:F438) -> 19059 | Y438: =W438-X438 -> -297
A439: =A438+1 -> 46095 | B439: =YEAR(A439) -> 2026 | C439: =MONTH($A439) -> 3 | D439: =DAY($A439) -> 14 | E439: =DATE($B439,$C439,1)-1 -> 46081 | F439: =_xlfn.XLOOKUP($A439,m1_cv!$B:$B,m1_cv!$C:$C) -> 1088 | G439: =MAX(0,ROUND(SUMIFS(m1_cv!$E:$E,m1_cv!$A:$A,$E439,m1_cv!$B:$B,$A439),0)) -> 1646 | H439: =MAX(0,ROUND(SUMIFS(m2_cv!$E:$E,m2_cv!$A:$A,$E439,m2_cv!$B:$B,$A439),0)) -> 833 | I439: =MAX(0,ROUND(SUMIFS(m3_cv!$E:$E,m3_cv!$A:$A,$E439,m3_cv!$B:$B,$A439),0)) -> 851 | J439: =MAX(0,ROUND(SUMIFS(m4_cv!$E:$E,m4_cv!$A:$A,$E439,m4_cv!$B:$B,$A439),0)) -> 844 | K439: =MAX(0,ROUND(SUMIFS(m5_cv!$E:$E,m5_cv!$A:$A,$E439,m5_cv!$B:$B,$A439),0)) -> 640 | L439: =MAX(0,ROUND(SUMIFS(m6_cv!$E:$E,m6_cv!$A:$A,$E439,m6_cv!$B:$B,$A439),0)) -> 429 | M439: =MAX(0,ROUND(SUMIFS(m7_cv!$E:$E,m7_cv!$A:$A,$E439,m7_cv!$B:$B,$A439),0)) -> 666 | N439: =ROUND(_xlfn.XLOOKUP($D439,Charts!$W$82:$W$112,Charts!$X$82:$X$112)*$L439+_xlfn.XLOOKUP($D439,Charts!$W$82:$W$112,Charts!$Y$82:$Y$112)*$M439,0) -> 666 | P439: 429 | Q439: 666 | R439: =Q439-S439 -> 0 | S439: =Q439 -> 666 | T439: =ROUND(S439+S439/$S$459*$R$457,0) -> 765 | V439: =SUM(S$426:S439) -> 18238 | W439: =SUM(T$426:T439) -> 19527 | X439: =SUM(F$426:F439) -> 20147 | Y439: =W439-X439 -> -620
A440: =A439+1 -> 46096 | B440: =YEAR(A440) -> 2026 | C440: =MONTH($A440) -> 3 | D440: =DAY($A440) -> 15 | E440: =DATE($B440,$C440,1)-1 -> 46081 | F440: =_xlfn.XLOOKUP($A440,m1_cv!$B:$B,m1_cv!$C:$C) -> 228 | G440: =MAX(0,ROUND(SUMIFS(m1_cv!$E:$E,m1_cv!$A:$A,$E440,m1_cv!$B:$B,$A440),0)) -> 974 | H440: =MAX(0,ROUND(SUMIFS(m2_cv!$E:$E,m2_cv!$A:$A,$E440,m2_cv!$B:$B,$A440),0)) -> 249 | I440: =MAX(0,ROUND(SUMIFS(m3_cv!$E:$E,m3_cv!$A:$A,$E440,m3_cv!$B:$B,$A440),0)) -> 319 | J440: =MAX(0,ROUND(SUMIFS(m4_cv!$E:$E,m4_cv!$A:$A,$E440,m4_cv!$B:$B,$A440),0)) -> 313 | K440: =MAX(0,ROUND(SUMIFS(m5_cv!$E:$E,m5_cv!$A:$A,$E440,m5_cv!$B:$B,$A440),0)) -> 106 | L440: =MAX(0,ROUND(SUMIFS(m6_cv!$E:$E,m6_cv!$A:$A,$E440,m6_cv!$B:$B,$A440),0)) -> 165 | M440: =MAX(0,ROUND(SUMIFS(m7_cv!$E:$E,m7_cv!$A:$A,$E440,m7_cv!$B:$B,$A440),0)) -> 164 | N440: =ROUND(_xlfn.XLOOKUP($D440,Charts!$W$82:$W$112,Charts!$X$82:$X$112)*$L440+_xlfn.XLOOKUP($D440,Charts!$W$82:$W$112,Charts!$Y$82:$Y$112)*$M440,0) -> 164 | P440: 165 | Q440: 164 | R440: =Q440-S440 -> 0 | S440: =Q440 -> 164 | T440: =ROUND(S440+S440/$S$459*$R$457,0) -> 188 | V440: =SUM(S$426:S440) -> 18402 | W440: =SUM(T$426:T440) -> 19715 | X440: =SUM(F$426:F440) -> 20375 | Y440: =W440-X440 -> -660
A441: =A440+1 -> 46097 | B441: =YEAR(A441) -> 2026 | C441: =MONTH($A441) -> 3 | D441: =DAY($A441) -> 16 | E441: =DATE($B441,$C441,1)-1 -> 46081 | F441: =_xlfn.XLOOKUP($A441,m1_cv!$B:$B,m1_cv!$C:$C) -> 3950 | G441: =MAX(0,ROUND(SUMIFS(m1_cv!$E:$E,m1_cv!$A:$A,$E441,m1_cv!$B:$B,$A441),0)) -> 3224 | H441: =MAX(0,ROUND(SUMIFS(m2_cv!$E:$E,m2_cv!$A:$A,$E441,m2_cv!$B:$B,$A441),0)) -> 2485 | I441: =MAX(0,ROUND(SUMIFS(m3_cv!$E:$E,m3_cv!$A:$A,$E441,m3_cv!$B:$B,$A441),0)) -> 2732 | J441: =MAX(0,ROUND(SUMIFS(m4_cv!$E:$E,m4_cv!$A:$A,$E441,m4_cv!$B:$B,$A441),0)) -> 2728 | K441: =MAX(0,ROUND(SUMIFS(m5_cv!$E:$E,m5_cv!$A:$A,$E441,m5_cv!$B:$B,$A441),0)) -> 2663 | L441: =MAX(0,ROUND(SUMIFS(m6_cv!$E:$E,m6_cv!$A:$A,$E441,m6_cv!$B:$B,$A441),0)) -> 2242 | M441: =MAX(0,ROUND(SUMIFS(m7_cv!$E:$E,m7_cv!$A:$A,$E441,m7_cv!$B:$B,$A441),0)) -> 2704 | N441: =ROUND(_xlfn.XLOOKUP($D441,Charts!$W$82:$W$112,Charts!$X$82:$X$112)*$L441+_xlfn.XLOOKUP($D441,Charts!$W$82:$W$112,Charts!$Y$82:$Y$112)*$M441,0) -> 2704 | P441: 2242 | Q441: 2704 | R441: =Q441-S441 -> 0 | S441: =Q441 -> 2704 | T441: =ROUND(S441+S441/$S$459*$R$457,0) -> 3105 | V441: =SUM(S$426:S441) -> 21106 | W441: =SUM(T$426:T441) -> 22820 | X441: =SUM(F$426:F441) -> 24325 | Y441: =W441-X441 -> -1505
A442: =A441+1 -> 46098 | B442: =YEAR(A442) -> 2026 | C442: =MONTH($A442) -> 3 | D442: =DAY($A442) -> 17 | E442: =DATE($B442,$C442,1)-1 -> 46081 | F442: =_xlfn.XLOOKUP($A442,m1_cv!$B:$B,m1_cv!$C:$C) -> 5807 | G442: =MAX(0,ROUND(SUMIFS(m1_cv!$E:$E,m1_cv!$A:$A,$E442,m1_cv!$B:$B,$A442),0)) -> 3719 | H442: =MAX(0,ROUND(SUMIFS(m2_cv!$E:$E,m2_cv!$A:$A,$E442,m2_cv!$B:$B,$A442),0)) -> 3012 | I442: =MAX(0,ROUND(SUMIFS(m3_cv!$E:$E,m3_cv!$A:$A,$E442,m3_cv!$B:$B,$A442),0)) -> 3020 | J442: =MAX(0,ROUND(SUMIFS(m4_cv!$E:$E,m4_cv!$A:$A,$E442,m4_cv!$B:$B,$A442),0)) -> 3014 | K442: =MAX(0,ROUND(SUMIFS(m5_cv!$E:$E,m5_cv!$A:$A,$E442,m5_cv!$B:$B,$A442),0)) -> 3100 | L442: =MAX(0,ROUND(SUMIFS(m6_cv!$E:$E,m6_cv!$A:$A,$E442,m6_cv!$B:$B,$A442),0)) -> 2922 | M442: =MAX(0,ROUND(SUMIFS(m7_cv!$E:$E,m7_cv!$A:$A,$E442,m7_cv!$B:$B,$A442),0)) -> 3092 | N442: =ROUND(_xlfn.XLOOKUP($D442,Charts!$W$82:$W$112,Charts!$X$82:$X$112)*$L442+_xlfn.XLOOKUP($D442,Charts!$W$82:$W$112,Charts!$Y$82:$Y$112)*$M442,0) -> 3092 | P442: 2922 | Q442: 3092 | R442: =Q442-S442 -> 0 | S442: =Q442 -> 3092 | T442: =ROUND(S442+S442/$S$459*$R$457,0) -> 3550 | V442: =SUM(S$426:S442) -> 24198 | W442: =SUM(T$426:T442) -> 26370 | X442: =SUM(F$426:F442) -> 30132 | Y442: =W442-X442 -> -3762
A443: =A442+1 -> 46099 | B443: =YEAR(A443) -> 2026 | C443: =MONTH($A443) -> 3 | D443: =DAY($A443) -> 18 | E443: =DATE($B443,$C443,1)-1 -> 46081 | F443: =_xlfn.XLOOKUP($A443,m1_cv!$B:$B,m1_cv!$C:$C) -> 5295 | G443: =MAX(0,ROUND(SUMIFS(m1_cv!$E:$E,m1_cv!$A:$A,$E443,m1_cv!$B:$B,$A443),0)) -> 3750 | H443: =MAX(0,ROUND(SUMIFS(m2_cv!$E:$E,m2_cv!$A:$A,$E443,m2_cv!$B:$B,$A443),0)) -> 3240 | I443: =MAX(0,ROUND(SUMIFS(m3_cv!$E:$E,m3_cv!$A:$A,$E443,m3_cv!$B:$B,$A443),0)) -> 3281 | J443: =MAX(0,ROUND(SUMIFS(m4_cv!$E:$E,m4_cv!$A:$A,$E443,m4_cv!$B:$B,$A443),0)) -> 3274 | K443: =MAX(0,ROUND(SUMIFS(m5_cv!$E:$E,m5_cv!$A:$A,$E443,m5_cv!$B:$B,$A443),0)) -> 3347 | L443: =MAX(0,ROUND(SUMIFS(m6_cv!$E:$E,m6_cv!$A:$A,$E443,m6_cv!$B:$B,$A443),0)) -> 3138 | M443: =MAX(0,ROUND(SUMIFS(m7_cv!$E:$E,m7_cv!$A:$A,$E443,m7_cv!$B:$B,$A443),0)) -> 3300 | N443: =ROUND(_xlfn.XLOOKUP($D443,Charts!$W$82:$W$112,Charts!$X$82:$X$112)*$L443+_xlfn.XLOOKUP($D443,Charts!$W$82:$W$112,Charts!$Y$82:$Y$112)*$M443,0) -> 3300 | P443: 3138 | Q443: 3300 | R443: =Q443-S443 -> 0 | S443: =Q443 -> 3300 | T443: =ROUND(S443+S443/$S$459*$R$457,0) -> 3789 | V443: =SUM(S$426:S443) -> 27498 | W443: =SUM(T$426:T443) -> 30159 | X443: =SUM(F$426:F443) -> 35427 | Y443: =W443-X443 -> -5268
A444: =A443+1 -> 46100 | B444: =YEAR(A444) -> 2026 | C444: =MONTH($A444) -> 3 | D444: =DAY($A444) -> 19 | E444: =DATE($B444,$C444,1)-1 -> 46081 | F444: =_xlfn.XLOOKUP($A444,m1_cv!$B:$B,m1_cv!$C:$C) -> 3557 | G444: =MAX(0,ROUND(SUMIFS(m1_cv!$E:$E,m1_cv!$A:$A,$E444,m1_cv!$B:$B,$A444),0)) -> 3719 | H444: =MAX(0,ROUND(SUMIFS(m2_cv!$E:$E,m2_cv!$A:$A,$E444,m2_cv!$B:$B,$A444),0)) -> 3435 | I444: =MAX(0,ROUND(SUMIFS(m3_cv!$E:$E,m3_cv!$A:$A,$E444,m3_cv!$B:$B,$A444),0)) -> 3536 | J444: =MAX(0,ROUND(SUMIFS(m4_cv!$E:$E,m4_cv!$A:$A,$E444,m4_cv!$B:$B,$A444),0)) -> 3530 | K444: =MAX(0,ROUND(SUMIFS(m5_cv!$E:$E,m5_cv!$A:$A,$E444,m5_cv!$B:$B,$A444),0)) -> 3462 | L444: =MAX(0,ROUND(SUMIFS(m6_cv!$E:$E,m6_cv!$A:$A,$E444,m6_cv!$B:$B,$A444),0)) -> 3406 | M444: =MAX(0,ROUND(SUMIFS(m7_cv!$E:$E,m7_cv!$A:$A,$E444,m7_cv!$B:$B,$A444),0)) -> 3455 | N444: =ROUND(_xlfn.XLOOKUP($D444,Charts!$W$82:$W$112,Charts!$X$82:$X$112)*$L444+_xlfn.XLOOKUP($D444,Charts!$W$82:$W$112,Charts!$Y$82:$Y$112)*$M444,0) -> 3455 | P444: 3406 | Q444: 3455 | R444: =Q444-S444 -> 0 | S444: =Q444 -> 3455 | T444: =ROUND(S444+S444/$S$459*$R$457,0) -> 3967 | V444: =SUM(S$426:S444) -> 30953 | W444: =SUM(T$426:T444) -> 34126 | X444: =SUM(F$426:F444) -> 38984 | Y444: =W444-X444 -> -4858
A445: =A444+1 -> 46101 | B445: =YEAR(A445) -> 2026 | C445: =MONTH($A445) -> 3 | D445: =DAY($A445) -> 20 | E445: =DATE($B445,$C445,1)-1 -> 46081 | F445: =_xlfn.XLOOKUP($A445,m1_cv!$B:$B,m1_cv!$C:$C) -> 61 | G445: =MAX(0,ROUND(SUMIFS(m1_cv!$E:$E,m1_cv!$A:$A,$E445,m1_cv!$B:$B,$A445),0)) -> 3740 | H445: =MAX(0,ROUND(SUMIFS(m2_cv!$E:$E,m2_cv!$A:$A,$E445,m2_cv!$B:$B,$A445),0)) -> 3542 | I445: =MAX(0,ROUND(SUMIFS(m3_cv!$E:$E,m3_cv!$A:$A,$E445,m3_cv!$B:$B,$A445),0)) -> 275 | J445: =MAX(0,ROUND(SUMIFS(m4_cv!$E:$E,m4_cv!$A:$A,$E445,m4_cv!$B:$B,$A445),0)) -> 260 | K445: =MAX(0,ROUND(SUMIFS(m5_cv!$E:$E,m5_cv!$A:$A,$E445,m5_cv!$B:$B,$A445),0)) -> 0 | L445: =MAX(0,ROUND(SUMIFS(m6_cv!$E:$E,m6_cv!$A:$A,$E445,m6_cv!$B:$B,$A445),0)) -> 24 | M445: =MAX(0,ROUND(SUMIFS(m7_cv!$E:$E,m7_cv!$A:$A,$E445,m7_cv!$B:$B,$A445),0)) -> 0 | N445: =ROUND(_xlfn.XLOOKUP($D445,Charts!$W$82:$W$112,Charts!$X$82:$X$112)*$L445+_xlfn.XLOOKUP($D445,Charts!$W$82:$W$112,Charts!$Y$82:$Y$112)*$M445,0) -> 0 | P445: 24 | Q445: 0 | R445: =Q445-S445 -> 0 | S445: =Q445 -> 0 | T445: =ROUND(S445+S445/$S$459*$R$457,0) -> 0 | V445: =SUM(S$426:S445) -> 30953 | W445: =SUM(T$426:T445) -> 34126 | X445: =SUM(F$426:F445) -> 39045 | Y445: =W445-X445 -> -4919
A446: =A445+1 -> 46102 | B446: =YEAR(A446) -> 2026 | C446: =MONTH($A446) -> 3 | D446: =DAY($A446) -> 21 | E446: =DATE($B446,$C446,1)-1 -> 46081 | F446: =_xlfn.XLOOKUP($A446,m1_cv!$B:$B,m1_cv!$C:$C) -> 3 | G446: =MAX(0,ROUND(SUMIFS(m1_cv!$E:$E,m1_cv!$A:$A,$E446,m1_cv!$B:$B,$A446),0)) -> 1454 | H446: =MAX(0,ROUND(SUMIFS(m2_cv!$E:$E,m2_cv!$A:$A,$E446,m2_cv!$B:$B,$A446),0)) -> 1190 | I446: =MAX(0,ROUND(SUMIFS(m3_cv!$E:$E,m3_cv!$A:$A,$E446,m3_cv!$B:$B,$A446),0)) -> 0 | J446: =MAX(0,ROUND(SUMIFS(m4_cv!$E:$E,m4_cv!$A:$A,$E446,m4_cv!$B:$B,$A446),0)) -> 0 | K446: =MAX(0,ROUND(SUMIFS(m5_cv!$E:$E,m5_cv!$A:$A,$E446,m5_cv!$B:$B,$A446),0)) -> 0 | L446: =MAX(0,ROUND(SUMIFS(m6_cv!$E:$E,m6_cv!$A:$A,$E446,m6_cv!$B:$B,$A446),0)) -> 0 | M446: =MAX(0,ROUND(SUMIFS(m7_cv!$E:$E,m7_cv!$A:$A,$E446,m7_cv!$B:$B,$A446),0)) -> 0 | N446: =ROUND(_xlfn.XLOOKUP($D446,Charts!$W$82:$W$112,Charts!$X$82:$X$112)*$L446+_xlfn.XLOOKUP($D446,Charts!$W$82:$W$112,Charts!$Y$82:$Y$112)*$M446,0) -> 0 | P446: 0 | Q446: 0 | R446: =Q446-S446 -> 0 | S446: =Q446 -> 0 | T446: =ROUND(S446+S446/$S$459*$R$457,0) -> 0 | V446: =SUM(S$426:S446) -> 30953 | W446: =SUM(T$426:T446) -> 34126 | X446: =SUM(F$426:F446) -> 39048 | Y446: =W446-X446 -> -4922
