Workbook

Sheet Charts
A2: Yearly Seasonality Cross-Validation
B4: Year | C4: 2025 | D4: =IF(C5=12,C4+1,C4) -> 2025 | E4: =IF(D5=12,D4+1,D4) -> 2025 | F4: =IF(E5=12,E4+1,E4) -> 2025 | G4: =IF(F5=12,F4+1,F4) -> 2025 | H4: =IF(G5=12,G4+1,G4) -> 2025 | I4: =IF(H5=12,H4+1,H4) -> 2025 | J4: =IF(I5=12,I4+1,I4) -> 2025 | K4: =IF(J5=12,J4+1,J4) -> 2025 | ... Q4: =IF(P5=12,P4+1,P4) -> 2026
B5: Month | C5: 1 | D5: =IF(C5=12,1,C5+1) -> 2 | E5: =IF(D5=12,1,D5+1) -> 3 | F5: =IF(E5=12,1,E5+1) -> 4 | G5: =IF(F5=12,1,F5+1) -> 5 | H5: =IF(G5=12,1,G5+1) -> 6 | I5: =IF(H5=12,1,H5+1) -> 7 | J5: =IF(I5=12,1,I5+1) -> 8 | K5: =IF(J5=12,1,J5+1) -> 9 | ... Q5: =IF(P5=12,1,P5+1) -> 3
B6: Actual | C6: =SUMIFS(Consolidated!$F:$F,Consolidated!$B:$B,C$4,Consolidated!$C:$C,C$5) -> 53930 | D6: =SUMIFS(Consolidated!$F:$F,Consolidated!$B:$B,D$4,Consolidated!$C:$C,D$5) -> 67327 | E6: =SUMIFS(Consolidated!$F:$F,Consolidated!$B:$B,E$4,Consolidated!$C:$C,E$5) -> 77121 | F6: =SUMIFS(Consolidated!$F:$F,Consolidated!$B:$B,F$4,Consolidated!$C:$C,F$5) -> 65200 | G6: =SUMIFS(Consolidated!$F:$F,Consolidated!$B:$B,G$4,Consolidated!$C:$C,G$5) -> 74393 | H6: =SUMIFS(Consolidated!$F:$F,Consolidated!$B:$B,H$4,Consolidated!$C:$C,H$5) -> 58858 | I6: =SUMIFS(Consolidated!$F:$F,Consolidated!$B:$B,I$4,Consolidated!$C:$C,I$5) -> 75663 | J6: =SUMIFS(Consolidated!$F:$F,Consolidated!$B:$B,J$4,Consolidated!$C:$C,J$5) -> 78978 | ... Q6: =SUMIFS(Consolidated!$F:$F,Consolidated!$B:$B,Q$4,Consolidated!$C:$C,Q$5) -> 67846
B7: M1 | C7: =SUMIFS(Consolidated!$G:$G,Consolidated!$B:$B,C$4,Consolidated!$C:$C,C$5) -> 73955 | D7: =SUMIFS(Consolidated!$G:$G,Consolidated!$B:$B,D$4,Consolidated!$C:$C,D$5) -> 68102 | E7: =SUMIFS(Consolidated!$G:$G,Consolidated!$B:$B,E$4,Consolidated!$C:$C,E$5) -> 85688 | F7: =SUMIFS(Consolidated!$G:$G,Consolidated!$B:$B,F$4,Consolidated!$C:$C,F$5) -> 75093 | G7: =SUMIFS(Consolidated!$G:$G,Consolidated!$B:$B,G$4,Consolidated!$C:$C,G$5) -> 75430 | H7: =SUMIFS(Consolidated!$G:$G,Consolidated!$B:$B,H$4,Consolidated!$C:$C,H$5) -> 75499 | I7: =SUMIFS(Consolidated!$G:$G,Consolidated!$B:$B,I$4,Consolidated!$C:$C,I$5) -> 77712 | J7: =SUMIFS(Consolidated!$G:$G,Consolidated!$B:$B,J$4,Consolidated!$C:$C,J$5) -> 82371 | ... Q7: =SUMIFS(Consolidated!$G:$G,Consolidated!$B:$B,Q$4,Consolidated!$C:$C,Q$5) -> 88381
B8: M2 | C8: =SUMIFS(Consolidated!$H:$H,Consolidated!$B:$B,C$4,Consolidated!$C:$C,C$5) -> 73148 | D8: =SUMIFS(Consolidated!$H:$H,Consolidated!$B:$B,D$4,Consolidated!$C:$C,D$5) -> 58587 | E8: =SUMIFS(Consolidated!$H:$H,Consolidated!$B:$B,E$4,Consolidated!$C:$C,E$5) -> 83786 | F8: =SUMIFS(Consolidated!$H:$H,Consolidated!$B:$B,F$4,Consolidated!$C:$C,F$5) -> 70245 | G8: =SUMIFS(Consolidated!$H:$H,Consolidated!$B:$B,G$4,Consolidated!$C:$C,G$5) -> 74723 | H8: =SUMIFS(Consolidated!$H:$H,Consolidated!$B:$B,H$4,Consolidated!$C:$C,H$5) -> 70027 | I8: =SUMIFS(Consolidated!$H:$H,Consolidated!$B:$B,I$4,Consolidated!$C:$C,I$5) -> 78078 | J8: =SUMIFS(Consolidated!$H:$H,Consolidated!$B:$B,J$4,Consolidated!$C:$C,J$5) -> 79767 | ... Q8: =SUMIFS(Consolidated!$H:$H,Consolidated!$B:$B,Q$4,Consolidated!$C:$C,Q$5) -> 88468
B9: M3 | C9: =SUMIFS(Consolidated!$I:$I,Consolidated!$B:$B,C$4,Consolidated!$C:$C,C$5) -> 71732 | D9: =SUMIFS(Consolidated!$I:$I,Consolidated!$B:$B,D$4,Consolidated!$C:$C,D$5) -> 59376 | E9: =SUMIFS(Consolidated!$I:$I,Consolidated!$B:$B,E$4,Consolidated!$C:$C,E$5) -> 79445 | F9: =SUMIFS(Consolidated!$I:$I,Consolidated!$B:$B,F$4,Consolidated!$C:$C,F$5) -> 71266 | G9: =SUMIFS(Consolidated!$I:$I,Consolidated!$B:$B,G$4,Consolidated!$C:$C,G$5) -> 76738 | H9: =SUMIFS(Consolidated!$I:$I,Consolidated!$B:$B,H$4,Consolidated!$C:$C,H$5) -> 67278 | I9: =SUMIFS(Consolidated!$I:$I,Consolidated!$B:$B,I$4,Consolidated!$C:$C,I$5) -> 83376 | J9: =SUMIFS(Consolidated!$I:$I,Consolidated!$B:$B,J$4,Consolidated!$C:$C,J$5) -> 77931 | ... Q9: =SUMIFS(Consolidated!$I:$I,Consolidated!$B:$B,Q$4,Consolidated!$C:$C,Q$5) -> 71599
B10: M4 | C10: =SUMIFS(Consolidated!$J:$J,Consolidated!$B:$B,C$4,Consolidated!$C:$C,C$5) -> 71428 | D10: =SUMIFS(Consolidated!$J:$J,Consolidated!$B:$B,D$4,Consolidated!$C:$C,D$5) -> 59336 | E10: =SUMIFS(Consolidated!$J:$J,Consolidated!$B:$B,E$4,Consolidated!$C:$C,E$5) -> 79613 | F10: =SUMIFS(Consolidated!$J:$J,Consolidated!$B:$B,F$4,Consolidated!$C:$C,F$5) -> 71388 | G10: =SUMIFS(Consolidated!$J:$J,Consolidated!$B:$B,G$4,Consolidated!$C:$C,G$5) -> 76741 | H10: =SUMIFS(Consolidated!$J:$J,Consolidated!$B:$B,H$4,Consolidated!$C:$C,H$5) -> 67298 | I10: =SUMIFS(Consolidated!$J:$J,Consolidated!$B:$B,I$4,Consolidated!$C:$C,I$5) -> 83116 | J10: =SUMIFS(Consolidated!$J:$J,Consolidated!$B:$B,J$4,Consolidated!$C:$C,J$5) -> 77954 | ... Q10: =SUMIFS(Consolidated!$J:$J,Consolidated!$B:$B,Q$4,Consolidated!$C:$C,Q$5) -> 71386
B11: M5 | C11: =SUMIFS(Consolidated!$K:$K,Consolidated!$B:$B,C$4,Consolidated!$C:$C,C$5) -> 70203 | D11: =SUMIFS(Consolidated!$K:$K,Consolidated!$B:$B,D$4,Consolidated!$C:$C,D$5) -> 63569 | E11: =SUMIFS(Consolidated!$K:$K,Consolidated!$B:$B,E$4,Consolidated!$C:$C,E$5) -> 75150 | F11: =SUMIFS(Consolidated!$K:$K,Consolidated!$B:$B,F$4,Consolidated!$C:$C,F$5) -> 71274 | G11: =SUMIFS(Consolidated!$K:$K,Consolidated!$B:$B,G$4,Consolidated!$C:$C,G$5) -> 73475 | H11: =SUMIFS(Consolidated!$K:$K,Consolidated!$B:$B,H$4,Consolidated!$C:$C,H$5) -> 66262 | I11: =SUMIFS(Consolidated!$K:$K,Consolidated!$B:$B,I$4,Consolidated!$C:$C,I$5) -> 78310 | J11: =SUMIFS(Consolidated!$K:$K,Consolidated!$B:$B,J$4,Consolidated!$C:$C,J$5) -> 75780 | ... Q11: =SUMIFS(Consolidated!$K:$K,Consolidated!$B:$B,Q$4,Consolidated!$C:$C,Q$5) -> 66279
B12: M6 | C12: =SUMIFS(Consolidated!$L:$L,Consolidated!$B:$B,C$4,Consolidated!$C:$C,C$5) -> 67095 | D12: =SUMIFS(Consolidated!$L:$L,Consolidated!$B:$B,D$4,Consolidated!$C:$C,D$5) -> 83768 | E12: =SUMIFS(Consolidated!$L:$L,Consolidated!$B:$B,E$4,Consolidated!$C:$C,E$5) -> 59748 | F12: =SUMIFS(Consolidated!$L:$L,Consolidated!$B:$B,F$4,Consolidated!$C:$C,F$5) -> 78274 | G12: =SUMIFS(Consolidated!$L:$L,Consolidated!$B:$B,G$4,Consolidated!$C:$C,G$5) -> 61223 | H12: =SUMIFS(Consolidated!$L:$L,Consolidated!$B:$B,H$4,Consolidated!$C:$C,H$5) -> 59177 | I12: =SUMIFS(Consolidated!$L:$L,Consolidated!$B:$B,I$4,Consolidated!$C:$C,I$5) -> 87952 | J12: =SUMIFS(Consolidated!$L:$L,Consolidated!$B:$B,J$4,Consolidated!$C:$C,J$5) -> 68742 | ... Q12: =SUMIFS(Consolidated!$L:$L,Consolidated!$B:$B,Q$4,Consolidated!$C:$C,Q$5) -> 64232
B13: M7 | C13: =SUMIFS(Consolidated!$M:$M,Consolidated!$B:$B,C$4,Consolidated!$C:$C,C$5) -> 69912 | D13: =SUMIFS(Consolidated!$M:$M,Consolidated!$B:$B,D$4,Consolidated!$C:$C,D$5) -> 64223 | E13: =SUMIFS(Consolidated!$M:$M,Consolidated!$B:$B,E$4,Consolidated!$C:$C,E$5) -> 75344 | F13: =SUMIFS(Consolidated!$M:$M,Consolidated!$B:$B,F$4,Consolidated!$C:$C,F$5) -> 71290 | G13: =SUMIFS(Consolidated!$M:$M,Consolidated!$B:$B,G$4,Consolidated!$C:$C,G$5) -> 73818 | H13: =SUMIFS(Consolidated!$M:$M,Consolidated!$B:$B,H$4,Consolidated!$C:$C,H$5) -> 66365 | I13: =SUMIFS(Consolidated!$M:$M,Consolidated!$B:$B,I$4,Consolidated!$C:$C,I$5) -> 78407 | J13: =SUMIFS(Consolidated!$M:$M,Consolidated!$B:$B,J$4,Consolidated!$C:$C,J$5) -> 75947 | ... Q13: =SUMIFS(Consolidated!$M:$M,Consolidated!$B:$B,Q$4,Consolidated!$C:$C,Q$5) -> 66831
B14: M6xM7 | C14: =SUMIFS(Consolidated!$N:$N,Consolidated!$B:$B,C$4,Consolidated!$C:$C,C$5) -> 70408 | D14: =SUMIFS(Consolidated!$N:$N,Consolidated!$B:$B,D$4,Consolidated!$C:$C,D$5) -> 87127 | E14: =SUMIFS(Consolidated!$N:$N,Consolidated!$B:$B,E$4,Consolidated!$C:$C,E$5) -> 78400 | F14: =SUMIFS(Consolidated!$N:$N,Consolidated!$B:$B,F$4,Consolidated!$C:$C,F$5) -> 67869 | G14: =SUMIFS(Consolidated!$N:$N,Consolidated!$B:$B,G$4,Consolidated!$C:$C,G$5) -> 69392 | H14: =SUMIFS(Consolidated!$N:$N,Consolidated!$B:$B,H$4,Consolidated!$C:$C,H$5) -> 63271 | I14: =SUMIFS(Consolidated!$N:$N,Consolidated!$B:$B,I$4,Consolidated!$C:$C,I$5) -> 73169 | J14: =SUMIFS(Consolidated!$N:$N,Consolidated!$B:$B,J$4,Consolidated!$C:$C,J$5) -> 78324 | ... Q14: =SUMIFS(Consolidated!$N:$N,Consolidated!$B:$B,Q$4,Consolidated!$C:$C,Q$5) -> 53840
B15: M8 | C15: =SUMIFS(Consolidated!$O:$O,Consolidated!$B:$B,C$4,Consolidated!$C:$C,C$5) -> 72807 | D15: =SUMIFS(Consolidated!$O:$O,Consolidated!$B:$B,D$4,Consolidated!$C:$C,D$5) -> 67581 | E15: =SUMIFS(Consolidated!$O:$O,Consolidated!$B:$B,E$4,Consolidated!$C:$C,E$5) -> 78391 | F15: =SUMIFS(Consolidated!$O:$O,Consolidated!$B:$B,F$4,Consolidated!$C:$C,F$5) -> 66854 | G15: =SUMIFS(Consolidated!$O:$O,Consolidated!$B:$B,G$4,Consolidated!$C:$C,G$5) -> 75555 | H15: =SUMIFS(Consolidated!$O:$O,Consolidated!$B:$B,H$4,Consolidated!$C:$C,H$5) -> 66709 | I15: =SUMIFS(Consolidated!$O:$O,Consolidated!$B:$B,I$4,Consolidated!$C:$C,I$5) -> 80872 | J15: =SUMIFS(Consolidated!$O:$O,Consolidated!$B:$B,J$4,Consolidated!$C:$C,J$5) -> 77569 | ... Q15: =SUMIFS(Consolidated!$O:$O,Consolidated!$B:$B,Q$4,Consolidated!$C:$C,Q$5) -> 66298
A16: MSE
B17: M1 | C17: =(C7-C$6)^2 -> 401000625 | D17: =(D7-D$6)^2 -> 600625 | E17: =(E7-E$6)^2 -> 73393489 | F17: =(F7-F$6)^2 -> 97871449 | G17: =(G7-G$6)^2 -> 1075369 | H17: =(H7-H$6)^2 -> 276922881 | I17: =(I7-I$6)^2 -> 4198401 | J17: =(J7-J$6)^2 -> 11512449 | ... Q17: =(Q7-Q$6)^2 -> 421686225 | S17: =SQRT(AVERAGE(C17:Q17)) -> 10684.174 | U17: =LN(4900) -> 8.4969905
B18: M2 | C18: =(C8-C$6)^2 -> 369331524 | D18: =(D8-D$6)^2 -> 76387600 | E18: =(E8-E$6)^2 -> 44422225 | F18: =(F8-F$6)^2 -> 25452025 | G18: =(G8-G$6)^2 -> 108900 | H18: =(H8-H$6)^2 -> 124746561 | I18: =(I8-I$6)^2 -> 5832225 | J18: =(J8-J$6)^2 -> 622521 | ... Q18: =(Q8-Q$6)^2 -> 425266884 | S18: =SQRT(AVERAGE(C18:Q18)) -> 9233.8631 | U18: =900000/365 -> 2465.7534
B19: M3 | C19: =(C9-C$6)^2 -> 316911204 | D19: =(D9-D$6)^2 -> 63218401 | E19: =(E9-E$6)^2 -> 5400976 | F19: =(F9-F$6)^2 -> 36796356 | G19: =(G9-G$6)^2 -> 5499025 | H19: =(H9-H$6)^2 -> 70896400 | I19: =(I9-I$6)^2 -> 59490369 | J19: =(J9-J$6)^2 -> 1096209 | ... Q19: =(Q9-Q$6)^2 -> 14085009 | S19: =SQRT(AVERAGE(C19:Q19)) -> 6739.5612 | U19: =LN(U18) -> 7.8102527
B20: M4 | C20: =(C10-C$6)^2 -> 306180004 | D20: =(D10-D$6)^2 -> 63856081 | E20: =(E10-E$6)^2 -> 6210064 | F20: =(F10-F$6)^2 -> 38291344 | G20: =(G10-G$6)^2 -> 5513104 | H20: =(H10-H$6)^2 -> 71233600 | I20: =(I10-I$6)^2 -> 55547209 | J20: =(J10-J$6)^2 -> 1048576 | ... Q20: =(Q10-Q$6)^2 -> 12531600 | S20: =SQRT(AVERAGE(C20:Q20)) -> 6683.1995
B21: M5 | C21: =(C11-C$6)^2 -> 264810529 | D21: =(D11-D$6)^2 -> 14122564 | E21: =(E11-E$6)^2 -> 3884841 | F21: =(F11-F$6)^2 -> 36893476 | G21: =(G11-G$6)^2 -> 842724 | H21: =(H11-H$6)^2 -> 54819216 | I21: =(I11-I$6)^2 -> 7006609 | J21: =(J11-J$6)^2 -> 10227204 | ... Q21: =(Q11-Q$6)^2 -> 2455489 | S21: =SQRT(AVERAGE(C21:Q21)) -> 6043.5943
B22: M6 | C22: =(C12-C$6)^2 -> 173317225 | D22: =(D12-D$6)^2 -> 270306481 | E22: =(E12-E$6)^2 -> 301821129 | F22: =(F12-F$6)^2 -> 170929476 | G22: =(G12-G$6)^2 -> 173448900 | H22: =(H12-H$6)^2 -> 101761 | I22: =(I12-I$6)^2 -> 151019521 | J22: =(J12-J$6)^2 -> 104775696 | ... Q22: =(Q12-Q$6)^2 -> 13060996 | S22: =SQRT(AVERAGE(C22:Q22)) -> 11709.587
B23: M7 | C23: =(C13-C$6)^2 -> 255424324 | D23: =(D13-D$6)^2 -> 9634816 | E23: =(E13-E$6)^2 -> 3157729 | F23: =(F13-F$6)^2 -> 37088100 | G23: =(G13-G$6)^2 -> 330625 | H23: =(H13-H$6)^2 -> 56355049 | I23: =(I13-I$6)^2 -> 7529536 | J23: =(J13-J$6)^2 -> 9186961 | ... Q23: =(Q13-Q$6)^2 -> 1030225 | S23: =SQRT(AVERAGE(C23:Q23)) -> 5920.5126
B24: M6xM7 | C24: =(C14-C$6)^2 -> 271524484 | D24: =(D14-D$6)^2 -> 392040000 | E24: =(E14-E$6)^2 -> 1635841 | F24: =(F14-F$6)^2 -> 7123561 | G24: =(G14-G$6)^2 -> 25010001 | H24: =(H14-H$6)^2 -> 19474569 | I24: =(I14-I$6)^2 -> 6220036 | J24: =(J14-J$6)^2 -> 427716 | ... Q24: =(Q14-Q$6)^2 -> 196168036 | S24: =SQRT(AVERAGE(C24:Q24)) -> 9710.5509
B25: M8 | C25: =(C15-C$6)^2 -> 356341129 | D25: =(D15-D$6)^2 -> 64516 | E25: =(E15-E$6)^2 -> 1612900 | F25: =(F15-F$6)^2 -> 2735716 | G25: =(G15-G$6)^2 -> 1350244 | H25: =(H15-H$6)^2 -> 61638201 | I25: =(I15-I$6)^2 -> 27133681 | J25: =(J15-J$6)^2 -> 1985281 | ... Q25: =(Q15-Q$6)^2 -> 2396304 | S25: =SQRT(AVERAGE(C25:Q25)) -> 6437.9242
A60: Monthly Seasonality Cross-Validation
B62: Day | C62: 1 | D62: =C62+1 -> 2 | E62: =D62+1 -> 3 | F62: =E62+1 -> 4 | G62: =F62+1 -> 5 | H62: =G62+1 -> 6 | I62: =H62+1 -> 7 | J62: =I62+1 -> 8 | K62: =J62+1 -> 9 | ... AG62: =AF62+1 -> 31
B63: Actual | C63: =AVERAGEIFS(Consolidated!$F:$F,Consolidated!$D:$D,C$62) -> 385.53333 | D63: =AVERAGEIFS(Consolidated!$F:$F,Consolidated!$D:$D,D$62) -> 454.33333 | E63: =AVERAGEIFS(Consolidated!$F:$F,Consolidated!$D:$D,E$62) -> 558.4 | F63: =AVERAGEIFS(Consolidated!$F:$F,Consolidated!$D:$D,F$62) -> 654.4 | G63: =AVERAGEIFS(Consolidated!$F:$F,Consolidated!$D:$D,G$62) -> 755.46667 | H63: =AVERAGEIFS(Consolidated!$F:$F,Consolidated!$D:$D,H$62) -> 865.6 | I63: =AVERAGEIFS(Consolidated!$F:$F,Consolidated!$D:$D,I$62) -> 822.66667 | J63: =AVERAGEIFS(Consolidated!$F:$F,Consolidated!$D:$D,J$62) -> 875.26667 | ... AG63: =AVERAGEIFS(Consolidated!$F:$F,Consolidated!$D:$D,AG$62) -> 8048.5556
B64: M1 | C64: =AVERAGEIFS(Consolidated!$G:$G,Consolidated!$D:$D,C$62) -> 2482.0667 | D64: =AVERAGEIFS(Consolidated!$G:$G,Consolidated!$D:$D,D$62) -> 2754.4 | E64: =AVERAGEIFS(Consolidated!$G:$G,Consolidated!$D:$D,E$62) -> 2975 | F64: =AVERAGEIFS(Consolidated!$G:$G,Consolidated!$D:$D,F$62) -> 2882 | G64: =AVERAGEIFS(Consolidated!$G:$G,Consolidated!$D:$D,G$62) -> 2823.3333 | H64: =AVERAGEIFS(Consolidated!$G:$G,Consolidated!$D:$D,H$62) -> 2831.0667 | I64: =AVERAGEIFS(Consolidated!$G:$G,Consolidated!$D:$D,I$62) -> 2660.5333 | J64: =AVERAGEIFS(Consolidated!$G:$G,Consolidated!$D:$D,J$62) -> 2446.3333 | ... AG64: =AVERAGEIFS(Consolidated!$G:$G,Consolidated!$D:$D,AG$62) -> 2378.2222
B65: M2 | C65: =AVERAGEIFS(Consolidated!$H:$H,Consolidated!$D:$D,C$62) -> 4603.4667 | D65: =AVERAGEIFS(Consolidated!$H:$H,Consolidated!$D:$D,D$62) -> 3469.0667 | E65: =AVERAGEIFS(Consolidated!$H:$H,Consolidated!$D:$D,E$62) -> 2075.3333 | F65: =AVERAGEIFS(Consolidated!$H:$H,Consolidated!$D:$D,F$62) -> 1295.5333 | G65: =AVERAGEIFS(Consolidated!$H:$H,Consolidated!$D:$D,G$62) -> 1051.2 | H65: =AVERAGEIFS(Consolidated!$H:$H,Consolidated!$D:$D,H$62) -> 1217.4667 | I65: =AVERAGEIFS(Consolidated!$H:$H,Consolidated!$D:$D,I$62) -> 1236.8 | J65: =AVERAGEIFS(Consolidated!$H:$H,Consolidated!$D:$D,J$62) -> 1203.4 | ... AG65: =AVERAGEIFS(Consolidated!$H:$H,Consolidated!$D:$D,AG$62) -> 5540.5556
B66: M3 | C66: =AVERAGEIFS(Consolidated!$I:$I,Consolidated!$D:$D,C$62) -> 4041.4667 | D66: =AVERAGEIFS(Consolidated!$I:$I,Consolidated!$D:$D,D$62) -> 3444.6667 | E66: =AVERAGEIFS(Consolidated!$I:$I,Consolidated!$D:$D,E$62) -> 2119.2667 | F66: =AVERAGEIFS(Consolidated!$I:$I,Consolidated!$D:$D,F$62) -> 1368.9333 | G66: =AVERAGEIFS(Consolidated!$I:$I,Consolidated!$D:$D,G$62) -> 1091.0667 | H66: =AVERAGEIFS(Consolidated!$I:$I,Consolidated!$D:$D,H$62) -> 1223.5333 | I66: =AVERAGEIFS(Consolidated!$I:$I,Consolidated!$D:$D,I$62) -> 1226.9333 | J66: =AVERAGEIFS(Consolidated!$I:$I,Consolidated!$D:$D,J$62) -> 1153.8 | ... AG66: =AVERAGEIFS(Consolidated!$I:$I,Consolidated!$D:$D,AG$62) -> 5326.3333
B67: M4 | C67: =AVERAGEIFS(Consolidated!$J:$J,Consolidated!$D:$D,C$62) -> 4038.9333 | D67: =AVERAGEIFS(Consolidated!$J:$J,Consolidated!$D:$D,D$62) -> 3442.1333 | E67: =AVERAGEIFS(Consolidated!$J:$J,Consolidated!$D:$D,E$62) -> 2120.3333 | F67: =AVERAGEIFS(Consolidated!$J:$J,Consolidated!$D:$D,F$62) -> 1369.3333 | G67: =AVERAGEIFS(Consolidated!$J:$J,Consolidated!$D:$D,G$62) -> 1089.8667 | H67: =AVERAGEIFS(Consolidated!$J:$J,Consolidated!$D:$D,H$62) -> 1221.7333 | I67: =AVERAGEIFS(Consolidated!$J:$J,Consolidated!$D:$D,I$62) -> 1224.6 | J67: =AVERAGEIFS(Consolidated!$J:$J,Consolidated!$D:$D,J$62) -> 1153.5333 | ... AG67: =AVERAGEIFS(Consolidated!$J:$J,Consolidated!$D:$D,AG$62) -> 5322.5556
B68: M5 | C68: =AVERAGEIFS(Consolidated!$K:$K,Consolidated!$D:$D,C$62) -> 1052.3333 | D68: =AVERAGEIFS(Consolidated!$K:$K,Consolidated!$D:$D,D$62) -> 1237 | E68: =AVERAGEIFS(Consolidated!$K:$K,Consolidated!$D:$D,E$62) -> 1130.0667 | F68: =AVERAGEIFS(Consolidated!$K:$K,Consolidated!$D:$D,F$62) -> 1156.8667 | G68: =AVERAGEIFS(Consolidated!$K:$K,Consolidated!$D:$D,G$62) -> 1131 | H68: =AVERAGEIFS(Consolidated!$K:$K,Consolidated!$D:$D,H$62) -> 1175.2 | I68: =AVERAGEIFS(Consolidated!$K:$K,Consolidated!$D:$D,I$62) -> 1025.2667 | J68: =AVERAGEIFS(Consolidated!$K:$K,Consolidated!$D:$D,J$62) -> 1308.6667 | ... AG68: =AVERAGEIFS(Consolidated!$K:$K,Consolidated!$D:$D,AG$62) -> 8403.5556
B69: M6 | C69: =AVERAGEIFS(Consolidated!$L:$L,Consolidated!$D:$D,C$62) -> 345.86667 | D69: =AVERAGEIFS(Consolidated!$L:$L,Consolidated!$D:$D,D$62) -> 383.6 | E69: =AVERAGEIFS(Consolidated!$L:$L,Consolidated!$D:$D,E$62) -> 660.73333 | F69: =AVERAGEIFS(Consolidated!$L:$L,Consolidated!$D:$D,F$62) -> 646.53333 | G69: =AVERAGEIFS(Consolidated!$L:$L,Consolidated!$D:$D,G$62) -> 592.93333 | H69: =AVERAGEIFS(Consolidated!$L:$L,Consolidated!$D:$D,H$62) -> 611.06667 | I69: =AVERAGEIFS(Consolidated!$L:$L,Consolidated!$D:$D,I$62) -> 594.93333 | J69: =AVERAGEIFS(Consolidated!$L:$L,Consolidated!$D:$D,J$62) -> 1047.8667 | ... AG69: =AVERAGEIFS(Consolidated!$L:$L,Consolidated!$D:$D,AG$62) -> 10819.667
B70: M7 | C70: =AVERAGEIFS(Consolidated!$M:$M,Consolidated!$D:$D,C$62) -> 1080.8 | D70: =AVERAGEIFS(Consolidated!$M:$M,Consolidated!$D:$D,D$62) -> 1105.6 | E70: =AVERAGEIFS(Consolidated!$M:$M,Consolidated!$D:$D,E$62) -> 1070.1333 | F70: =AVERAGEIFS(Consolidated!$M:$M,Consolidated!$D:$D,F$62) -> 1188.4 | G70: =AVERAGEIFS(Consolidated!$M:$M,Consolidated!$D:$D,G$62) -> 1131.2 | H70: =AVERAGEIFS(Consolidated!$M:$M,Consolidated!$D:$D,H$62) -> 1148.4667 | I70: =AVERAGEIFS(Consolidated!$M:$M,Consolidated!$D:$D,I$62) -> 1005.2 | J70: =AVERAGEIFS(Consolidated!$M:$M,Consolidated!$D:$D,J$62) -> 1314.9333 | ... AG70: =AVERAGEIFS(Consolidated!$M:$M,Consolidated!$D:$D,AG$62) -> 8591.6667
B71: M6xM7 | C71: =AVERAGEIFS(Consolidated!$N:$N,Consolidated!$D:$D,C$62) -> 345.86667 | D71: =AVERAGEIFS(Consolidated!$N:$N,Consolidated!$D:$D,D$62) -> 383.6 | E71: =AVERAGEIFS(Consolidated!$N:$N,Consolidated!$D:$D,E$62) -> 660.73333 | F71: =AVERAGEIFS(Consolidated!$N:$N,Consolidated!$D:$D,F$62) -> 646.53333 | G71: =AVERAGEIFS(Consolidated!$N:$N,Consolidated!$D:$D,G$62) -> 700.53333 | H71: =AVERAGEIFS(Consolidated!$N:$N,Consolidated!$D:$D,H$62) -> 880.06667 | I71: =AVERAGEIFS(Consolidated!$N:$N,Consolidated!$D:$D,I$62) -> 800.4 | J71: =AVERAGEIFS(Consolidated!$N:$N,Consolidated!$D:$D,J$62) -> 1181.5333 | ... AG71: =AVERAGEIFS(Consolidated!$N:$N,Consolidated!$D:$D,AG$62) -> 8591.6667
B72: M8 | C72: =AVERAGEIFS(Consolidated!$O:$O,Consolidated!$D:$D,C$62) -> 1089.4667 | D72: =AVERAGEIFS(Consolidated!$O:$O,Consolidated!$D:$D,D$62) -> 1129.9333 | E72: =AVERAGEIFS(Consolidated!$O:$O,Consolidated!$D:$D,E$62) -> 1187.6667 | F72: =AVERAGEIFS(Consolidated!$O:$O,Consolidated!$D:$D,F$62) -> 1273.4 | G72: =AVERAGEIFS(Consolidated!$O:$O,Consolidated!$D:$D,G$62) -> 1201.6667 | H72: =AVERAGEIFS(Consolidated!$O:$O,Consolidated!$D:$D,H$62) -> 1200.0667 | I72: =AVERAGEIFS(Consolidated!$O:$O,Consolidated!$D:$D,I$62) -> 1019.8667 | J72: =AVERAGEIFS(Consolidated!$O:$O,Consolidated!$D:$D,J$62) -> 1690.8 | ... AG72: =AVERAGEIFS(Consolidated!$O:$O,Consolidated!$D:$D,AG$62) -> 8516.5556
A73: MSE
B74: M1 | C74: =(C64-C$63)^2 -> 4395452 | D74: =(D64-D$63)^2 -> 5290306.7 | E74: =(E64-E$63)^2 -> 5839955.6 | F74: =(F64-F$63)^2 -> 4962201.8 | G74: =(G64-G$63)^2 -> 4276072.6 | H74: =(H64-H$63)^2 -> 3863059.2 | I74: =(I64-I$63)^2 -> 3377753.9 | J74: =(J64-J$63)^2 -> 2468250.5 | ... AG74: =(AG64-AG$63)^2 -> 32152680 | AI74: =SQRT(AVERAGE(C74:AG74)) -> 2090.566
B75: M2 | C75: =(C65-C$63)^2 -> 17790962 | D75: =(D65-D$63)^2 -> 9088617.1 | E75: =(E65-E$63)^2 -> 2301086.7 | F75: =(F65-F$63)^2 -> 411051.95 | G75: =(G65-G$63)^2 -> 87458.204 | H75: =(H65-H$63)^2 -> 123810.15 | I75: =(I65-I$63)^2 -> 171506.42 | J75: =(J65-J$63)^2 -> 107671.48 | ... AG75: =(AG65-AG$63)^2 -> 6290064 | AI75: =SQRT(AVERAGE(C75:AG75)) -> 1218.4412
B76: M3 | C76: =(C66-C$63)^2 -> 13365849 | D76: =(D66-D$63)^2 -> 8942093.4 | E76: =(E66-E$63)^2 -> 2436304.8 | F76: =(F66-F$63)^2 -> 510557.88 | G76: =(G66-G$63)^2 -> 112627.36 | H76: =(H66-H$63)^2 -> 128116.27 | I76: =(I66-I$63)^2 -> 163431.54 | J76: =(J66-J$63)^2 -> 77580.818 | ... AG76: =(AG66-AG$63)^2 -> 7410493.8 | AI76: =SQRT(AVERAGE(C76:AG76)) -> 1177.9276
B77: M4 | C77: =(C67-C$63)^2 -> 13347332 | D77: =(D67-D$63)^2 -> 8926948.8 | E77: =(E67-E$63)^2 -> 2439635.7 | F77: =(F67-F$63)^2 -> 511129.67 | G77: =(G67-G$63)^2 -> 111823.36 | H77: =(H67-H$63)^2 -> 126830.95 | I77: =(I67-I$63)^2 -> 161550.4 | J77: =(J67-J$63)^2 -> 77432.338 | ... AG77: =(AG67-AG$63)^2 -> 7431076 | AI77: =SQRT(AVERAGE(C77:AG77)) -> 1178.349
...

Sheet Consolidated
A1: Date | B1: Year | C1: Month | D1: Day | E1: Cutoff | F1: Actual | G1: M1 | H1: M2 | I1: M3 | J1: M4 | K1: M5 | L1: M6 | M1: M7 | N1: M6xM7 | O1: M8
A2: 45658 | B2: =YEAR($A2) -> 2025 | C2: =MONTH($A2) -> 1 | D2: =DAY($A2) -> 1 | E2: =DATE($B2,$C2,1)-1 -> 45657 | F2: =_xlfn.XLOOKUP($A2,m1_cv!$B:$B,m1_cv!$C:$C) -> 90 | G2: =MAX(0,ROUND(SUMIFS(m1_cv!$E:$E,m1_cv!$A:$A,$E2,m1_cv!$B:$B,$A2),0)) -> 3522 | H2: =MAX(0,ROUND(SUMIFS(m2_cv!$E:$E,m2_cv!$A:$A,$E2,m2_cv!$B:$B,$A2),0)) -> 4096 | I2: =MAX(0,ROUND(SUMIFS(m3_cv!$E:$E,m3_cv!$A:$A,$E2,m3_cv!$B:$B,$A2),0)) -> 2895 | J2: =MAX(0,ROUND(SUMIFS(m4_cv!$E:$E,m4_cv!$A:$A,$E2,m4_cv!$B:$B,$A2),0)) -> 2889 | K2: =MAX(0,ROUND(SUMIFS(m5_cv!$E:$E,m5_cv!$A:$A,$E2,m5_cv!$B:$B,$A2),0)) -> 626 | L2: =MAX(0,ROUND(SUMIFS(m6_cv!$E:$E,m6_cv!$A:$A,$E2,m6_cv!$B:$B,$A2),0)) -> 93 | M2: =MAX(0,ROUND(SUMIFS(m7_cv!$E:$E,m7_cv!$A:$A,$E2,m7_cv!$B:$B,$A2),0)) -> 490 | N2: =ROUND(_xlfn.XLOOKUP($D2,Charts!$W$86:$W$116,Charts!$X$86:$X$116)*$L2+_xlfn.XLOOKUP($D2,Charts!$W$86:$W$116,Charts!$Y$86:$Y$116)*$M2,0) -> 93 | O2: =MAX(0,ROUND(SUMIFS(m8_cv!$E:$E,m8_cv!$A:$A,$E2,m8_cv!$B:$B,$A2),0)) -> 553
A3: =A2+1 -> 45659 | B3: =YEAR(A3) -> 2025 | C3: =MONTH($A3) -> 1 | D3: =DAY($A3) -> 2 | E3: =DATE($B3,$C3,1)-1 -> 45657 | F3: =_xlfn.XLOOKUP($A3,m1_cv!$B:$B,m1_cv!$C:$C) -> 541 | G3: =MAX(0,ROUND(SUMIFS(m1_cv!$E:$E,m1_cv!$A:$A,$E3,m1_cv!$B:$B,$A3),0)) -> 3467 | H3: =MAX(0,ROUND(SUMIFS(m2_cv!$E:$E,m2_cv!$A:$A,$E3,m2_cv!$B:$B,$A3),0)) -> 2253 | I3: =MAX(0,ROUND(SUMIFS(m3_cv!$E:$E,m3_cv!$A:$A,$E3,m3_cv!$B:$B,$A3),0)) -> 2572 | J3: =MAX(0,ROUND(SUMIFS(m4_cv!$E:$E,m4_cv!$A:$A,$E3,m4_cv!$B:$B,$A3),0)) -> 2563 | K3: =MAX(0,ROUND(SUMIFS(m5_cv!$E:$E,m5_cv!$A:$A,$E3,m5_cv!$B:$B,$A3),0)) -> 1723 | L3: =MAX(0,ROUND(SUMIFS(m6_cv!$E:$E,m6_cv!$A:$A,$E3,m6_cv!$B:$B,$A3),0)) -> 556 | M3: =MAX(0,ROUND(SUMIFS(m7_cv!$E:$E,m7_cv!$A:$A,$E3,m7_cv!$B:$B,$A3),0)) -> 1782 | N3: =ROUND(_xlfn.XLOOKUP($D3,Charts!$W$86:$W$116,Charts!$X$86:$X$116)*$L3+_xlfn.XLOOKUP($D3,Charts!$W$86:$W$116,Charts!$Y$86:$Y$116)*$M3,0) -> 556 | O3: =MAX(0,ROUND(SUMIFS(m8_cv!$E:$E,m8_cv!$A:$A,$E3,m8_cv!$B:$B,$A3),0)) -> 1882
A4: =A3+1 -> 45660 | B4: =YEAR(A4) -> 2025 | C4: =MONTH($A4) -> 1 | D4: =DAY($A4) -> 3 | E4: =DATE($B4,$C4,1)-1 -> 45657 | F4: =_xlfn.XLOOKUP($A4,m1_cv!$B:$B,m1_cv!$C:$C) -> 563 | G4: =MAX(0,ROUND(SUMIFS(m1_cv!$E:$E,m1_cv!$A:$A,$E4,m1_cv!$B:$B,$A4),0)) -> 3307 | H4: =MAX(0,ROUND(SUMIFS(m2_cv!$E:$E,m2_cv!$A:$A,$E4,m2_cv!$B:$B,$A4),0)) -> 1153 | I4: =MAX(0,ROUND(SUMIFS(m3_cv!$E:$E,m3_cv!$A:$A,$E4,m3_cv!$B:$B,$A4),0)) -> 1356 | J4: =MAX(0,ROUND(SUMIFS(m4_cv!$E:$E,m4_cv!$A:$A,$E4,m4_cv!$B:$B,$A4),0)) -> 1348 | K4: =MAX(0,ROUND(SUMIFS(m5_cv!$E:$E,m5_cv!$A:$A,$E4,m5_cv!$B:$B,$A4),0)) -> 1710 | L4: =MAX(0,ROUND(SUMIFS(m6_cv!$E:$E,m6_cv!$A:$A,$E4,m6_cv!$B:$B,$A4),0)) -> 640 | M4: =MAX(0,ROUND(SUMIFS(m7_cv!$E:$E,m7_cv!$A:$A,$E4,m7_cv!$B:$B,$A4),0)) -> 1824 | N4: =ROUND(_xlfn.XLOOKUP($D4,Charts!$W$86:$W$116,Charts!$X$86:$X$116)*$L4+_xlfn.XLOOKUP($D4,Charts!$W$86:$W$116,Charts!$Y$86:$Y$116)*$M4,0) -> 640 | O4: =MAX(0,ROUND(SUMIFS(m8_cv!$E:$E,m8_cv!$A:$A,$E4,m8_cv!$B:$B,$A4),0)) -> 2003
A5: =A4+1 -> 45661 | B5: =YEAR(A5) -> 2025 | C5: =MONTH($A5) -> 1 | D5: =DAY($A5) -> 4 | E5: =DATE($B5,$C5,1)-1 -> 45657 | F5: =_xlfn.XLOOKUP($A5,m1_cv!$B:$B,m1_cv!$C:$C) -> 42 | G5: =MAX(0,ROUND(SUMIFS(m1_cv!$E:$E,m1_cv!$A:$A,$E5,m1_cv!$B:$B,$A5),0)) -> 1098 | H5: =MAX(0,ROUND(SUMIFS(m2_cv!$E:$E,m2_cv!$A:$A,$E5,m2_cv!$B:$B,$A5),0)) -> 0 | I5: =MAX(0,ROUND(SUMIFS(m3_cv!$E:$E,m3_cv!$A:$A,$E5,m3_cv!$B:$B,$A5),0)) -> 0 | J5: =MAX(0,ROUND(SUMIFS(m4_cv!$E:$E,m4_cv!$A:$A,$E5,m4_cv!$B:$B,$A5),0)) -> 0 | K5: =MAX(0,ROUND(SUMIFS(m5_cv!$E:$E,m5_cv!$A:$A,$E5,m5_cv!$B:$B,$A5),0)) -> 0 | L5: =MAX(0,ROUND(SUMIFS(m6_cv!$E:$E,m6_cv!$A:$A,$E5,m6_cv!$B:$B,$A5),0)) -> 108 | M5: =MAX(0,ROUND(SUMIFS(m7_cv!$E:$E,m7_cv!$A:$A,$E5,m7_cv!$B:$B,$A5),0)) -> 0 | N5: =ROUND(_xlfn.XLOOKUP($D5,Charts!$W$86:$W$116,Charts!$X$86:$X$116)*$L5+_xlfn.XLOOKUP($D5,Charts!$W$86:$W$116,Charts!$Y$86:$Y$116)*$M5,0) -> 108 | O5: =MAX(0,ROUND(SUMIFS(m8_cv!$E:$E,m8_cv!$A:$A,$E5,m8_cv!$B:$B,$A5),0)) -> 0
A6: =A5+1 -> 45662 | B6: =YEAR(A6) -> 2025 | C6: =MONTH($A6) -> 1 | D6: =DAY($A6) -> 5 | E6: =DATE($B6,$C6,1)-1 -> 45657 | F6: =_xlfn.XLOOKUP($A6,m1_cv!$B:$B,m1_cv!$C:$C) -> 22 | G6: =MAX(0,ROUND(SUMIFS(m1_cv!$E:$E,m1_cv!$A:$A,$E6,m1_cv!$B:$B,$A6),0)) -> 505 | H6: =MAX(0,ROUND(SUMIFS(m2_cv!$E:$E,m2_cv!$A:$A,$E6,m2_cv!$B:$B,$A6),0)) -> 0 | I6: =MAX(0,ROUND(SUMIFS(m3_cv!$E:$E,m3_cv!$A:$A,$E6,m3_cv!$B:$B,$A6),0)) -> 0 | J6: =MAX(0,ROUND(SUMIFS(m4_cv!$E:$E,m4_cv!$A:$A,$E6,m4_cv!$B:$B,$A6),0)) -> 0 | K6: =MAX(0,ROUND(SUMIFS(m5_cv!$E:$E,m5_cv!$A:$A,$E6,m5_cv!$B:$B,$A6),0)) -> 0 | L6: =MAX(0,ROUND(SUMIFS(m6_cv!$E:$E,m6_cv!$A:$A,$E6,m6_cv!$B:$B,$A6),0)) -> 48 | M6: =MAX(0,ROUND(SUMIFS(m7_cv!$E:$E,m7_cv!$A:$A,$E6,m7_cv!$B:$B,$A6),0)) -> 0 | N6: =ROUND(_xlfn.XLOOKUP($D6,Charts!$W$86:$W$116,Charts!$X$86:$X$116)*$L6+_xlfn.XLOOKUP($D6,Charts!$W$86:$W$116,Charts!$Y$86:$Y$116)*$M6,0) -> 38 | O6: =MAX(0,ROUND(SUMIFS(m8_cv!$E:$E,m8_cv!$A:$A,$E6,m8_cv!$B:$B,$A6),0)) -> 0
A7: =A6+1 -> 45663 | B7: =YEAR(A7) -> 2025 | C7: =MONTH($A7) -> 1 | D7: =DAY($A7) -> 6 | E7: =DATE($B7,$C7,1)-1 -> 45657 | F7: =_xlfn.XLOOKUP($A7,m1_cv!$B:$B,m1_cv!$C:$C) -> 533 | G7: =MAX(0,ROUND(SUMIFS(m1_cv!$E:$E,m1_cv!$A:$A,$E7,m1_cv!$B:$B,$A7),0)) -> 2745 | H7: =MAX(0,ROUND(SUMIFS(m2_cv!$E:$E,m2_cv!$A:$A,$E7,m2_cv!$B:$B,$A7),0)) -> 1504 | I7: =MAX(0,ROUND(SUMIFS(m3_cv!$E:$E,m3_cv!$A:$A,$E7,m3_cv!$B:$B,$A7),0)) -> 1781 | J7: =MAX(0,ROUND(SUMIFS(m4_cv!$E:$E,m4_cv!$A:$A,$E7,m4_cv!$B:$B,$A7),0)) -> 1771 | K7: =MAX(0,ROUND(SUMIFS(m5_cv!$E:$E,m5_cv!$A:$A,$E7,m5_cv!$B:$B,$A7),0)) -> 1412 | L7: =MAX(0,ROUND(SUMIFS(m6_cv!$E:$E,m6_cv!$A:$A,$E7,m6_cv!$B:$B,$A7),0)) -> 604 | M7: =MAX(0,ROUND(SUMIFS(m7_cv!$E:$E,m7_cv!$A:$A,$E7,m7_cv!$B:$B,$A7),0)) -> 1410 | N7: =ROUND(_xlfn.XLOOKUP($D7,Charts!$W$86:$W$116,Charts!$X$86:$X$116)*$L7+_xlfn.XLOOKUP($D7,Charts!$W$86:$W$116,Charts!$Y$86:$Y$116)*$M7,0) -> 1007 | O7: =MAX(0,ROUND(SUMIFS(m8_cv!$E:$E,m8_cv!$A:$A,$E7,m8_cv!$B:$B,$A7),0)) -> 1568
A8: =A7+1 -> 45664 | B8: =YEAR(A8) -> 2025 | C8: =MONTH($A8) -> 1 | D8: =DAY($A8) -> 7 | E8: =DATE($B8,$C8,1)-1 -> 45657 | F8: =_xlfn.XLOOKUP($A8,m1_cv!$B:$B,m1_cv!$C:$C) -> 712 | G8: =MAX(0,ROUND(SUMIFS(m1_cv!$E:$E,m1_cv!$A:$A,$E8,m1_cv!$B:$B,$A8),0)) -> 3284 | H8: =MAX(0,ROUND(SUMIFS(m2_cv!$E:$E,m2_cv!$A:$A,$E8,m2_cv!$B:$B,$A8),0)) -> 2043 | I8: =MAX(0,ROUND(SUMIFS(m3_cv!$E:$E,m3_cv!$A:$A,$E8,m3_cv!$B:$B,$A8),0)) -> 2024 | J8: =MAX(0,ROUND(SUMIFS(m4_cv!$E:$E,m4_cv!$A:$A,$E8,m4_cv!$B:$B,$A8),0)) -> 2016 | K8: =MAX(0,ROUND(SUMIFS(m5_cv!$E:$E,m5_cv!$A:$A,$E8,m5_cv!$B:$B,$A8),0)) -> 1550 | L8: =MAX(0,ROUND(SUMIFS(m6_cv!$E:$E,m6_cv!$A:$A,$E8,m6_cv!$B:$B,$A8),0)) -> 717 | M8: =MAX(0,ROUND(SUMIFS(m7_cv!$E:$E,m7_cv!$A:$A,$E8,m7_cv!$B:$B,$A8),0)) -> 1644 | N8: =ROUND(_xlfn.XLOOKUP($D8,Charts!$W$86:$W$116,Charts!$X$86:$X$116)*$L8+_xlfn.XLOOKUP($D8,Charts!$W$86:$W$116,Charts!$Y$86:$Y$116)*$M8,0) -> 1181 | O8: =MAX(0,ROUND(SUMIFS(m8_cv!$E:$E,m8_cv!$A:$A,$E8,m8_cv!$B:$B,$A8),0)) -> 1611
A9: =A8+1 -> 45665 | B9: =YEAR(A9) -> 2025 | C9: =MONTH($A9) -> 1 | D9: =DAY($A9) -> 8 | E9: =DATE($B9,$C9,1)-1 -> 45657 | F9: =_xlfn.XLOOKUP($A9,m1_cv!$B:$B,m1_cv!$C:$C) -> 904 | G9: =MAX(0,ROUND(SUMIFS(m1_cv!$E:$E,m1_cv!$A:$A,$E9,m1_cv!$B:$B,$A9),0)) -> 3230 | H9: =MAX(0,ROUND(SUMIFS(m2_cv!$E:$E,m2_cv!$A:$A,$E9,m2_cv!$B:$B,$A9),0)) -> 1850 | I9: =MAX(0,ROUND(SUMIFS(m3_cv!$E:$E,m3_cv!$A:$A,$E9,m3_cv!$B:$B,$A9),0)) -> 1871 | J9: =MAX(0,ROUND(SUMIFS(m4_cv!$E:$E,m4_cv!$A:$A,$E9,m4_cv!$B:$B,$A9),0)) -> 1860 | K9: =MAX(0,ROUND(SUMIFS(m5_cv!$E:$E,m5_cv!$A:$A,$E9,m5_cv!$B:$B,$A9),0)) -> 2144 | L9: =MAX(0,ROUND(SUMIFS(m6_cv!$E:$E,m6_cv!$A:$A,$E9,m6_cv!$B:$B,$A9),0)) -> 1304 | M9: =MAX(0,ROUND(SUMIFS(m7_cv!$E:$E,m7_cv!$A:$A,$E9,m7_cv!$B:$B,$A9),0)) -> 2144 | N9: =ROUND(_xlfn.XLOOKUP($D9,Charts!$W$86:$W$116,Charts!$X$86:$X$116)*$L9+_xlfn.XLOOKUP($D9,Charts!$W$86:$W$116,Charts!$Y$86:$Y$116)*$M9,0) -> 1724 | O9: =MAX(0,ROUND(SUMIFS(m8_cv!$E:$E,m8_cv!$A:$A,$E9,m8_cv!$B:$B,$A9),0)) -> 2435
A10: =A9+1 -> 45666 | B10: =YEAR(A10) -> 2025 | C10: =MONTH($A10) -> 1 | D10: =DAY($A10) -> 9 | E10: =DATE($B10,$C10,1)-1 -> 45657 | F10: =_xlfn.XLOOKUP($A10,m1_cv!$B:$B,m1_cv!$C:$C) -> 1135 | G10: =MAX(0,ROUND(SUMIFS(m1_cv!$E:$E,m1_cv!$A:$A,$E10,m1_cv!$B:$B,$A10),0)) -> 3181 | H10: =MAX(0,ROUND(SUMIFS(m2_cv!$E:$E,m2_cv!$A:$A,$E10,m2_cv!$B:$B,$A10),0)) -> 1773 | I10: =MAX(0,ROUND(SUMIFS(m3_cv!$E:$E,m3_cv!$A:$A,$E10,m3_cv!$B:$B,$A10),0)) -> 1784 | J10: =MAX(0,ROUND(SUMIFS(m4_cv!$E:$E,m4_cv!$A:$A,$E10,m4_cv!$B:$B,$A10),0)) -> 1773 | K10: =MAX(0,ROUND(SUMIFS(m5_cv!$E:$E,m5_cv!$A:$A,$E10,m5_cv!$B:$B,$A10),0)) -> 2039 | L10: =MAX(0,ROUND(SUMIFS(m6_cv!$E:$E,m6_cv!$A:$A,$E10,m6_cv!$B:$B,$A10),0)) -> 1292 | M10: =MAX(0,ROUND(SUMIFS(m7_cv!$E:$E,m7_cv!$A:$A,$E10,m7_cv!$B:$B,$A10),0)) -> 1968 | N10: =ROUND(_xlfn.XLOOKUP($D10,Charts!$W$86:$W$116,Charts!$X$86:$X$116)*$L10+_xlfn.XLOOKUP($D10,Charts!$W$86:$W$116,Charts!$Y$86:$Y$116)*$M10,0) -> 1630 | O10: =MAX(0,ROUND(SUMIFS(m8_cv!$E:$E,m8_cv!$A:$A,$E10,m8_cv!$B:$B,$A10),0)) -> 2129
A11: =A10+1 -> 45667 | B11: =YEAR(A11) -> 2025 | C11: =MONTH($A11) -> 1 | D11: =DAY($A11) -> 10 | E11: =DATE($B11,$C11,1)-1 -> 45657 | F11: =_xlfn.XLOOKUP($A11,m1_cv!$B:$B,m1_cv!$C:$C) -> 1270 | G11: =MAX(0,ROUND(SUMIFS(m1_cv!$E:$E,m1_cv!$A:$A,$E11,m1_cv!$B:$B,$A11),0)) -> 3030 | H11: =MAX(0,ROUND(SUMIFS(m2_cv!$E:$E,m2_cv!$A:$A,$E11,m2_cv!$B:$B,$A11),0)) -> 1814 | I11: =MAX(0,ROUND(SUMIFS(m3_cv!$E:$E,m3_cv!$A:$A,$E11,m3_cv!$B:$B,$A11),0)) -> 1785 | J11: =MAX(0,ROUND(SUMIFS(m4_cv!$E:$E,m4_cv!$A:$A,$E11,m4_cv!$B:$B,$A11),0)) -> 1775 | K11: =MAX(0,ROUND(SUMIFS(m5_cv!$E:$E,m5_cv!$A:$A,$E11,m5_cv!$B:$B,$A11),0)) -> 1918 | L11: =MAX(0,ROUND(SUMIFS(m6_cv!$E:$E,m6_cv!$A:$A,$E11,m6_cv!$B:$B,$A11),0)) -> 1182 | M11: =MAX(0,ROUND(SUMIFS(m7_cv!$E:$E,m7_cv!$A:$A,$E11,m7_cv!$B:$B,$A11),0)) -> 1907 | N11: =ROUND(_xlfn.XLOOKUP($D11,Charts!$W$86:$W$116,Charts!$X$86:$X$116)*$L11+_xlfn.XLOOKUP($D11,Charts!$W$86:$W$116,Charts!$Y$86:$Y$116)*$M11,0) -> 1545 | O11: =MAX(0,ROUND(SUMIFS(m8_cv!$E:$E,m8_cv!$A:$A,$E11,m8_cv!$B:$B,$A11),0)) -> 2049
A12: =A11+1 -> 45668 | B12: =YEAR(A12) -> 2025 | C12: =MONTH($A12) -> 1 | D12: =DAY($A12) -> 11 | E12: =DATE($B12,$C12,1)-1 -> 45657 | F12: =_xlfn.XLOOKUP($A12,m1_cv!$B:$B,m1_cv!$C:$C) -> 203 | G12: =MAX(0,ROUND(SUMIFS(m1_cv!$E:$E,m1_cv!$A:$A,$E12,m1_cv!$B:$B,$A12),0)) -> 834 | H12: =MAX(0,ROUND(SUMIFS(m2_cv!$E:$E,m2_cv!$A:$A,$E12,m2_cv!$B:$B,$A12),0)) -> 0 | I12: =MAX(0,ROUND(SUMIFS(m3_cv!$E:$E,m3_cv!$A:$A,$E12,m3_cv!$B:$B,$A12),0)) -> 0 | J12: =MAX(0,ROUND(SUMIFS(m4_cv!$E:$E,m4_cv!$A:$A,$E12,m4_cv!$B:$B,$A12),0)) -> 0 | K12: =MAX(0,ROUND(SUMIFS(m5_cv!$E:$E,m5_cv!$A:$A,$E12,m5_cv!$B:$B,$A12),0)) -> 0 | L12: =MAX(0,ROUND(SUMIFS(m6_cv!$E:$E,m6_cv!$A:$A,$E12,m6_cv!$B:$B,$A12),0)) -> 224 | M12: =MAX(0,ROUND(SUMIFS(m7_cv!$E:$E,m7_cv!$A:$A,$E12,m7_cv!$B:$B,$A12),0)) -> 0 | N12: =ROUND(_xlfn.XLOOKUP($D12,Charts!$W$86:$W$116,Charts!$X$86:$X$116)*$L12+_xlfn.XLOOKUP($D12,Charts!$W$86:$W$116,Charts!$Y$86:$Y$116)*$M12,0) -> 67 | O12: =MAX(0,ROUND(SUMIFS(m8_cv!$E:$E,m8_cv!$A:$A,$E12,m8_cv!$B:$B,$A12),0)) -> 0
A13: =A12+1 -> 45669 | B13: =YEAR(A13) -> 2025 | C13: =MONTH($A13) -> 1 | D13: =DAY($A13) -> 12 | E13: =DATE($B13,$C13,1)-1 -> 45657 | F13: =_xlfn.XLOOKUP($A13,m1_cv!$B:$B,m1_cv!$C:$C) -> 41 | G13: =MAX(0,ROUND(SUMIFS(m1_cv!$E:$E,m1_cv!$A:$A,$E13,m1_cv!$B:$B,$A13),0)) -> 257 | H13: =MAX(0,ROUND(SUMIFS(m2_cv!$E:$E,m2_cv!$A:$A,$E13,m2_cv!$B:$B,$A13),0)) -> 0 | I13: =MAX(0,ROUND(SUMIFS(m3_cv!$E:$E,m3_cv!$A:$A,$E13,m3_cv!$B:$B,$A13),0)) -> 0 | J13: =MAX(0,ROUND(SUMIFS(m4_cv!$E:$E,m4_cv!$A:$A,$E13,m4_cv!$B:$B,$A13),0)) -> 0 | K13: =MAX(0,ROUND(SUMIFS(m5_cv!$E:$E,m5_cv!$A:$A,$E13,m5_cv!$B:$B,$A13),0)) -> 0 | L13: =MAX(0,ROUND(SUMIFS(m6_cv!$E:$E,m6_cv!$A:$A,$E13,m6_cv!$B:$B,$A13),0)) -> 106 | M13: =MAX(0,ROUND(SUMIFS(m7_cv!$E:$E,m7_cv!$A:$A,$E13,m7_cv!$B:$B,$A13),0)) -> 0 | N13: =ROUND(_xlfn.XLOOKUP($D13,Charts!$W$86:$W$116,Charts!$X$86:$X$116)*$L13+_xlfn.XLOOKUP($D13,Charts!$W$86:$W$116,Charts!$Y$86:$Y$116)*$M13,0) -> 32 | O13: =MAX(0,ROUND(SUMIFS(m8_cv!$E:$E,m8_cv!$A:$A,$E13,m8_cv!$B:$B,$A13),0)) -> 0
A14: =A13+1 -> 45670 | B14: =YEAR(A14) -> 2025 | C14: =MONTH($A14) -> 1 | D14: =DAY($A14) -> 13 | E14: =DATE($B14,$C14,1)-1 -> 45657 | F14: =_xlfn.XLOOKUP($A14,m1_cv!$B:$B,m1_cv!$C:$C) -> 1313 | G14: =MAX(0,ROUND(SUMIFS(m1_cv!$E:$E,m1_cv!$A:$A,$E14,m1_cv!$B:$B,$A14),0)) -> 2515 | H14: =MAX(0,ROUND(SUMIFS(m2_cv!$E:$E,m2_cv!$A:$A,$E14,m2_cv!$B:$B,$A14),0)) -> 1705 | I14: =MAX(0,ROUND(SUMIFS(m3_cv!$E:$E,m3_cv!$A:$A,$E14,m3_cv!$B:$B,$A14),0)) -> 1860 | J14: =MAX(0,ROUND(SUMIFS(m4_cv!$E:$E,m4_cv!$A:$A,$E14,m4_cv!$B:$B,$A14),0)) -> 1848 | K14: =MAX(0,ROUND(SUMIFS(m5_cv!$E:$E,m5_cv!$A:$A,$E14,m5_cv!$B:$B,$A14),0)) -> 1804 | L14: =MAX(0,ROUND(SUMIFS(m6_cv!$E:$E,m6_cv!$A:$A,$E14,m6_cv!$B:$B,$A14),0)) -> 1386 | M14: =MAX(0,ROUND(SUMIFS(m7_cv!$E:$E,m7_cv!$A:$A,$E14,m7_cv!$B:$B,$A14),0)) -> 1794 | N14: =ROUND(_xlfn.XLOOKUP($D14,Charts!$W$86:$W$116,Charts!$X$86:$X$116)*$L14+_xlfn.XLOOKUP($D14,Charts!$W$86:$W$116,Charts!$Y$86:$Y$116)*$M14,0) -> 1672 | O14: =MAX(0,ROUND(SUMIFS(m8_cv!$E:$E,m8_cv!$A:$A,$E14,m8_cv!$B:$B,$A14),0)) -> 1919
... A424: =A423+1 -> 46080 | B424: =YEAR(A424) -> 2026 | C424: =MONTH($A424) -> 2 | D424: =DAY($A424) -> 27 | E424: =DATE($B424,$C424,1)-1 -> 46053 | F424: =_xlfn.XLOOKUP($A424,m1_cv!$B:$B,m1_cv!$C:$C) -> 8803 | G424: =MAX(0,ROUND(SUMIFS(m1_cv!$E:$E,m1_cv!$A:$A,$E424,m1_cv!$B:$B,$A424),0)) -> 3417 | H424: =MAX(0,ROUND(SUMIFS(m2_cv!$E:$E,m2_cv!$A:$A,$E424,m2_cv!$B:$B,$A424),0)) -> 5151 | I424: =MAX(0,ROUND(SUMIFS(m3_cv!$E:$E,m3_cv!$A:$A,$E424,m3_cv!$B:$B,$A424),0)) -> 4922 | J424: =MAX(0,ROUND(SUMIFS(m4_cv!$E:$E,m4_cv!$A:$A,$E424,m4_cv!$B:$B,$A424),0)) -> 4918 | K424: =MAX(0,ROUND(SUMIFS(m5_cv!$E:$E,m5_cv!$A:$A,$E424,m5_cv!$B:$B,$A424),0)) -> 7703 | L424: =MAX(0,ROUND(SUMIFS(m6_cv!$E:$E,m6_cv!$A:$A,$E424,m6_cv!$B:$B,$A424),0)) -> 12736 | M424: =MAX(0,ROUND(SUMIFS(m7_cv!$E:$E,m7_cv!$A:$A,$E424,m7_cv!$B:$B,$A424),0)) -> 7424 | N424: =ROUND(_xlfn.XLOOKUP($D424,Charts!$W$86:$W$116,Charts!$X$86:$X$116)*$L424+_xlfn.XLOOKUP($D424,Charts!$W$86:$W$116,Charts!$Y$86:$Y$116)*$M424,0) -> 12736 | O424: =MAX(0,ROUND(SUMIFS(m8_cv!$E:$E,m8_cv!$A:$A,$E424,m8_cv!$B:$B,$A424),0)) -> 7179
A425: =A424+1 -> 46081 | B425: =YEAR(A425) -> 2026 | C425: =MONTH($A425) -> 2 | D425: =DAY($A425) -> 28 | E425: =DATE($B425,$C425,1)-1 -> 46053 | F425: =_xlfn.XLOOKUP($A425,m1_cv!$B:$B,m1_cv!$C:$C) -> 9425 | G425: =MAX(0,ROUND(SUMIFS(m1_cv!$E:$E,m1_cv!$A:$A,$E425,m1_cv!$B:$B,$A425),0)) -> 1174 | H425: =MAX(0,ROUND(SUMIFS(m2_cv!$E:$E,m2_cv!$A:$A,$E425,m2_cv!$B:$B,$A425),0)) -> 4125 | I425: =MAX(0,ROUND(SUMIFS(m3_cv!$E:$E,m3_cv!$A:$A,$E425,m3_cv!$B:$B,$A425),0)) -> 3861 | J425: =MAX(0,ROUND(SUMIFS(m4_cv!$E:$E,m4_cv!$A:$A,$E425,m4_cv!$B:$B,$A425),0)) -> 3858 | K425: =MAX(0,ROUND(SUMIFS(m5_cv!$E:$E,m5_cv!$A:$A,$E425,m5_cv!$B:$B,$A425),0)) -> 8030 | L425: =MAX(0,ROUND(SUMIFS(m6_cv!$E:$E,m6_cv!$A:$A,$E425,m6_cv!$B:$B,$A425),0)) -> 3448 | M425: =MAX(0,ROUND(SUMIFS(m7_cv!$E:$E,m7_cv!$A:$A,$E425,m7_cv!$B:$B,$A425),0)) -> 8196 | N425: =ROUND(_xlfn.XLOOKUP($D425,Charts!$W$86:$W$116,Charts!$X$86:$X$116)*$L425+_xlfn.XLOOKUP($D425,Charts!$W$86:$W$116,Charts!$Y$86:$Y$116)*$M425,0) -> 3448 | O425: =MAX(0,ROUND(SUMIFS(m8_cv!$E:$E,m8_cv!$A:$A,$E425,m8_cv!$B:$B,$A425),0)) -> 7938 | Q425: M6 | R425: M7 | S425: Diff | T425: Adj | U425: Adj NoDiff | W425: Adj | X425: Adj No Diff | Y425: Actual
A426: =A425+1 -> 46082 | B426: =YEAR(A426) -> 2026 | C426: =MONTH($A426) -> 3 | D426: =DAY($A426) -> 1 | E426: =DATE($B426,$C426,1)-1 -> 46081 | F426: =_xlfn.XLOOKUP($A426,m1_cv!$B:$B,m1_cv!$C:$C) -> 40 | G426: =MAX(0,ROUND(SUMIFS(m1_cv!$E:$E,m1_cv!$A:$A,$E426,m1_cv!$B:$B,$A426),0)) -> 759 | H426: =MAX(0,ROUND(SUMIFS(m2_cv!$E:$E,m2_cv!$A:$A,$E426,m2_cv!$B:$B,$A426),0)) -> 4377 | I426: =MAX(0,ROUND(SUMIFS(m3_cv!$E:$E,m3_cv!$A:$A,$E426,m3_cv!$B:$B,$A426),0)) -> 4263 | J426: =MAX(0,ROUND(SUMIFS(m4_cv!$E:$E,m4_cv!$A:$A,$E426,m4_cv!$B:$B,$A426),0)) -> 4257 | K426: =MAX(0,ROUND(SUMIFS(m5_cv!$E:$E,m5_cv!$A:$A,$E426,m5_cv!$B:$B,$A426),0)) -> 667 | L426: =MAX(0,ROUND(SUMIFS(m6_cv!$E:$E,m6_cv!$A:$A,$E426,m6_cv!$B:$B,$A426),0)) -> 87 | M426: =MAX(0,ROUND(SUMIFS(m7_cv!$E:$E,m7_cv!$A:$A,$E426,m7_cv!$B:$B,$A426),0)) -> 1125 | N426: =ROUND(_xlfn.XLOOKUP($D426,Charts!$W$86:$W$116,Charts!$X$86:$X$116)*$L426+_xlfn.XLOOKUP($D426,Charts!$W$86:$W$116,Charts!$Y$86:$Y$116)*$M426,0) -> 87 | O426: =MAX(0,ROUND(SUMIFS(m8_cv!$E:$E,m8_cv!$A:$A,$E426,m8_cv!$B:$B,$A426),0)) -> 991 | Q426: 95 | R426: 1294 | S426: =R426-T426 -> 1199 | T426: =Q426 -> 95 | U426: =T426 -> 95 | W426: Cumulative | X426: Cumulative | Y426: Cumulative
A427: =A426+1 -> 46083 | B427: =YEAR(A427) -> 2026 | C427: =MONTH($A427) -> 3 | D427: =DAY($A427) -> 2 | E427: =DATE($B427,$C427,1)-1 -> 46081 | F427: =_xlfn.XLOOKUP($A427,m1_cv!$B:$B,m1_cv!$C:$C) -> 617 | G427: =MAX(0,ROUND(SUMIFS(m1_cv!$E:$E,m1_cv!$A:$A,$E427,m1_cv!$B:$B,$A427),0)) -> 3079 | H427: =MAX(0,ROUND(SUMIFS(m2_cv!$E:$E,m2_cv!$A:$A,$E427,m2_cv!$B:$B,$A427),0)) -> 6287 | I427: =MAX(0,ROUND(SUMIFS(m3_cv!$E:$E,m3_cv!$A:$A,$E427,m3_cv!$B:$B,$A427),0)) -> 6488 | J427: =MAX(0,ROUND(SUMIFS(m4_cv!$E:$E,m4_cv!$A:$A,$E427,m4_cv!$B:$B,$A427),0)) -> 6484 | K427: =MAX(0,ROUND(SUMIFS(m5_cv!$E:$E,m5_cv!$A:$A,$E427,m5_cv!$B:$B,$A427),0)) -> 2630 | L427: =MAX(0,ROUND(SUMIFS(m6_cv!$E:$E,m6_cv!$A:$A,$E427,m6_cv!$B:$B,$A427),0)) -> 766 | M427: =MAX(0,ROUND(SUMIFS(m7_cv!$E:$E,m7_cv!$A:$A,$E427,m7_cv!$B:$B,$A427),0)) -> 2593 | N427: =ROUND(_xlfn.XLOOKUP($D427,Charts!$W$86:$W$116,Charts!$X$86:$X$116)*$L427+_xlfn.XLOOKUP($D427,Charts!$W$86:$W$116,Charts!$Y$86:$Y$116)*$M427,0) -> 766 | O427: =MAX(0,ROUND(SUMIFS(m8_cv!$E:$E,m8_cv!$A:$A,$E427,m8_cv!$B:$B,$A427),0)) -> 2526 | Q427: 836 | R427: 2797 | S427: =R427-T427 -> 1961 | T427: =Q427 -> 836 | U427: =T427 -> 836 | W427: =SUM(T$426:T427) -> 931 | X427: =SUM(U$426:U427) -> 931 | Y427: =SUM(F$426:F427) -> 657 | Z427: =X427-Y427 -> 274
A428: =A427+1 -> 46084 | B428: =YEAR(A428) -> 2026 | C428: =MONTH($A428) -> 3 | D428: =DAY($A428) -> 3 | E428: =DATE($B428,$C428,1)-1 -> 46081 | F428: =_xlfn.XLOOKUP($A428,m1_cv!$B:$B,m1_cv!$C:$C) -> 799 | G428: =MAX(0,ROUND(SUMIFS(m1_cv!$E:$E,m1_cv!$A:$A,$E428,m1_cv!$B:$B,$A428),0)) -> 3644 | H428: =MAX(0,ROUND(SUMIFS(m2_cv!$E:$E,m2_cv!$A:$A,$E428,m2_cv!$B:$B,$A428),0)) -> 5336 | I428: =MAX(0,ROUND(SUMIFS(m3_cv!$E:$E,m3_cv!$A:$A,$E428,m3_cv!$B:$B,$A428),0)) -> 5408 | J428: =MAX(0,ROUND(SUMIFS(m4_cv!$E:$E,m4_cv!$A:$A,$E428,m4_cv!$B:$B,$A428),0)) -> 5402 | K428: =MAX(0,ROUND(SUMIFS(m5_cv!$E:$E,m5_cv!$A:$A,$E428,m5_cv!$B:$B,$A428),0)) -> 2375 | L428: =MAX(0,ROUND(SUMIFS(m6_cv!$E:$E,m6_cv!$A:$A,$E428,m6_cv!$B:$B,$A428),0)) -> 1371 | M428: =MAX(0,ROUND(SUMIFS(m7_cv!$E:$E,m7_cv!$A:$A,$E428,m7_cv!$B:$B,$A428),0)) -> 1964 | N428: =ROUND(_xlfn.XLOOKUP($D428,Charts!$W$86:$W$116,Charts!$X$86:$X$116)*$L428+_xlfn.XLOOKUP($D428,Charts!$W$86:$W$116,Charts!$Y$86:$Y$116)*$M428,0) -> 1371 | O428: =MAX(0,ROUND(SUMIFS(m8_cv!$E:$E,m8_cv!$A:$A,$E428,m8_cv!$B:$B,$A428),0)) -> 2108 | Q428: 1413 | R428: 2199 | S428: =R428-T428 -> 786 | T428: =Q428 -> 1413 | U428: =T428 -> 1413 | W428: =SUM(T$426:T428) -> 2344 | X428: =SUM(U$426:U428) -> 2344 | Y428: =SUM(F$426:F428) -> 1456 | Z428: =X428-Y428 -> 888
A429: =A428+1 -> 46085 | B429: =YEAR(A429) -> 2026 | C429: =MONTH($A429) -> 3 | D429: =DAY($A429) -> 4 | E429: =DATE($B429,$C429,1)-1 -> 46081 | F429: =_xlfn.XLOOKUP($A429,m1_cv!$B:$B,m1_cv!$C:$C) -> 995 | G429: =MAX(0,ROUND(SUMIFS(m1_cv!$E:$E,m1_cv!$A:$A,$E429,m1_cv!$B:$B,$A429),0)) -> 3744 | H429: =MAX(0,ROUND(SUMIFS(m2_cv!$E:$E,m2_cv!$A:$A,$E429,m2_cv!$B:$B,$A429),0)) -> 3537 | I429: =MAX(0,ROUND(SUMIFS(m3_cv!$E:$E,m3_cv!$A:$A,$E429,m3_cv!$B:$B,$A429),0)) -> 3631 | J429: =MAX(0,ROUND(SUMIFS(m4_cv!$E:$E,m4_cv!$A:$A,$E429,m4_cv!$B:$B,$A429),0)) -> 3626 | K429: =MAX(0,ROUND(SUMIFS(m5_cv!$E:$E,m5_cv!$A:$A,$E429,m5_cv!$B:$B,$A429),0)) -> 1903 | L429: =MAX(0,ROUND(SUMIFS(m6_cv!$E:$E,m6_cv!$A:$A,$E429,m6_cv!$B:$B,$A429),0)) -> 1193 | M429: =MAX(0,ROUND(SUMIFS(m7_cv!$E:$E,m7_cv!$A:$A,$E429,m7_cv!$B:$B,$A429),0)) -> 1742 | N429: =ROUND(_xlfn.XLOOKUP($D429,Charts!$W$86:$W$116,Charts!$X$86:$X$116)*$L429+_xlfn.XLOOKUP($D429,Charts!$W$86:$W$116,Charts!$Y$86:$Y$116)*$M429,0) -> 1193 | O429: =MAX(0,ROUND(SUMIFS(m8_cv!$E:$E,m8_cv!$A:$A,$E429,m8_cv!$B:$B,$A429),0)) -> 1853 | Q429: 1185 | R429: 1882 | S429: =R429-T429 -> 697 | T429: =Q429 -> 1185 | U429: =T429 -> 1185 | W429: =SUM(T$426:T429) -> 3529 | X429: =SUM(U$426:U429) -> 3529 | Y429: =SUM(F$426:F429) -> 2451 | Z429: =X429-Y429 -> 1078
A430: =A429+1 -> 46086 | B430: =YEAR(A430) -> 2026 | C430: =MONTH($A430) -> 3 | D430: =DAY($A430) -> 5 | E430: =DATE($B430,$C430,1)-1 -> 46081 | F430: =_xlfn.XLOOKUP($A430,m1_cv!$B:$B,m1_cv!$C:$C) -> 1314 | G430: =MAX(0,ROUND(SUMIFS(m1_cv!$E:$E,m1_cv!$A:$A,$E430,m1_cv!$B:$B,$A430),0)) -> 3779 | H430: =MAX(0,ROUND(SUMIFS(m2_cv!$E:$E,m2_cv!$A:$A,$E430,m2_cv!$B:$B,$A430),0)) -> 2118 | I430: =MAX(0,ROUND(SUMIFS(m3_cv!$E:$E,m3_cv!$A:$A,$E430,m3_cv!$B:$B,$A430),0)) -> 2162 | J430: =MAX(0,ROUND(SUMIFS(m4_cv!$E:$E,m4_cv!$A:$A,$E430,m4_cv!$B:$B,$A430),0)) -> 2157 | K430: =MAX(0,ROUND(SUMIFS(m5_cv!$E:$E,m5_cv!$A:$A,$E430,m5_cv!$B:$B,$A430),0)) -> 1693 | L430: =MAX(0,ROUND(SUMIFS(m6_cv!$E:$E,m6_cv!$A:$A,$E430,m6_cv!$B:$B,$A430),0)) -> 1088 | M430: =MAX(0,ROUND(SUMIFS(m7_cv!$E:$E,m7_cv!$A:$A,$E430,m7_cv!$B:$B,$A430),0)) -> 1841 | N430: =ROUND(_xlfn.XLOOKUP($D430,Charts!$W$86:$W$116,Charts!$X$86:$X$116)*$L430+_xlfn.XLOOKUP($D430,Charts!$W$86:$W$116,Charts!$Y$86:$Y$116)*$M430,0) -> 1239 | O430: =MAX(0,ROUND(SUMIFS(m8_cv!$E:$E,m8_cv!$A:$A,$E430,m8_cv!$B:$B,$A430),0)) -> 1916 | Q430: 1081 | R430: 1919 | S430: =R430-T430 -> 838 | T430: =Q430 -> 1081 | U430: =T430 -> 1081 | W430: =SUM(T$426:T430) -> 4610 | X430: =SUM(U$426:U430) -> 4610 | Y430: =SUM(F$426:F430) -> 3765 | Z430: =X430-Y430 -> 845
A431: =A430+1 -> 46087 | B431: =YEAR(A431) -> 2026 | C431: =MONTH($A431) -> 3 | D431: =DAY($A431) -> 6 | E431: =DATE($B431,$C431,1)-1 -> 46081 | F431: =_xlfn.XLOOKUP($A431,m1_cv!$B:$B,m1_cv!$C:$C) -> 1617 | G431: =MAX(0,ROUND(SUMIFS(m1_cv!$E:$E,m1_cv!$A:$A,$E431,m1_cv!$B:$B,$A431),0)) -> 3863 | H431: =MAX(0,ROUND(SUMIFS(m2_cv!$E:$E,m2_cv!$A:$A,$E431,m2_cv!$B:$B,$A431),0)) -> 1652 | I431: =MAX(0,ROUND(SUMIFS(m3_cv!$E:$E,m3_cv!$A:$A,$E431,m3_cv!$B:$B,$A431),0)) -> 1588 | J431: =MAX(0,ROUND(SUMIFS(m4_cv!$E:$E,m4_cv!$A:$A,$E431,m4_cv!$B:$B,$A431),0)) -> 1582 | K431: =MAX(0,ROUND(SUMIFS(m5_cv!$E:$E,m5_cv!$A:$A,$E431,m5_cv!$B:$B,$A431),0)) -> 1795 | L431: =MAX(0,ROUND(SUMIFS(m6_cv!$E:$E,m6_cv!$A:$A,$E431,m6_cv!$B:$B,$A431),0)) -> 977 | M431: =MAX(0,ROUND(SUMIFS(m7_cv!$E:$E,m7_cv!$A:$A,$E431,m7_cv!$B:$B,$A431),0)) -> 1873 | N431: =ROUND(_xlfn.XLOOKUP($D431,Charts!$W$86:$W$116,Charts!$X$86:$X$116)*$L431+_xlfn.XLOOKUP($D431,Charts!$W$86:$W$116,Charts!$Y$86:$Y$116)*$M431,0) -> 1425 | O431: =MAX(0,ROUND(SUMIFS(m8_cv!$E:$E,m8_cv!$A:$A,$E431,m8_cv!$B:$B,$A431),0)) -> 1895 | Q431: 989 | R431: 1890 | S431: =R431-T431 -> 901 | T431: =Q431 -> 989 | U431: =T431 -> 989 | W431: =SUM(T$426:T431) -> 5599 | X431: =SUM(U$426:U431) -> 5599 | Y431: =SUM(F$426:F431) -> 5382 | Z431: =X431-Y431 -> 217
A432: =A431+1 -> 46088 | B432: =YEAR(A432) -> 2026 | C432: =MONTH($A432) -> 3 | D432: =DAY($A432) -> 7 | E432: =DATE($B432,$C432,1)-1 -> 46081 | F432: =_xlfn.XLOOKUP($A432,m1_cv!$B:$B,m1_cv!$C:$C) -> 220 | G432: =MAX(0,ROUND(SUMIFS(m1_cv!$E:$E,m1_cv!$A:$A,$E432,m1_cv!$B:$B,$A432),0)) -> 1634 | H432: =MAX(0,ROUND(SUMIFS(m2_cv!$E:$E,m2_cv!$A:$A,$E432,m2_cv!$B:$B,$A432),0)) -> 0 | I432: =MAX(0,ROUND(SUMIFS(m3_cv!$E:$E,m3_cv!$A:$A,$E432,m3_cv!$B:$B,$A432),0)) -> 0 | J432: =MAX(0,ROUND(SUMIFS(m4_cv!$E:$E,m4_cv!$A:$A,$E432,m4_cv!$B:$B,$A432),0)) -> 0 | K432: =MAX(0,ROUND(SUMIFS(m5_cv!$E:$E,m5_cv!$A:$A,$E432,m5_cv!$B:$B,$A432),0)) -> 0 | L432: =MAX(0,ROUND(SUMIFS(m6_cv!$E:$E,m6_cv!$A:$A,$E432,m6_cv!$B:$B,$A432),0)) -> 19 | M432: =MAX(0,ROUND(SUMIFS(m7_cv!$E:$E,m7_cv!$A:$A,$E432,m7_cv!$B:$B,$A432),0)) -> 0 | N432: =ROUND(_xlfn.XLOOKUP($D432,Charts!$W$86:$W$116,Charts!$X$86:$X$116)*$L432+_xlfn.XLOOKUP($D432,Charts!$W$86:$W$116,Charts!$Y$86:$Y$116)*$M432,0) -> 10 | O432: =MAX(0,ROUND(SUMIFS(m8_cv!$E:$E,m8_cv!$A:$A,$E432,m8_cv!$B:$B,$A432),0)) -> 0 | Q432: 19 | R432: 0 | S432: =R432-T432 -> -19 | T432: =Q432 -> 19 | U432: =T432 -> 19 | W432: =SUM(T$426:T432) -> 5618 | X432: =SUM(U$426:U432) -> 5618 | Y432: =SUM(F$426:F432) -> 5602 | Z432: =X432-Y432 -> 16
A433: =A432+1 -> 46089 | B433: =YEAR(A433) -> 2026 | C433: =MONTH($A433) -> 3 | D433: =DAY($A433) -> 8 | E433: =DATE($B433,$C433,1)-1 -> 46081 | F433: =_xlfn.XLOOKUP($A433,m1_cv!$B:$B,m1_cv!$C:$C) -> 43 | G433: =MAX(0,ROUND(SUMIFS(m1_cv!$E:$E,m1_cv!$A:$A,$E433,m1_cv!$B:$B,$A433),0)) -> 1001 | H433: =MAX(0,ROUND(SUMIFS(m2_cv!$E:$E,m2_cv!$A:$A,$E433,m2_cv!$B:$B,$A433),0)) -> 0 | I433: =MAX(0,ROUND(SUMIFS(m3_cv!$E:$E,m3_cv!$A:$A,$E433,m3_cv!$B:$B,$A433),0)) -> 0 | J433: =MAX(0,ROUND(SUMIFS(m4_cv!$E:$E,m4_cv!$A:$A,$E433,m4_cv!$B:$B,$A433),0)) -> 0 | K433: =MAX(0,ROUND(SUMIFS(m5_cv!$E:$E,m5_cv!$A:$A,$E433,m5_cv!$B:$B,$A433),0)) -> 0 | L433: =MAX(0,ROUND(SUMIFS(m6_cv!$E:$E,m6_cv!$A:$A,$E433,m6_cv!$B:$B,$A433),0)) -> 127 | M433: =MAX(0,ROUND(SUMIFS(m7_cv!$E:$E,m7_cv!$A:$A,$E433,m7_cv!$B:$B,$A433),0)) -> 0 | N433: =ROUND(_xlfn.XLOOKUP($D433,Charts!$W$86:$W$116,Charts!$X$86:$X$116)*$L433+_xlfn.XLOOKUP($D433,Charts!$W$86:$W$116,Charts!$Y$86:$Y$116)*$M433,0) -> 64 | O433: =MAX(0,ROUND(SUMIFS(m8_cv!$E:$E,m8_cv!$A:$A,$E433,m8_cv!$B:$B,$A433),0)) -> 401 | Q433: 128 | R433: 0 | S433: =R433-T433 -> -128 | T433: =Q433 -> 128 | U433: =T433 -> 128 | W433: =SUM(T$426:T433) -> 5746 | X433: =SUM(U$426:U433) -> 5746 | Y433: =SUM(F$426:F433) -> 5645 | Z433: =X433-Y433 -> 101
A434: =A433+1 -> 46090 | B434: =YEAR(A434) -> 2026 | C434: =MONTH($A434) -> 3 | D434: =DAY($A434) -> 9 | E434: =DATE($B434,$C434,1)-1 -> 46081 | F434: =_xlfn.XLOOKUP($A434,m1_cv!$B:$B,m1_cv!$C:$C) -> 1766 | G434: =MAX(0,ROUND(SUMIFS(m1_cv!$E:$E,m1_cv!$A:$A,$E434,m1_cv!$B:$B,$A434),0)) -> 3287 | H434: =MAX(0,ROUND(SUMIFS(m2_cv!$E:$E,m2_cv!$A:$A,$E434,m2_cv!$B:$B,$A434),0)) -> 1986 | I434: =MAX(0,ROUND(SUMIFS(m3_cv!$E:$E,m3_cv!$A:$A,$E434,m3_cv!$B:$B,$A434),0)) -> 2119 | J434: =MAX(0,ROUND(SUMIFS(m4_cv!$E:$E,m4_cv!$A:$A,$E434,m4_cv!$B:$B,$A434),0)) -> 2114 | K434: =MAX(0,ROUND(SUMIFS(m5_cv!$E:$E,m5_cv!$A:$A,$E434,m5_cv!$B:$B,$A434),0)) -> 2320 | L434: =MAX(0,ROUND(SUMIFS(m6_cv!$E:$E,m6_cv!$A:$A,$E434,m6_cv!$B:$B,$A434),0)) -> 1711 | M434: =MAX(0,ROUND(SUMIFS(m7_cv!$E:$E,m7_cv!$A:$A,$E434,m7_cv!$B:$B,$A434),0)) -> 2289 | N434: =ROUND(_xlfn.XLOOKUP($D434,Charts!$W$86:$W$116,Charts!$X$86:$X$116)*$L434+_xlfn.XLOOKUP($D434,Charts!$W$86:$W$116,Charts!$Y$86:$Y$116)*$M434,0) -> 2000 | O434: =MAX(0,ROUND(SUMIFS(m8_cv!$E:$E,m8_cv!$A:$A,$E434,m8_cv!$B:$B,$A434),0)) -> 2869 | Q434: 1698 | R434: 2398 | S434: =R434-T434 -> 700 | T434: =Q434 -> 1698 | U434: =T434 -> 1698 | W434: =SUM(T$426:T434) -> 7444 | X434: =SUM(U$426:U434) -> 7444 | Y434: =SUM(F$426:F434) -> 7411 | Z434: =X434-Y434 -> 33
A435: =A434+1 -> 46091 | B435: =YEAR(A435) -> 2026 | C435: =MONTH($A435) -> 3 | D435: =DAY($A435) -> 10 | E435: =DATE($B435,$C435,1)-1 -> 46081 | F435: =_xlfn.XLOOKUP($A435,m1_cv!$B:$B,m1_cv!$C:$C) -> 2170 | G435: =MAX(0,ROUND(SUMIFS(m1_cv!$E:$E,m1_cv!$A:$A,$E435,m1_cv!$B:$B,$A435),0)) -> 3814 | H435: =MAX(0,ROUND(SUMIFS(m2_cv!$E:$E,m2_cv!$A:$A,$E435,m2_cv!$B:$B,$A435),0)) -> 2463 | I435: =MAX(0,ROUND(SUMIFS(m3_cv!$E:$E,m3_cv!$A:$A,$E435,m3_cv!$B:$B,$A435),0)) -> 2370 | J435: =MAX(0,ROUND(SUMIFS(m4_cv!$E:$E,m4_cv!$A:$A,$E435,m4_cv!$B:$B,$A435),0)) -> 2364 | K435: =MAX(0,ROUND(SUMIFS(m5_cv!$E:$E,m5_cv!$A:$A,$E435,m5_cv!$B:$B,$A435),0)) -> 2504 | L435: =MAX(0,ROUND(SUMIFS(m6_cv!$E:$E,m6_cv!$A:$A,$E435,m6_cv!$B:$B,$A435),0)) -> 2130 | M435: =MAX(0,ROUND(SUMIFS(m7_cv!$E:$E,m7_cv!$A:$A,$E435,m7_cv!$B:$B,$A435),0)) -> 2570 | N435: =ROUND(_xlfn.XLOOKUP($D435,Charts!$W$86:$W$116,Charts!$X$86:$X$116)*$L435+_xlfn.XLOOKUP($D435,Charts!$W$86:$W$116,Charts!$Y$86:$Y$116)*$M435,0) -> 2350 | O435: =MAX(0,ROUND(SUMIFS(m8_cv!$E:$E,m8_cv!$A:$A,$E435,m8_cv!$B:$B,$A435),0)) -> 2928 | Q435: 2107 | R435: 2633 | S435: =R435-T435 -> 526 | T435: =Q435 -> 2107 | U435: =T435 -> 2107 | W435: =SUM(T$426:T435) -> 9551 | X435: =SUM(U$426:U435) -> 9551 | Y435: =SUM(F$426:F435) -> 9581 | Z435: =X435-Y435 -> -30
A436: =A435+1 -> 46092 | B436: =YEAR(A436) -> 2026 | C436: =MONTH($A436) -> 3 | D436: =DAY($A436) -> 11 | E436: =DATE($B436,$C436,1)-1 -> 46081 | F436: =_xlfn.XLOOKUP($A436,m1_cv!$B:$B,m1_cv!$C:$C) -> 2907 | G436: =MAX(0,ROUND(SUMIFS(m1_cv!$E:$E,m1_cv!$A:$A,$E436,m1_cv!$B:$B,$A436),0)) -> 3876 | H436: =MAX(0,ROUND(SUMIFS(m2_cv!$E:$E,m2_cv!$A:$A,$E436,m2_cv!$B:$B,$A436),0)) -> 2463 | I436: =MAX(0,ROUND(SUMIFS(m3_cv!$E:$E,m3_cv!$A:$A,$E436,m3_cv!$B:$B,$A436),0)) -> 2382 | J436: =MAX(0,ROUND(SUMIFS(m4_cv!$E:$E,m4_cv!$A:$A,$E436,m4_cv!$B:$B,$A436),0)) -> 2376 | K436: =MAX(0,ROUND(SUMIFS(m5_cv!$E:$E,m5_cv!$A:$A,$E436,m5_cv!$B:$B,$A436),0)) -> 2548 | L436: =MAX(0,ROUND(SUMIFS(m6_cv!$E:$E,m6_cv!$A:$A,$E436,m6_cv!$B:$B,$A436),0)) -> 2147 | M436: =MAX(0,ROUND(SUMIFS(m7_cv!$E:$E,m7_cv!$A:$A,$E436,m7_cv!$B:$B,$A436),0)) -> 2597 | N436: =ROUND(_xlfn.XLOOKUP($D436,Charts!$W$86:$W$116,Charts!$X$86:$X$116)*$L436+_xlfn.XLOOKUP($D436,Charts!$W$86:$W$116,Charts!$Y$86:$Y$116)*$M436,0) -> 2462 | O436: =MAX(0,ROUND(SUMIFS(m8_cv!$E:$E,m8_cv!$A:$A,$E436,m8_cv!$B:$B,$A436),0)) -> 2699 | Q436: 2154 | R436: 2621 | S436: =R436-T436 -> 0 | T436: =R436 -> 2621 | U436: =ROUND(T436+T436/$T$459*$S$457,0) -> 3010 | W436: =SUM(T$426:T436) -> 12172 | X436: =SUM(U$426:U436) -> 12561 | Y436: =SUM(F$426:F436) -> 12488 | Z436: =X436-Y436 -> 73
A437: =A436+1 -> 46093 | B437: =YEAR(A437) -> 2026 | C437: =MONTH($A437) -> 3 | D437: =DAY($A437) -> 12 | E437: =DATE($B437,$C437,1)-1 -> 46081 | F437: =_xlfn.XLOOKUP($A437,m1_cv!$B:$B,m1_cv!$C:$C) -> 3020 | G437: =MAX(0,ROUND(SUMIFS(m1_cv!$E:$E,m1_cv!$A:$A,$E437,m1_cv!$B:$B,$A437),0)) -> 3871 | H437: =MAX(0,ROUND(SUMIFS(m2_cv!$E:$E,m2_cv!$A:$A,$E437,m2_cv!$B:$B,$A437),0)) -> 2573 | I437: =MAX(0,ROUND(SUMIFS(m3_cv!$E:$E,m3_cv!$A:$A,$E437,m3_cv!$B:$B,$A437),0)) -> 2526 | J437: =MAX(0,ROUND(SUMIFS(m4_cv!$E:$E,m4_cv!$A:$A,$E437,m4_cv!$B:$B,$A437),0)) -> 2520 | K437: =MAX(0,ROUND(SUMIFS(m5_cv!$E:$E,m5_cv!$A:$A,$E437,m5_cv!$B:$B,$A437),0)) -> 2657 | L437: =MAX(0,ROUND(SUMIFS(m6_cv!$E:$E,m6_cv!$A:$A,$E437,m6_cv!$B:$B,$A437),0)) -> 2258 | M437: =MAX(0,ROUND(SUMIFS(m7_cv!$E:$E,m7_cv!$A:$A,$E437,m7_cv!$B:$B,$A437),0)) -> 2622 | N437: =ROUND(_xlfn.XLOOKUP($D437,Charts!$W$86:$W$116,Charts!$X$86:$X$116)*$L437+_xlfn.XLOOKUP($D437,Charts!$W$86:$W$116,Charts!$Y$86:$Y$116)*$M437,0) -> 2513 | O437: =MAX(0,ROUND(SUMIFS(m8_cv!$E:$E,m8_cv!$A:$A,$E437,m8_cv!$B:$B,$A437),0)) -> 2637 | Q437: 2296 | R437: 2623 | S437: =R437-T437 -> 0 | T437: =R437 -> 2623 | U437: =ROUND(T437+T437/$T$459*$S$457,0) -> 3012 | W437: =SUM(T$426:T437) -> 14795 | X437: =SUM(U$426:U437) -> 15573 | Y437: =SUM(F$426:F437) -> 15508 | Z437: =X437-Y437 -> 65
A438: =A437+1 -> 46094 | B438: =YEAR(A438) -> 2026 | C438: =MONTH($A438) -> 3 | D438: =DAY($A438) -> 13 | E438: =DATE($B438,$C438,1)-1 -> 46081 | F438: =_xlfn.XLOOKUP($A438,m1_cv!$B:$B,m1_cv!$C:$C) -> 3551 | G438: =MAX(0,ROUND(SUMIFS(m1_cv!$E:$E,m1_cv!$A:$A,$E438,m1_cv!$B:$B,$A438),0)) -> 3914 | H438: =MAX(0,ROUND(SUMIFS(m2_cv!$E:$E,m2_cv!$A:$A,$E438,m2_cv!$B:$B,$A438),0)) -> 2878 | I438: =MAX(0,ROUND(SUMIFS(m3_cv!$E:$E,m3_cv!$A:$A,$E438,m3_cv!$B:$B,$A438),0)) -> 2845 | J438: =MAX(0,ROUND(SUMIFS(m4_cv!$E:$E,m4_cv!$A:$A,$E438,m4_cv!$B:$B,$A438),0)) -> 2839 | K438: =MAX(0,ROUND(SUMIFS(m5_cv!$E:$E,m5_cv!$A:$A,$E438,m5_cv!$B:$B,$A438),0)) -> 2821 | L438: =MAX(0,ROUND(SUMIFS(m6_cv!$E:$E,m6_cv!$A:$A,$E438,m6_cv!$B:$B,$A438),0)) -> 2268 | M438: =MAX(0,ROUND(SUMIFS(m7_cv!$E:$E,m7_cv!$A:$A,$E438,m7_cv!$B:$B,$A438),0)) -> 2781 | N438: =ROUND(_xlfn.XLOOKUP($D438,Charts!$W$86:$W$116,Charts!$X$86:$X$116)*$L438+_xlfn.XLOOKUP($D438,Charts!$W$86:$W$116,Charts!$Y$86:$Y$116)*$M438,0) -> 2627 | O438: =MAX(0,ROUND(SUMIFS(m8_cv!$E:$E,m8_cv!$A:$A,$E438,m8_cv!$B:$B,$A438),0)) -> 2784 | Q438: 2295 | R438: 2777 | S438: =R438-T438 -> 0 | T438: =R438 -> 2777 | U438: =ROUND(T438+T438/$T$459*$S$457,0) -> 3189 | W438: =SUM(T$426:T438) -> 17572 | X438: =SUM(U$426:U438) -> 18762 | Y438: =SUM(F$426:F438) -> 19059 | Z438: =X438-Y438 -> -297
A439: =A438+1 -> 46095 | B439: =YEAR(A439) -> 2026 | C439: =MONTH($A439) -> 3 | D439: =DAY($A439) -> 14 | E439: =DATE($B439,$C439,1)-1 -> 46081 | F439: =_xlfn.XLOOKUP($A439,m1_cv!$B:$B,m1_cv!$C:$C) -> 1088 | G439: =MAX(0,ROUND(SUMIFS(m1_cv!$E:$E,m1_cv!$A:$A,$E439,m1_cv!$B:$B,$A439),0)) -> 1646 | H439: =MAX(0,ROUND(SUMIFS(m2_cv!$E:$E,m2_cv!$A:$A,$E439,m2_cv!$B:$B,$A439),0)) -> 833 | I439: =MAX(0,ROUND(SUMIFS(m3_cv!$E:$E,m3_cv!$A:$A,$E439,m3_cv!$B:$B,$A439),0)) -> 851 | J439: =MAX(0,ROUND(SUMIFS(m4_cv!$E:$E,m4_cv!$A:$A,$E439,m4_cv!$B:$B,$A439),0)) -> 844 | K439: =MAX(0,ROUND(SUMIFS(m5_cv!$E:$E,m5_cv!$A:$A,$E439,m5_cv!$B:$B,$A439),0)) -> 657 | L439: =MAX(0,ROUND(SUMIFS(m6_cv!$E:$E,m6_cv!$A:$A,$E439,m6_cv!$B:$B,$A439),0)) -> 432 | M439: =MAX(0,ROUND(SUMIFS(m7_cv!$E:$E,m7_cv!$A:$A,$E439,m7_cv!$B:$B,$A439),0)) -> 669 | N439: =ROUND(_xlfn.XLOOKUP($D439,Charts!$W$86:$W$116,Charts!$X$86:$X$116)*$L439+_xlfn.XLOOKUP($D439,Charts!$W$86:$W$116,Charts!$Y$86:$Y$116)*$M439,0) -> 669 | O439: =MAX(0,ROUND(SUMIFS(m8_cv!$E:$E,m8_cv!$A:$A,$E439,m8_cv!$B:$B,$A439),0)) -> 661 | Q439: 429 | R439: 666 | S439: =R439-T439 -> 0 | T439: =R439 -> 666 | U439: =ROUND(T439+T439/$T$459*$S$457,0) -> 765 | W439: =SUM(T$426:T439) -> 18238 | X439: =SUM(U$426:U439) -> 19527 | Y439: =SUM(F$426:F439) -> 20147 | Z439: =X439-Y439 -> -620
A440: =A439+1 -> 46096 | B440: =YEAR(A440) -> 2026 | C440: =MONTH($A440) -> 3 | D440: =DAY($A440) -> 15 | E440: =DATE($B440,$C440,1)-1 -> 46081 | F440: =_xlfn.XLOOKUP($A440,m1_cv!$B:$B,m1_cv!$C:$C) -> 228 | G440: =MAX(0,ROUND(SUMIFS(m1_cv!$E:$E,m1_cv!$A:$A,$E440,m1_cv!$B:$B,$A440),0)) -> 974 | H440: =MAX(0,ROUND(SUMIFS(m2_cv!$E:$E,m2_cv!$A:$A,$E440,m2_cv!$B:$B,$A440),0)) -> 249 | I440: =MAX(0,ROUND(SUMIFS(m3_cv!$E:$E,m3_cv!$A:$A,$E440,m3_cv!$B:$B,$A440),0)) -> 319 | J440: =MAX(0,ROUND(SUMIFS(m4_cv!$E:$E,m4_cv!$A:$A,$E440,m4_cv!$B:$B,$A440),0)) -> 313 | K440: =MAX(0,ROUND(SUMIFS(m5_cv!$E:$E,m5_cv!$A:$A,$E440,m5_cv!$B:$B,$A440),0)) -> 136 | L440: =MAX(0,ROUND(SUMIFS(m6_cv!$E:$E,m6_cv!$A:$A,$E440,m6_cv!$B:$B,$A440),0)) -> 168 | M440: =MAX(0,ROUND(SUMIFS(m7_cv!$E:$E,m7_cv!$A:$A,$E440,m7_cv!$B:$B,$A440),0)) -> 177 | N440: =ROUND(_xlfn.XLOOKUP($D440,Charts!$W$86:$W$116,Charts!$X$86:$X$116)*$L440+_xlfn.XLOOKUP($D440,Charts!$W$86:$W$116,Charts!$Y$86:$Y$116)*$M440,0) -> 177 | O440: =MAX(0,ROUND(SUMIFS(m8_cv!$E:$E,m8_cv!$A:$A,$E440,m8_cv!$B:$B,$A440),0)) -> 161 | Q440: 165 | R440: 164 | S440: =R440-T440 -> 0 | T440: =R440 -> 164 | U440: =ROUND(T440+T440/$T$459*$S$457,0) -> 188 | W440: =SUM(T$426:T440) -> 18402 | X440: =SUM(U$426:U440) -> 19715 | Y440: =SUM(F$426:F440) -> 20375 | Z440: =X440-Y440 -> -660
A441: =A440+1 -> 46097 | B441: =YEAR(A441) -> 2026 | C441: =MONTH($A441) -> 3 | D441: =DAY($A441) -> 16 | E441: =DATE($B441,$C441,1)-1 -> 46081 | F441: =_xlfn.XLOOKUP($A441,m1_cv!$B:$B,m1_cv!$C:$C) -> 3950 | G441: =MAX(0,ROUND(SUMIFS(m1_cv!$E:$E,m1_cv!$A:$A,$E441,m1_cv!$B:$B,$A441),0)) -> 3224 | H441: =MAX(0,ROUND(SUMIFS(m2_cv!$E:$E,m2_cv!$A:$A,$E441,m2_cv!$B:$B,$A441),0)) -> 2485 | I441: =MAX(0,ROUND(SUMIFS(m3_cv!$E:$E,m3_cv!$A:$A,$E441,m3_cv!$B:$B,$A441),0)) -> 2732 | J441: =MAX(0,ROUND(SUMIFS(m4_cv!$E:$E,m4_cv!$A:$A,$E441,m4_cv!$B:$B,$A441),0)) -> 2728 | K441: =MAX(0,ROUND(SUMIFS(m5_cv!$E:$E,m5_cv!$A:$A,$E441,m5_cv!$B:$B,$A441),0)) -> 2674 | L441: =MAX(0,ROUND(SUMIFS(m6_cv!$E:$E,m6_cv!$A:$A,$E441,m6_cv!$B:$B,$A441),0)) -> 2265 | M441: =MAX(0,ROUND(SUMIFS(m7_cv!$E:$E,m7_cv!$A:$A,$E441,m7_cv!$B:$B,$A441),0)) -> 2714 | N441: =ROUND(_xlfn.XLOOKUP($D441,Charts!$W$86:$W$116,Charts!$X$86:$X$116)*$L441+_xlfn.XLOOKUP($D441,Charts!$W$86:$W$116,Charts!$Y$86:$Y$116)*$M441,0) -> 2714 | O441: =MAX(0,ROUND(SUMIFS(m8_cv!$E:$E,m8_cv!$A:$A,$E441,m8_cv!$B:$B,$A441),0)) -> 2702 | Q441: 2242 | R441: 2704 | S441: =R441-T441 -> 0 | T441: =R441 -> 2704 | U441: =ROUND(T441+T441/$T$459*$S$457,0) -> 3105 | W441: =SUM(T$426:T441) -> 21106 | X441: =SUM(U$426:U441) -> 22820 | Y441: =SUM(F$426:F441) -> 24325 | Z441: =X441-Y441 -> -1505
A442: =A441+1 -> 46098 | B442: =YEAR(A442) -> 2026 | C442: =MONTH($A442) -> 3 | D442: =DAY($A442) -> 17 | E442: =DATE($B442,$C442,1)-1 -> 46081 | F442: =_xlfn.XLOOKUP($A442,m1_cv!$B:$B,m1_cv!$C:$C) -> 5807 | G442: =MAX(0,ROUND(SUMIFS(m1_cv!$E:$E,m1_cv!$A:$A,$E442,m1_cv!$B:$B,$A442),0)) -> 3719 | H442: =MAX(0,ROUND(SUMIFS(m2_cv!$E:$E,m2_cv!$A:$A,$E442,m2_cv!$B:$B,$A442),0)) -> 3012 | I442: =MAX(0,ROUND(SUMIFS(m3_cv!$E:$E,m3_cv!$A:$A,$E442,m3_cv!$B:$B,$A442),0)) -> 3020 | J442: =MAX(0,ROUND(SUMIFS(m4_cv!$E:$E,m4_cv!$A:$A,$E442,m4_cv!$B:$B,$A442),0)) -> 3014 | K442: =MAX(0,ROUND(SUMIFS(m5_cv!$E:$E,m5_cv!$A:$A,$E442,m5_cv!$B:$B,$A442),0)) -> 3084 | L442: =MAX(0,ROUND(SUMIFS(m6_cv!$E:$E,m6_cv!$A:$A,$E442,m6_cv!$B:$B,$A442),0)) -> 2899 | M442: =MAX(0,ROUND(SUMIFS(m7_cv!$E:$E,m7_cv!$A:$A,$E442,m7_cv!$B:$B,$A442),0)) -> 3094 | N442: =ROUND(_xlfn.XLOOKUP($D442,Charts!$W$86:$W$116,Charts!$X$86:$X$116)*$L442+_xlfn.XLOOKUP($D442,Charts!$W$86:$W$116,Charts!$Y$86:$Y$116)*$M442,0) -> 3094 | O442: =MAX(0,ROUND(SUMIFS(m8_cv!$E:$E,m8_cv!$A:$A,$E442,m8_cv!$B:$B,$A442),0)) -> 3089 | Q442: 2922 | R442: 3092 | S442: =R442-T442 -> 0 | T442: =R442 -> 3092 | U442: =ROUND(T442+T442/$T$459*$S$457,0) -> 3550 | W442: =SUM(T$426:T442) -> 24198 | X442: =SUM(U$426:U442) -> 26370 | Y442: =SUM(F$426:F442) -> 30132 | Z442: =X442-Y442 -> -3762
A443: =A442+1 -> 46099 | B443: =YEAR(A443) -> 2026 | C443: =MONTH($A443) -> 3 | D443: =DAY($A443) -> 18 | E443: =DATE($B443,$C443,1)-1 -> 46081 | F443: =_xlfn.XLOOKUP($A443,m1_cv!$B:$B,m1_cv!$C:$C) -> 5295 | G443: =MAX(0,ROUND(SUMIFS(m1_cv!$E:$E,m1_cv!$A:$A,$E443,m1_cv!$B:$B,$A443),0)) -> 3750 | H443: =MAX(0,ROUND(SUMIFS(m2_cv!$E:$E,m2_cv!$A:$A,$E443,m2_cv!$B:$B,$A443),0)) -> 3240 | I443: =MAX(0,ROUND(SUMIFS(m3_cv!$E:$E,m3_cv!$A:$A,$E443,m3_cv!$B:$B,$A443),0)) -> 3281 | J443: =MAX(0,ROUND(SUMIFS(m4_cv!$E:$E,m4_cv!$A:$A,$E443,m4_cv!$B:$B,$A443),0)) -> 3274 | K443: =MAX(0,ROUND(SUMIFS(m5_cv!$E:$E,m5_cv!$A:$A,$E443,m5_cv!$B:$B,$A443),0)) -> 3324 | L443: =MAX(0,ROUND(SUMIFS(m6_cv!$E:$E,m6_cv!$A:$A,$E443,m6_cv!$B:$B,$A443),0)) -> 3093 | M443: =MAX(0,ROUND(SUMIFS(m7_cv!$E:$E,m7_cv!$A:$A,$E443,m7_cv!$B:$B,$A443),0)) -> 3314 | N443: =ROUND(_xlfn.XLOOKUP($D443,Charts!$W$86:$W$116,Charts!$X$86:$X$116)*$L443+_xlfn.XLOOKUP($D443,Charts!$W$86:$W$116,Charts!$Y$86:$Y$116)*$M443,0) -> 3314 | O443: =MAX(0,ROUND(SUMIFS(m8_cv!$E:$E,m8_cv!$A:$A,$E443,m8_cv!$B:$B,$A443),0)) -> 3297 | Q443: 3138 | R443: 3300 | S443: =R443-T443 -> 0 | T443: =R443 -> 3300 | U443: =ROUND(T443+T443/$T$459*$S$457,0) -> 3789 | W443: =SUM(T$426:T443) -> 27498 | X443: =SUM(U$426:U443) -> 30159 | Y443: =SUM(F$426:F443) -> 35427 | Z443: =X443-Y443 -> -5268
